Workbook
Name 在此区间: 建设单位管理费!$L$5
Name 在此区间内: 建设单位管理费!$L$5

Sheet 项目技术经济指标
A1: 序号 | B1: 内容名称 | C1: 单位 | D1: 数量 | E1: 备注
A2: 一 | B2: 方案技术指标
A3: =总投资估算!A4 -> （一） | B3: =总投资估算!B4 -> 农村产业融合示范园
A4: =总投资估算!A5 -> 1 | B4: =总投资估算!B5 -> 分拣仓库 | C4: =总投资估算!I6 -> 平方米 | D4: =总投资估算!J5 -> 1000
A5: =总投资估算!A6 -> 1.1 | B5: =总投资估算!B6 -> 土建工程 | C5: =总投资估算!I7 -> 平方米 | D5: =总投资估算!J6 -> 1000
A6: =总投资估算!A7 -> 1.2 | B6: =总投资估算!B7 -> 给排水工程 | C6: =总投资估算!I8 -> 平方米 | D6: =总投资估算!J7 -> 1000
A7: =总投资估算!A8 -> 1.3 | B7: =总投资估算!B8 -> 电气工程 | C7: =总投资估算!I9 -> 平方米 | D7: =总投资估算!J8 -> 1000
A8: =总投资估算!A9 -> 1.4 | B8: =总投资估算!B9 -> 消防工程 | C8: =总投资估算!I10 -> 平方米 | D8: =总投资估算!J9 -> 1000 | G8: 成本 | H8: 工资 | I8: 管理人员 | K8: 职工 | M8: 每五年增长率
A9: =总投资估算!A10 -> 1.5 | B9: =总投资估算!B10 -> 暖通工程 | C9: =总投资估算!I11 -> 平方米 | D9: =总投资估算!J10 -> 1000 | I9: 人数 | J9: 月工资 | K9: 人数 | L9: 月工资
A10: =总投资估算!A11 -> 2 | B10: =总投资估算!B11 -> 农产品加工厂房 | C10: =总投资估算!I12 -> 平方米 | D10: =总投资估算!J11 -> 1000 | I10: 5 | J10: 4500 | K10: 15 | L10: 4000 | M10: 0.1
A11: =总投资估算!A12 -> 2.1 | B11: =总投资估算!B12 -> 土建工程 | C11: =总投资估算!I13 -> 平方米 | D11: =总投资估算!J12 -> 1000
A12: =总投资估算!A13 -> 2.2 | B12: =总投资估算!B13 -> 给排水工程 | C12: =总投资估算!I14 -> 平方米 | D12: =总投资估算!J13 -> 1000 | H12: =SUM(D5:D8) -> 4000 | I12: =SUM(H12:H13) -> 6000
A13: =总投资估算!A14 -> 2.3 | B13: =总投资估算!B14 -> 电气工程 | C13: =总投资估算!I15 -> 平方米 | D13: =总投资估算!J14 -> 1000 | H13: =SUM(D10:D11) -> 2000
A14: =总投资估算!A15 -> 2.4 | B14: =总投资估算!B15 -> 消防工程 | C14: =总投资估算!I16 -> 平方米 | D14: =总投资估算!J15 -> 1000
A15: =总投资估算!A16 -> 2.5 | B15: =总投资估算!B16 -> 暖通工程 | C15: =总投资估算!I17 -> 平方米 | D15: =总投资估算!J16 -> 1000
A16: =总投资估算!A17 -> 3 | B16: =总投资估算!B17 -> 保鲜仓储中心 | C16: =总投资估算!I18 -> 平方米 | D16: =总投资估算!J17 -> 500
A17: =总投资估算!A18 -> 3.1 | B17: =总投资估算!B18 -> 土建工程 | C17: =总投资估算!I19 -> 平方米 | D17: =总投资估算!J18 -> 500
A18: =总投资估算!A19 -> 3.2 | B18: =总投资估算!B19 -> 给排水工程 | C18: =总投资估算!I20 -> 平方米 | D18: =总投资估算!J19 -> 500
A19: =总投资估算!A20 -> 3.3 | B19: =总投资估算!B20 -> 电气工程 | C19: =总投资估算!I21 -> 平方米 | D19: =总投资估算!J20 -> 500
A20: =总投资估算!A21 -> 3.4 | B20: =总投资估算!B21 -> 消防工程 | C20: =总投资估算!I22 -> 平方米 | D20: =总投资估算!J21 -> 500
A21: =总投资估算!A22 -> 3.5 | B21: =总投资估算!B22 -> 暖通工程 | C21: =总投资估算!I23 -> 平方米 | D21: =总投资估算!J22 -> 500
A22: =总投资估算!A23 -> 4 | B22: =总投资估算!B23 -> 实践教育综合基地 | C22: =总投资估算!I24 -> 平方米 | D22: =总投资估算!J23 -> 5300
A23: =总投资估算!A24 -> 4.1 | B23: =总投资估算!B24 -> 土建工程 | C23: =总投资估算!I25 -> 平方米 | D23: =总投资估算!J24 -> 5300
A24: =总投资估算!A25 -> 4.2 | B24: =总投资估算!B25 -> 给排水工程 | C24: =总投资估算!I26 -> 平方米 | D24: =总投资估算!J25 -> 5300
A25: =总投资估算!A26 -> 4.3 | B25: =总投资估算!B26 -> 电气工程 | C25: =总投资估算!I27 -> 平方米 | D25: =总投资估算!J26 -> 5300
... A39: =总投资估算!A40 -> 6.5 | B39: =总投资估算!B40 -> 暖通工程 | C39: =总投资估算!I41 -> 平方米 | D39: =总投资估算!J40 -> 20089
A40: =总投资估算!A41 -> 7 | B40: =总投资估算!B41 -> 创新创业孵化平台地下停车场 | C40: =总投资估算!I42 -> 平方米 | D40: =总投资估算!J41 -> 6000 | E40: 停车位225个
A41: =总投资估算!A42 -> 7.1 | B41: =总投资估算!B42 -> 支护工程 | C41: =总投资估算!I43 -> 平方米 | D41: =总投资估算!J42 -> 6000
A42: =总投资估算!A43 -> 7.2 | B42: =总投资估算!B43 -> 主体工程 | C42: =总投资估算!I45 -> 平方米 | D42: =总投资估算!J43 -> 6000
A43: =总投资估算!A45 -> 9.2 | B43: =总投资估算!B45 -> 电气工程 | C43: =总投资估算!I46 -> 平方米 | D43: =总投资估算!J45 -> 6000
A44: =总投资估算!A46 -> 7.4 | B44: =总投资估算!B46 -> 消防工程 | C44: =总投资估算!I47 -> 平方米 | D44: =总投资估算!J46 -> 6000
A45: =总投资估算!A47 -> 7.5 | B45: =总投资估算!B47 -> 通风工程 | C45: =总投资估算!I48 -> 平方米 | D45: =总投资估算!J47 -> 6000
A46: =总投资估算!A48 -> 8 | B46: =总投资估算!B48 -> 停车场 | C46: =总投资估算!I49 -> 平方米 | D46: =总投资估算!J48 -> 1050 | E46: 停车位30个
A47: =总投资估算!A49 -> 8.1 | B47: =总投资估算!B49 -> 场地铺装 | C47: =总投资估算!I50 -> 平方米 | D47: =总投资估算!J49 -> 1050
A48: =总投资估算!A50 -> 8.2 | B48: =总投资估算!B50 -> 标线工程 | C48: =总投资估算!I51 -> 项 | D48: =总投资估算!J50 -> 1050
A49: =总投资估算!A51 -> 8.3 | B49: =总投资估算!B51 -> 闸机及停车管理系统 | C49: =总投资估算!I52 -> 亩 | D49: =总投资估算!J51 -> 1
A50: =总投资估算!A52 -> 9 | B50: =总投资估算!B52 -> 标准化农田 | C50: =总投资估算!I53 -> 亩 | D50: =总投资估算!J52 -> 73.86
A51: =总投资估算!A53 -> 9.1 | B51: =总投资估算!B53 -> 土地平整 | C51: =总投资估算!I54 -> 亩 | D51: =总投资估算!J53 -> 73.86
A52: =总投资估算!A54 -> 9.2 | B52: =总投资估算!B54 -> 挖壕打穴 | C52: =总投资估算!I55 -> 亩 | D52: =总投资估算!J54 -> 73.86
A53: =总投资估算!A55 -> 9.3 | B53: =总投资估算!B55 -> 水肥一体 | C53: =总投资估算!I56 -> 亩 | D53: =总投资估算!J55 -> 73.86
...

Sheet 标准化指标设定
C1: 本表所有此颜色单元格为基础数据，需自行嵌入。其余单元格均为联动，勿调整。
B3: 农村污水处理及中水再利用建设项目
A4: 江西省指标要求和假设参数设计 | J4: 江西省生活用水定额 | S4: 吉水县2021年末人口统计
A5: 序号 | B5: 指标项 | C5: 江西省用地指标（2018） | D5: 参数设定 | E5: 单位 | F5: 项目数据 | G5: 备注
A6: 1 | B6: 二级污水处理站用地 | C6: 参考城市污水处理厂建设用地指标 | D6: =1.5+(F11/10000-1)*((6-1.5)/(5-1)) -> 5.325 | E6: 公顷 | G6: 1、为应对突发情况污水处理厂、污水管网泵站设计规模应比计算规模适当增大 2、污水处理厂规模按项目数据中的污水处理量来测算，收入计算时按参数设定中的处理量来计算
A7: 1.1 | B7: 区域人口 | C7: 根据地区情况确定 | D7: =G60/10000 -> 28.4983 | E7: 万人
A8: 1.2 | B8: 用水定额 | C8: 参考江西省生活用水定额 | D8: 200 | E8: L/（人*天）
A9: 1.3 | B9: 产污系数 | C9: 0.80-0.9 | D9: 0.85
A10: 1.4 | B10: 污水收集系数 | C10: 0.7-0.95 | D10: 0.9
A11: 1.5 | B11: 污水处理量 | D11: =D7*D8*D9*D10*10000/1000 -> 43602.399 | E11: m³/天 | F11: 44000
A12: 1.6 | B12: 容积率 | C12: ≥0.7 | D12: 0.75
A13: 2 | B13: 污水管网泵站用地 | C13: 参考污水管网泵站建设用地指标 | D13: =800+(F15-0.1)*(2500-800)/(1-0.1) -> 2122.2222 | E13: ㎡
A14: 2.1 | B14: 容积率 | C14: ≥0.7 | D14: =F28/D13 -> 0.84816754 | I14: 污水处理厂规模按项目数据中的污水处理量来测定，收入计算时按参数设定中的处理量来计算
A15: 2.2 | B15: 建设规模 | C15: 参考污水管网泵站建设用地指标 | D15: =F11/(24*60*60) -> 0.50925926 | F15: 0.8
A16: 一 | B16: 总建筑面积 | F16: =F17+F28 -> 41737
A17: 1 | B17: 污水处理厂 | E17: ㎡ | F17: =INT(D6*10000*D12) -> 39937 | K17: 江西省用地指标（2018）
A18: 1.1 | B18: 粗格栅池 | C18: 根据实际需要确定 | E18: ㎡ | F18: 6300
A19: 1.2 | B19: 提升池 | C19: 根据实际需要确定 | E19: ㎡ | F19: 6300
A20: 1.3 | B20: 沉砂池 | C20: 根据实际需要确定 | E20: ㎡ | F20: 6300
A21: 1.4 | B21: 兼氧 FMBR 池 | C21: 根据实际需要确定 | E21: ㎡ | F21: 3800
A22: 1.5 | B22: 消毒回用池 | C22: 根据实际需要确定 | E22: ㎡ | F22: 3800
A23: 1.6 | B23: 污泥池 | C23: 根据实际需要确定 | E23: ㎡ | F23: 3100
A24: 1.7 | B24: 贮泥池 | C24: 根据实际需要确定 | E24: ㎡ | F24: 3100
A25: 1.8 | B25: 污泥脱水机房 | C25: 根据实际需要确定 | E25: ㎡ | F25: 3600
A26: 1.9 | B26: 管理用房 | C26: 建筑面积比例不超过总建筑面积的15% | E26: ㎡ | F26: =F17-SUM(F18:F25) -> 3637 | G26: =F16*0.15 -> 6260.55
A27: 2 | B27: 厂区室外工程 | C27: 不得低于用地面积的30% | D27: 0.3 | E27: ㎡ | F27: =INT(D6*10000*D27) -> 15975
A28: 3 | B28: 污水管网泵站 | E28: ㎡ | F28: 1800 | K28: 容积率
A29: 4 | B29: 污水管网 | E29: ㎞ | F29: =F30 -> 125
A30: 4.1 | B30: 新建污水管道 | C30: 根据实际需要确定 | E30: ㎞ | F30: =F31+F32+F33 -> 125
A31: 4.1.1 | B31: HDPE缠绕结构壁管-DN300 | C31: 根据实际需要确定 | E31: ㎞ | F31: 78
A32: 4.1.2 | B32: HDPE缠绕结构壁管-DN400 | C32: 根据实际需要确定 | E32: ㎞ | F32: 32
A33: 4.1.3 | B33: HDPE缠绕结构壁管-DN500 | C33: 根据实际需要确定 | E33: ㎞ | F33: 15
A34: 4.2 | B34: 检查井 | C34: 检查井之间的距离不宜大于50m | D34: 40 | E34: 个 | F34: =F30*1000/D34 -> 3125
I42: 吉水县农村生活污水治理专项规划
E50: 36573 | F50: 24368 | G50: 42477
E51: 31338 | F51: 19132 | G51: 29008
E52: 27783 | F52: 18504 | G52: 34226
E53: 31264 | F53: 27490 | G53: 38580
E54: 16007 | F54: 6259 | G54: 14591
E55: 10649 | F55: 8510 | G55: 14010
...

Sheet 总投资估算
A1: 序号 | B1: 工程或费用名称 | C1: 估算金额（万元） | I1: 技术经济指标 | L1: 备注
C2: 建筑工程费 | D2: 安装工程费 | E2: 设备购置费 | F2: 其他费用 | G2: 小计 | H2: 比例 | I2: 单位 | J2: 数量 | K2: 单价（元）
A3: 一 | B3: 工程费用 | C3: =SUM(C4+C64) -> 17385.78 | D3: =SUM(D4+D64) -> 0 | E3: =SUM(E4+E64) -> 0 | F3: =SUM(F4+F64) -> 0 | G3: =SUM(G4+G64) -> 17385.78 | H3: =SUM(H4+H64) -> 0.79026273
A4: （一） | B4: 农村产业融合示范园 | C4: =SUM(C5+C11+C17+C23+C29+C35+C41+C48+C52+C56+C60) -> 14755.78 | D4: =SUM(D5+D11+D17+D23+D29+D35+D41+D48+D52+D56+D60) -> 0 | E4: =SUM(E5+E11+E17+E23+E29+E35+E41+E48+E52+E56+E60) -> 0 | F4: =SUM(F5+F11+F17+F23+F29+F35+F41+F48+F52+F56+F60) -> 0 | G4: =SUM(G5+G11+G17+G23+G29+G35+G41+G48+G52+G56+G60) -> 14755.78 | H4: =G4/$G$95 -> 0.67071727
A5: 1 | B5: 分拣仓库 | C5: =SUM(C6:C10) -> 366 | D5: =SUM(D6:D10) -> 0 | E5: =SUM(E6:E10) -> 0 | F5: =SUM(F6:F10) -> 0 | G5: =SUM(G6:G10) -> 366 | H5: =G5/$G$95 -> 0.016636364 | I5: 平方米 | J5: 1000
A6: 1.1 | B6: 土建工程 | C6: =ROUND(J6*K6/10000,2) -> 330 | G6: =C6+E6+D6+F6 -> 330 | H6: =G6/$G$95 -> 0.015 | I6: 平方米 | J6: =J5 -> 1000 | K6: 3300
A7: 1.2 | B7: 给排水工程 | C7: =ROUND(J7*K7/10000,2) -> 9 | G7: =C7+E7+D7+F7 -> 9 | H7: =G7/$G$95 -> 0.00040909091 | I7: 平方米 | J7: =J6 -> 1000 | K7: 90
A8: 1.3 | B8: 电气工程 | C8: =ROUND(J8*K8/10000,2) -> 11 | G8: =C8+E8+D8+F8 -> 11 | H8: =G8/$G$95 -> 0.0005 | I8: 平方米 | J8: =J7 -> 1000 | K8: 110
A9: 1.4 | B9: 消防工程 | C9: =ROUND(J9*K9/10000,2) -> 9 | G9: =C9+E9+D9+F9 -> 9 | H9: =G9/$G$95 -> 0.00040909091 | I9: 平方米 | J9: =J8 -> 1000 | K9: 90
A10: 1.5 | B10: 暖通工程 | C10: =ROUND(J10*K10/10000,2) -> 7 | G10: =C10+E10+D10+F10 -> 7 | H10: =G10/$G$95 -> 0.00031818182 | I10: 平方米 | J10: =J9 -> 1000 | K10: 70
A11: 2 | B11: 农产品加工厂房 | C11: =SUM(C12:C16) -> 366 | D11: =SUM(D12:D16) -> 0 | E11: =SUM(E12:E16) -> 0 | F11: =SUM(F12:F16) -> 0 | G11: =C11+E11+D11+F11 -> 366 | H11: =G11/$G$95 -> 0.016636364 | I11: 平方米 | J11: 1000
A12: 2.1 | B12: 土建工程 | C12: =ROUND(J12*K12/10000,2) -> 330 | G12: =C12+E12+D12+F12 -> 330 | H12: =G12/$G$95 -> 0.015 | I12: 平方米 | J12: =J11 -> 1000 | K12: =K6 -> 3300
A13: 2.2 | B13: 给排水工程 | C13: =ROUND(J13*K13/10000,2) -> 9 | G13: =C13+E13+D13+F13 -> 9 | H13: =G13/$G$95 -> 0.00040909091 | I13: 平方米 | J13: =J12 -> 1000 | K13: =K7 -> 90
A14: 2.3 | B14: 电气工程 | C14: =ROUND(J14*K14/10000,2) -> 11 | G14: =C14+E14+D14+F14 -> 11 | H14: =G14/$G$95 -> 0.0005 | I14: 平方米 | J14: =J13 -> 1000 | K14: =K8 -> 110
A15: 2.4 | B15: 消防工程 | C15: =ROUND(J15*K15/10000,2) -> 9 | G15: =C15+E15+D15+F15 -> 9 | H15: =G15/$G$95 -> 0.00040909091 | I15: 平方米 | J15: =J14 -> 1000 | K15: =K9 -> 90
A16: 2.5 | B16: 暖通工程 | C16: =ROUND(J16*K16/10000,2) -> 7 | G16: =C16+E16+D16+F16 -> 7 | H16: =G16/$G$95 -> 0.00031818182 | I16: 平方米 | J16: =J15 -> 1000 | K16: =K10 -> 70
A17: 3 | B17: 保鲜仓储中心 | C17: =SUM(C18:C22) -> 194.5 | D17: =SUM(D18:D22) -> 0 | E17: =SUM(E18:E22) -> 0 | F17: =SUM(F18:F22) -> 0 | G17: =C17+E17+D17+F17 -> 194.5 | H17: =G17/$G$95 -> 0.0088409091 | I17: 平方米 | J17: 500
A18: 3.1 | B18: 土建工程 | C18: =ROUND(J18*K18/10000,2) -> 165 | G18: =C18+E18+D18+F18 -> 165 | H18: =G18/$G$95 -> 0.0075 | I18: 平方米 | J18: =J17 -> 500 | K18: =K12 -> 3300
A19: 3.2 | B19: 给排水工程 | C19: =ROUND(J19*K19/10000,2) -> 4.5 | G19: =C19+E19+D19+F19 -> 4.5 | H19: =G19/$G$95 -> 0.00020454545 | I19: 平方米 | J19: =J18 -> 500 | K19: =K13 -> 90
A20: 3.3 | B20: 电气工程 | C20: =ROUND(J20*K20/10000,2) -> 5.5 | G20: =C20+E20+D20+F20 -> 5.5 | H20: =G20/$G$95 -> 0.00025 | I20: 平方米 | J20: =J19 -> 500 | K20: =K14 -> 110
A21: 3.4 | B21: 消防工程 | C21: =ROUND(J21*K21/10000,2) -> 4.5 | G21: =C21+E21+D21+F21 -> 4.5 | H21: =G21/$G$95 -> 0.00020454545 | I21: 平方米 | J21: =J20 -> 500 | K21: =K15 -> 90
A22: 3.5 | B22: 暖通工程 | C22: =ROUND(J22*K22/10000,2) -> 15 | G22: =C22+E22+D22+F22 -> 15 | H22: =G22/$G$95 -> 0.00068181818 | I22: 平方米 | J22: =J21 -> 500 | K22: 300
A23: 4 | B23: 实践教育综合基地 | C23: =SUM(C24:C28) -> 1939.8 | D23: =SUM(D24:D28) -> 0 | E23: =SUM(E24:E28) -> 0 | F23: =SUM(F24:F28) -> 0 | G23: =C23+E23+D23+F23 -> 1939.8 | H23: =G23/$G$95 -> 0.088172727 | I23: 平方米 | J23: 5300
A24: 4.1 | B24: 土建工程 | C24: =ROUND(J24*K24/10000,2) -> 1749 | G24: =C24+E24+D24+F24 -> 1749 | H24: =G24/$G$95 -> 0.0795 | I24: 平方米 | J24: =J23 -> 5300 | K24: =K18 -> 3300
A25: 4.2 | B25: 给排水工程 | C25: =ROUND(J25*K25/10000,2) -> 47.7 | G25: =C25+E25+D25+F25 -> 47.7 | H25: =G25/$G$95 -> 0.0021681818 | I25: 平方米 | J25: =J24 -> 5300 | K25: =K19 -> 90
A26: 4.3 | B26: 电气工程 | C26: =ROUND(J26*K26/10000,2) -> 58.3 | G26: =C26+E26+D26+F26 -> 58.3 | H26: =G26/$G$95 -> 0.00265 | I26: 平方米 | J26: =J25 -> 5300 | K26: =K20 -> 110
A27: 4.4 | B27: 消防工程 | C27: =ROUND(J27*K27/10000,2) -> 47.7 | G27: =C27+E27+D27+F27 -> 47.7 | H27: =G27/$G$95 -> 0.0021681818 | I27: 平方米 | J27: =J26 -> 5300 | K27: =K21 -> 90
A28: 4.5 | B28: 暖通工程 | C28: =ROUND(J28*K28/10000,2) -> 37.1 | G28: =C28+E28+D28+F28 -> 37.1 | H28: =G28/$G$95 -> 0.0016863636 | I28: 平方米 | J28: =J27 -> 5300 | K28: =K16 -> 70
A29: 5 | B29: 农业技术推广中心 | C29: =SUM(C30:C34) -> 219.6 | D29: =SUM(D30:D34) -> 0 | E29: =SUM(E30:E34) -> 0 | F29: =SUM(F30:F34) -> 0 | G29: =C29+E29+D29+F29 -> 219.6 | H29: =G29/$G$95 -> 0.0099818182 | I29: 平方米 | J29: 600
A30: 5.1 | B30: 土建工程 | C30: =ROUND(J30*K30/10000,2) -> 198 | G30: =C30+E30+D30+F30 -> 198 | H30: =G30/$G$95 -> 0.009 | I30: 平方米 | J30: =J29 -> 600 | K30: =K24 -> 3300 | O30: =5000/0.8 -> 6250
A31: 5.2 | B31: 给排水工程 | C31: =ROUND(J31*K31/10000,2) -> 5.4 | G31: =C31+E31+D31+F31 -> 5.4 | H31: =G31/$G$95 -> 0.00024545455 | I31: 平方米 | J31: =J30 -> 600 | K31: =K25 -> 90
A32: 5.3 | B32: 电气工程 | C32: =ROUND(J32*K32/10000,2) -> 6.6 | G32: =C32+E32+D32+F32 -> 6.6 | H32: =G32/$G$95 -> 0.0003 | I32: 平方米 | J32: =J31 -> 600 | K32: =K26 -> 110
A33: 5.4 | B33: 消防工程 | C33: =ROUND(J33*K33/10000,2) -> 5.4 | G33: =C33+E33+D33+F33 -> 5.4 | H33: =G33/$G$95 -> 0.00024545455 | I33: 平方米 | J33: =J32 -> 600 | K33: =K27 -> 90
A34: 5.5 | B34: 暖通工程 | C34: =ROUND(J34*K34/10000,2) -> 4.2 | G34: =C34+E34+D34+F34 -> 4.2 | H34: =G34/$G$95 -> 0.00019090909 | I34: 平方米 | J34: =J33 -> 600 | K34: =K28 -> 70
A35: 6 | B35: 创新创业孵化平台 | C35: =SUM(C36:C40) -> 7352.57 | D35: =SUM(D36:D40) -> 0 | E35: =SUM(E36:E40) -> 0 | F35: =SUM(F36:F40) -> 0 | G35: =C35+E35+D35+F35 -> 7352.57 | H35: =G35/$G$95 -> 0.33420773 | I35: 平方米 | J35: 20089
A36: 6.1 | B36: 土建工程 | C36: =ROUND(J36*K36/10000,2) -> 6629.37 | G36: =C36+E36+D36+F36 -> 6629.37 | H36: =G36/$G$95 -> 0.301335 | I36: 平方米 | J36: =J35 -> 20089 | K36: =K30 -> 3300
A37: 6.2 | B37: 给排水工程 | C37: =ROUND(J37*K37/10000,2) -> 180.8 | G37: =C37+E37+D37+F37 -> 180.8 | H37: =G37/$G$95 -> 0.0082181818 | I37: 平方米 | J37: =J36 -> 20089 | K37: =K31 -> 90
A38: 6.3 | B38: 电气工程 | C38: =ROUND(J38*K38/10000,2) -> 220.98 | G38: =C38+E38+D38+F38 -> 220.98 | H38: =G38/$G$95 -> 0.010044545 | I38: 平方米 | J38: =J37 -> 20089 | K38: =K32 -> 110
A39: 6.4 | B39: 消防工程 | C39: =ROUND(J39*K39/10000,2) -> 180.8 | G39: =C39+E39+D39+F39 -> 180.8 | H39: =G39/$G$95 -> 0.0082181818 | I39: 平方米 | J39: =J38 -> 20089 | K39: =K33 -> 90
A40: 6.5 | B40: 暖通工程 | C40: =ROUND(J40*K40/10000,2) -> 140.62 | G40: =C40+E40+D40+F40 -> 140.62 | H40: =G40/$G$95 -> 0.0063918182 | I40: 平方米 | J40: =J39 -> 20089 | K40: =K34 -> 70
...

Sheet 其他费自动计算
A1: 序号 | B1: 费用输入（万元） | C1: 输入👇
A2: 1 | B2: 工程费用 | C2: =总投资估算!G3 -> 17385.78 | E2: 总投资 | G2: 总建筑面积
A3: 2 | B3: 总投资 | E3: 7000 | F3: ☜手动输入 | G3: =项目技术经济指标!D3/10000 -> 0 | H3: ☜手动输入
A4: 3 | B4: 设备购置费 | C4: =总投资估算!E3 -> 0
A7: 地区筛选 | B7: 红谷滩区
E9: 单位：万元 | G9: 地区折扣目录
A10: 序号 | B10: 费用名称 | C10: 估算金额 | D10: 地区折扣 | E10: 折后金额 | F10: 计费基础 | G10: 南昌市 | I10: 红谷滩区 | K10: 南昌县
G11: 参考文件 | H11: 折扣率 | I11: 参考文件 | J11: 折扣率 | K11: 参考文件 | L11: 折扣率
A12: 1 | B12: =工程建设其他费细则说明!B4 -> 建设单位管理费 | C12: =H112 -> 213.8578 | D12: =SUMIF(G$10:L$10,B$7,H12) -> 0.8 | E12: =C12*D12 -> 171.08624 | F12: 工程费用 | H12: 0.3 | J12: 0.8 | L12: 0.7
A13: 2 | B13: =工程建设其他费细则说明!B18 -> 场地准备及临时设施费 | C13: =C2*1% -> 173.8578 | D13: =SUMIF(G$10:L$10,B$7,H13) -> 0.6 | E13: =C13*D13 -> 104.31468 | F13: 工程费用 | H13: 0.6 | J13: 0.6 | L13: 0.6
A14: 3 | B14: =工程建设其他费细则说明!B21 -> 前期工作咨询费 | C14: =G34 -> 21.141877 | D14: =SUMIF(G$10:L$10,B$7,H14) -> 0.5 | E14: =C14*D14 -> 10.570939 | F14: 总投资 | H14: 0.5 | J14: 0.5 | L14: 0.6
A15: 4 | B15: =工程建设其他费细则说明!B36 -> 勘察费 | C15: =C2*1% -> 173.8578 | D15: =SUMIF(G$10:L$10,B$7,H15) -> 0.4 | E15: =C15*D15 -> 69.54312 | F15: 工程费用 | H15: 0.8 | J15: 0.4 | L15: 0.85
A16: 5 | B16: =工程建设其他费细则说明!B37 -> 设计费 | C16: =E123 -> 498.30744 | D16: =SUMIF(G$10:L$10,B$7,H16) -> 0.4 | E16: =C16*D16 -> 199.32297 | F16: 工程费用 | H16: 0.9 | J16: 0.4 | L16: 0.85
A17: 6 | B17: =工程建设其他费细则说明!B38 -> 工程监理费 | C17: =E147 -> 347.70343 | D17: =SUMIF(G$10:L$10,B$7,H17) -> 0.7 | E17: =C17*D17 -> 243.3924 | F17: 工程费用 | H17: 0.5 | J17: 0.7 | L17: 0.7
A18: 7 | B18: =工程建设其他费细则说明!B42 -> 招标代理费 | C18: =S57 -> 44.501839 | D18: =SUMIF(G$10:L$10,B$7,H18) -> 0.49 | E18: =C18*D18 -> 21.805901 | F18: 分包 | H18: 0.3 | J18: 0.49 | L18: 0.8
A19: 8 | B19: =工程建设其他费细则说明!B43 -> 施工图审查费 | C19: =H181 -> 18.98578 | D19: =SUMIF(G$10:L$10,B$7,H19) -> 0.7 | E19: =C19*D19 -> 13.290046 | F19: 工程费用 | H19: 0.4 | J19: 0.7 | L19: 0.6
A20: 9 | B20: =工程建设其他费细则说明!B45 -> 工程造价咨询费 | C20: =H169 -> 127.16615 | D20: =SUMIF(G$10:L$10,B$7,H20) -> 0.5 | E20: =C20*D20 -> 63.583074 | F20: 工程费用 | H20: 0.7 | J20: 0.5 | L20: 0.7
A21: 10 | B21: =工程建设其他费细则说明!B46 -> 工程保险费 | C21: =C2*0.5% -> 86.9289 | D21: =SUMIF(G$10:L$10,B$7,H21) -> 0.7 | E21: =C21*D21 -> 60.85023 | F21: 工程费用 | H21: 0.6 | J21: 0.7 | L21: 0.7
A22: 11 | B22: =工程建设其他费细则说明!B23 -> 环境影响评价费 | C22: =G64 -> 5.2352941 | D22: =SUMIF(G$10:L$10,B$7,H22) -> 0.7 | E22: =C22*D22 -> 3.6647059 | F22: 总投资 | H22: 0.7 | J22: 0.7 | L22: 0.7
A23: 12 | B23: =工程建设其他费细则说明!B29 -> 节能评估费 | C23: =H218 -> 7.2925115 | D23: =SUMIF(G$10:L$10,B$7,H23) -> 0.7 | E23: =C23*D23 -> 5.1047581 | F23: 工程费用 | H23: 0.7 | J23: 0.7 | L23: 0.7
A24: 13 | B24: =工程建设其他费细则说明!B27 -> 水土保持评价费 | C24: =G190 -> 66.77156 | D24: =SUMIF(G$10:L$10,B$7,H24) -> 0.7 | E24: =C24*D24 -> 46.740092 | F24: 工程费用 | H24: 0.7 | J24: 0.7 | L24: 0.7
A25: 14 | B25: =工程建设其他费细则说明!B32 -> 劳动安全卫生评审费 | C25: =C2*0.5% -> 86.9289 | D25: =SUMIF(G$10:L$10,B$7,H25) -> 0.7 | E25: =C25*D25 -> 60.85023 | F25: 工程费用 | H25: 0.7 | J25: 0.7 | L25: 0.7
A26: 15 | B26: =工程建设其他费细则说明!B31 -> 社会稳定风险评估费 | C26: =I75 -> 5.6571429 | D26: =SUMIF(G$10:L$10,B$7,H26) -> 0.7 | E26: =C26*D26 -> 3.96 | F26: 总投资 | H26: 0.7 | J26: 0.7 | L26: 0.7
A27: 16 | B27: =工程建设其他费细则说明!B24 -> 安全预评价费 | C27: =G87 -> 7.2 | D27: =SUMIF(G$10:L$10,B$7,H27) -> 0.7 | E27: =C27*D27 -> 5.04 | F27: 总投资 | H27: 0.7 | J27: 0.7 | L27: 0.7
A28: 17 | B28: =工程建设其他费细则说明!B33 -> 交通影响评估费 | C28: 0 | D28: =SUMIF(G$10:L$10,B$7,H28) -> 0.7 | E28: =C28*D28 -> 0 | F28: 总建筑面积 | H28: 0.7 | J28: 0.7 | L28: 0.7
A29: 合计 | C29: =SUM(C12:C28) -> 1885.3942
A32: 前期工作咨询费（可行性研究报告）
A33: 序号 | B33: 计费额 | E33: 基价 | F33: 输入费用👇 | G33: 直线内插法计取
F34: =E3 -> 7000 | G34: =SUM(G35:G41) -> 21.141877
A35: 1 | C35: > | D35: 1000 | E35: 3 | F35: =IF(F34<=D35,1,0) -> 0 | G35: =IF($F35=1,(E35/D35*$F34),0) -> 0
A36: 2 | B36: 1001 | C36: ~ | D36: 3000 | E36: 6 | F36: =IF(AND($F$34<=D36,$F$34>B36),1,0) -> 0 | G36: =IF($F36=1,(E36+((E37-E36)/(D36-B36)*($F$34-B36))),0) -> 0
A37: 3 | B37: 3001 | C37: ~ | D37: 10000 | E37: 12 | F37: =IF(AND($F$34<=D37,$F$34>B37),1,0) -> 1 | G37: =IF($F37=1,(E37+((E38-E37)/(D37-B37)*($F$34-B37))),0) -> 21.141877
A38: 4 | B38: 10001 | C38: ~ | D38: 50000 | E38: 28 | F38: =IF(AND($F$34<=D38,$F$34>B38),1,0) -> 0 | G38: =IF($F38=1,(E38+((E39-E38)/(D38-B38)*($F$34-B38))),0) -> 0
A39: 5 | B39: 50001 | C39: ~ | D39: 100000 | E39: 75 | F39: =IF(AND($F$34<=D39,$F$34>B39),1,0) -> 0 | G39: =IF($F39=1,(E39+((E40-E39)/(D39-B39)*($F$34-B39))),0) -> 0
A40: 6 | B40: 100000 | C40: ~ | D40: 500000 | E40: 110 | F40: =IF(AND($F$34<=D40,$F$34>B40),1,0) -> 0 | G40: =IF($F40=1,(E40+((E41-E40)/(D40-B40)*($F$34-B40))),0) -> 0
A41: 7 | B41: 500000 | E41: 200 | F41: =IF(AND($F$34>B41),1,0) -> 0 | G41: =IF($F41=1,MIN(250,F34*E41/B41),0) -> 0
A44: 招标代理服务费
A45: 计费额 | D45: 货物采购 | G45: 服务招标（勘察） | J45: 服务招标（设计） | M45: 服务招标（监理） | P45: 工程招标
D46: =C4 -> 0 | G46: =C15 -> 173.8578 | J46: =C16 -> 498.30744 | M46: =C17 -> 347.70343 | P46: =C2-C4 -> 17385.78
B47: < | C47: 100 | D47: =C47*E47 -> 1.5 | E47: 0.015 | F47: =IF(D46<=C47,D46*E47,0) -> 0 | G47: =C47*H47 -> 1.5 | H47: 0.015 | I47: =IF(H46<=C47,H46*H47,0) -> 0 | J47: =C47*K47 -> 1.5 | K47: 0.015 | L47: =IF(J46<=C47,J46*K47,0) -> 0 | M47: =C47*N47 -> 1.5 | N47: 0.015 | O47: =IF(M46<=C47,M46*N47,0) -> 0 | P47: =C47*Q47 -> 1 | Q47: 0.01 | R47: =IF(P46<=C47,P46*Q47,0) -> 0
...

Sheet 分年计划及建设期利息
B1: 工期起始 | C1: 45108.9 | D1: 月数汇总 | F1: 资金来源 | G1: 金额（万元） | H1: 占比 | K1: ☜该色块为需手动输入
B2: 工期结束 | C2: 45535 | D2: =(YEAR(C2)-YEAR(C1))*12 -> 12 | F2: 资本金 | G2: =G4-G3 -> 13000 | H2: =G2/$G$4 -> 0.59090909 | K2: ☜出现该色块的单元格为报错格
B3: 建设年度 | C3: 建设年度起 | D3: 建设年度止 | F3: 发债金额 | G3: 9000 | H3: =G3/$G$4 -> 0.40909091
B4: 第一年度 | C4: =C1 -> 45108.9 | D4: =EOMONTH(C4,11) -> 45473 | F4: 总投资 | G4: =总投资估算!G95 -> 22000 | H4: =G4/$G$4 -> 1
B5: 第二年度 | C5: =EOMONTH(D4,1) -> 45504 | D5: =EOMONTH(C5,11) -> 45838
B6: 第三年度 | C6: =EOMONTH(D5,1) -> 45869 | D6: =C2 -> 45535
B8: 表1-分年资金使用
B9: 序号 | C9: 项目 | D9: 合计 | E9: 建设期 | I9: 检查列
E10: 2025 | F10: 2026 | G10: =F10+1 -> 2027 | H10: =G10+1 -> 2028
B11: 一 | C11: 进度安排
B12: 1 | C12: 建设进度 | D12: =SUM(E12:H12) -> 1 | E12: 0.6 | F12: 0.4 | G12: =1-F12-E12 -> 0 | H12: 0 | I12: =SUM(E12:H12) -> 1
B13: 2 | C13: 其他费投入进度 | D13: =SUM(E13:H13) -> 1 | E13: 0.6 | F13: 0.4 | G13: =1-F13-E13 -> 0 | H13: 0 | I13: =SUM(E13:H13) -> 1
B14: 3 | C14: 专项债投入进度 | D14: =SUM(E14:H14) -> 1 | E14: 1 | F14: 0 | G14: =1-F14-E14 -> 0 | H14: 0 | I14: =SUM(E14:H14) -> 1
B15: 二 | C15: 总投资 | D15: =D16+D20 -> 22000 | E15: =E16+E20 -> 13173.01 | F15: =F16+F20 -> 8826.99 | H15: =H16+H20 -> 0 | I15: =SUM(E15:H15) -> 22000 | J15: =I15-D15 -> 0
B16: 1 | C16: 建设投资 | D16: =SUM(E16:H16) -> 21730 | E16: =E17+E18+E19 -> 13038.01 | F16: =F17+F18+F19 -> 8691.99 | G16: =G17+G18+G19 -> 0 | H16: =H17+H18+H19 -> 0 | I16: =SUM(E16:H16) -> 21730 | J16: =I16-D16 -> 0
B17: 1.1 | C17: 工程费用 | D17: =总投资估算!G3 -> 17385.78 | E17: =ROUND($D$17*E12,2) -> 10431.47 | F17: =ROUND($D$17*F12,2) -> 6954.31 | G17: =ROUND($D$17*G12,2) -> 0 | H17: =ROUND($D$17*H12,2) -> 0 | I17: =SUM(E17:H17) -> 17385.78 | J17: =I17-D17 -> 0
B18: 1.2 | C18: 工程建设其他费 | D18: =总投资估算!G70 -> 2754.06 | E18: =ROUND($D$18*E13,2) -> 1652.44 | F18: =ROUND($D$18*F13,2) -> 1101.62 | G18: =ROUND($D$18*G13,2) -> 0 | H18: =ROUND($D$18*H13,2) -> 0 | I18: =SUM(E18:H18) -> 2754.06 | J18: =I18-D18 -> 0
B19: 1.3 | C19: 基本预备费 | D19: =总投资估算!G90 -> 1590.16 | E19: =ROUND($D$19*E12,2) -> 954.1 | F19: =ROUND($D$19*F12,2) -> 636.06 | G19: =ROUND($D$19*G12,2) -> 0 | H19: =ROUND($D$19*H12,2) -> 0 | I19: =SUM(E19:H19) -> 1590.16 | J19: =I19-D19 -> 0
B20: 2 | C20: 建设期利息 | D20: =SUM(E20:H20) -> 270 | E20: =E23*0.03*0.5 -> 135 | F20: =E23*0.03*0.5+F23*0.03 -> 135 | G20: 0 | H20: 0 | I20: =SUM(E20:H20) -> 270 | J20: =I20-D20 -> 0
B21: 三 | C21: 资金筹措 | D21: =D22+D23 -> 22000 | E21: =E15 -> 13173.01 | F21: =F15 -> 8826.99 | G21: =G15 -> 0 | H21: =H15 -> 0 | I21: =SUM(E21:H21) -> 22000 | J21: =I21-D21 -> 0
B22: 1 | C22: 项目资本金 | D22: =G2 -> 13000 | E22: =E21-E23 -> 4173.01 | F22: =F21-F23 -> 8826.99 | G22: =G21-G23 -> 0 | H22: =H21-H23 -> 0 | I22: =SUM(E22:H22) -> 13000 | J22: =I22-D22 -> 0
B23: 2 | C23: 专项债券 | D23: =G3 -> 9000 | E23: =D23*E14 -> 9000 | F23: 0 | G23: =$D$23*G14 -> 0 | H23: =$D$23*H14 -> 0 | I23: =SUM(E23:H23) -> 9000 | J23: =I23-D23 -> 0

Sheet 信息采集表
A1: 填表注释：公式请勿修改 | B1: 黄色单元格需要填写 | C1: 此为测算结果
A2: 1、项目建设期运营期相关
A3: 项目实际情况：
A4: ①截止到填表日，本项目是否开工 | B4: 否
A5: ②本项目建设期 | B5: =DATEDIF(B6,B7+1,"M") -> 14 | C5: 个月。
A6: ③本项目建设期开工日期 | B6: =分年计划及建设期利息!C1 -> 45108.9 | C6: 如：202X年X月1日
A7: ④本项目建设期完工日期 | B7: =分年计划及建设期利息!C2 -> 45535 | C7: 如：202X年X月1日 | D7: =(B7-B6)/30-B5 -> 0.20333333 | E7: （④-③）/30-② | F7: 注意与B5单元格的勾稽关系
A9: 项目可研报告中数据情况：
A10: ⑤本项目建设期 | B10: =B5 -> 14 | C10: 个月。 | D10: =B10-B5 -> 0 | E10: ⑤-②
A11: ⑥本项目建设期开工日期 | B11: =B6 -> 45108.9 | C11: 如：202X年X月1日 | D11: =B11-B6 -> 0 | E11: ⑥-③ | F11: 如与项目实际情况存在较大差异。1、笔误等情况酌情修改可研；2、编制错误或是以前年度编制可研造成，考虑是否影响可研数据的准确性（以前年度编制的可研，依据的参考数据都是以前年度的，是否与现在情况存在偏差，是否合理）；
A12: ⑦本项目建设期完工日期 | B12: =B7 -> 45535 | C12: 如：202X年X月1日 | D12: =B12-B7 -> 0 | E12: ⑦-④
A13: ⑧建设工程费用 | B13: =分年计划及建设期利息!D17 -> 17385.78 | C13: =B13-B24 -> 0 | D13: ⑧-⑭ | E13: 此处进行测算，存在差异，则需找具体原因
A14: ⑨工程建设其他费用 | B14: =分年计划及建设期利息!D18 -> 2754.06 | C14: =B14-B25 -> 0 | D14: ⑨-⑮ | E14: 此处进行测算，存在差异，则需找具体原因
A15: ⑩预备费 | B15: =分年计划及建设期利息!D19 -> 1590.16 | C15: =B15-B26 -> 0 | D15: ⑩-⑯ | E15: 此处进行测算，存在差异，则需找具体原因
A16: ⑪建设期利息 | B16: =分年计划及建设期利息!D20 -> 270 | C16: =B16-B27 -> 0 | D16: ⑪-⑰ | E16: 此处进行测算，存在差异，则需找具体原因
A17: 合计 | B17: =SUM(B13:B16) -> 22000 | C17: =B17-B28 -> 0 | D17: 合计差异 | E17: 此处进行测算，存在差异，则需找具体原因
A19: 2、投资构成及分年度计划（万元）
A20: 可研批复文号
A21: ⑫可研批复金额 | B21: =B22 -> 22000 | C21: =B21-B22 -> 0 | D21: ⑫-⑬ | E21: 此处进行测算，存在差异，则需找具体原因
A22: ⑬可研总投资金额 | B22: =总投资估算!G95 -> 22000 | C22: =B28-B22 -> 0 | D22: ⑬-（⑭+⑮+⑯+⑰） | E22: 此处进行测算，存在差异，则需找具体原因
A23: 具体每年项目投资情况 | B23: 合计 | C23: 以前年度 | D23: 2022年 | E23: 2023年 | F23: 2024年 | G23: 2025年 | H23: 2026年 | I23: 2027年
A24: ⑭建设工程费用 | B24: =SUM(C24:I24) -> 17385.78 | D24: =分年计划及建设期利息!E17 -> 10431.47 | E24: =分年计划及建设期利息!F17 -> 6954.31 | F24: =分年计划及建设期利息!G17 -> 0 | G24: =分年计划及建设期利息!H17 -> 0
A25: ⑮工程建设其他费用 | B25: =SUM(C25:I25) -> 2754.06 | D25: =分年计划及建设期利息!E18 -> 1652.44 | E25: =分年计划及建设期利息!F18 -> 1101.62 | F25: =分年计划及建设期利息!G18 -> 0 | G25: =分年计划及建设期利息!H18 -> 0
A26: ⑯预备费 | B26: =SUM(C26:I26) -> 1590.16 | D26: =分年计划及建设期利息!E19 -> 954.1 | E26: =分年计划及建设期利息!F19 -> 636.06 | F26: =分年计划及建设期利息!G19 -> 0 | G26: =分年计划及建设期利息!H19 -> 0
A27: ⑰建设期利息 | B27: =SUM(C27:I27) -> 270 | D27: =分年计划及建设期利息!E20 -> 135 | E27: =分年计划及建设期利息!F20 -> 135 | F27: =分年计划及建设期利息!G20 -> 0 | G27: =分年计划及建设期利息!H20 -> 0
A28: 合计 | B28: =SUM(B24:B27) -> 22000 | C28: =SUM(C24:C27) -> 0 | D28: =SUM(D24:D27) -> 13173.01 | E28: =SUM(E24:E27) -> 8826.99 | F28: =SUM(F24:F27) -> 0 | G28: =SUM(G24:G27) -> 0 | H28: =SUM(H24:H27) -> 0 | I28: =SUM(I24:I27) -> 0 | J28: 此处数据请与建设期所填数据核对，是否勾稽，不要存在无建设期，但存在项目投资的情况
A29: 注：若项目已开工，以前年度的支出按实际支出金额填写；若项目截止目前还未开工，按未来计划支出金额分年度填写
A31: 3、项目建设期运营期相关（万元） | B31: =B28-B36 -> 0 | C31: （⑭+⑮+⑯+⑰）-（⑱+⑲+⑳） | E31: 此处进行测算，存在差异，则需找具体原因 | G31: =B33/B36 -> 0.59090909 | H31: ⑱/（⑱+⑲+⑳） | I31: 此处不能小于20%，资本金必须大于等于占比20%
A32: 项目筹资情况 | B32: 合计 | C32: 以前年度 | D32: 2022年 | E32: 2023年 | F32: 2024年 | G32: 2025年 | H32: 2026年 | I32: 2027年
A33: ⑱资本金 | B33: =SUM(C33:I33) -> 13000 | D33: =分年计划及建设期利息!E22 -> 4173.01 | E33: =分年计划及建设期利息!F22 -> 8826.99 | F33: =分年计划及建设期利息!G22 -> 0 | G33: =分年计划及建设期利息!H22 -> 0
A34: ⑲其他融资 | B34: =SUM(C34:I34) -> 0 | J34: 如果该列填数，则前面的资料，一定要囊括这部分的资料
A35: ⑳债券发行 | B35: =SUM(C35:I35) -> 9000 | D35: =分年计划及建设期利息!E23 -> 9000 | E35: =分年计划及建设期利息!F23 -> 0 | F35: =分年计划及建设期利息!G23 -> 0 | G35: =分年计划及建设期利息!H23 -> 0
A36: 合计 | B36: =SUM(C36:I36) -> 22000 | C36: =SUM(C33:C35) -> 0 | D36: =SUM(D33:D35) -> 13173.01 | E36: =SUM(E33:E35) -> 8826.99 | F36: =SUM(F33:F35) -> 0 | G36: =SUM(G33:G35) -> 0 | H36: =SUM(H33:H35) -> 0 | I36: =SUM(I33:I35) -> 0
A37: 注：此列允许存在差异：如果是负数，则填列无误；如果是正数，则需修改发行债券分年计划，因此当年发债金额不允许大于当年投资金额 | D37: =D35-D28 -> -4173.01 | E37: =E35-E28 -> -8826.99 | F37: =F35-F28 -> 0 | G37: =G35-G28 -> 0 | H37: =H35-H28 -> 0 | I37: =I35-I28 -> 0

Sheet 还本付息
H2: 金额单位：人民币万元
B3: 年度 | C3: 期初本金余额 | D3: 本年发放 | E3: 本期偿还本金 | F3: 期末本金余额 | G3: 融资利率 | H3: 应付利息 | I3: 本息合计
B5: 1 | C5: 0 | D5: 9000 | F5: =C5+D5-E5 -> 9000 | G5: 0.03 | H5: =F5*G5 -> 270 | I5: =E5+H5 -> 270
B6: 2 | C6: =F5 -> 9000 | D6: 0 | F6: =C6+D6-E6 -> 9000 | G6: =G5 -> 0.03 | H6: =(C6+D6)*G6 -> 270 | I6: =E6+H6 -> 270
B7: 3 | C7: =F6 -> 9000 | D7: =分年计划及建设期利息!G23 -> 0 | F7: =C7+D7-E7 -> 9000 | G7: =G6 -> 0.03 | H7: =(C7+D7)*G7 -> 270 | I7: =E7+H7 -> 270
B8: 4 | C8: =F7 -> 9000 | D8: =分年计划及建设期利息!H23 -> 0 | F8: =C8+D8-E8 -> 9000 | G8: =G7 -> 0.03 | H8: =(C8+D8)*G8 -> 270 | I8: =E8+H8 -> 270
B9: 5 | C9: =F8 -> 9000 | F9: =C9+D9-E9 -> 9000 | G9: =G8 -> 0.03 | H9: =(C9+D9)*G9 -> 270 | I9: =E9+H9 -> 270
B10: 6 | C10: =F9 -> 9000 | F10: =C10+D10-E10 -> 9000 | G10: =G9 -> 0.03 | H10: =(C10+D10)*G10 -> 270 | I10: =E10+H10 -> 270
B11: 7 | C11: =F10 -> 9000 | F11: =C11+D11-E11 -> 9000 | G11: =G10 -> 0.03 | H11: =(C11+D11)*G11 -> 270 | I11: =E11+H11 -> 270
B12: 8 | C12: =F11 -> 9000 | F12: =C12+D12-E12 -> 9000 | G12: =G11 -> 0.03 | H12: =(C12+D12)*G12 -> 270 | I12: =E12+H12 -> 270
B13: 9 | C13: =F12 -> 9000 | F13: =C13+D13-E13 -> 9000 | G13: =G12 -> 0.03 | H13: =(C13+D13)*G13 -> 270 | I13: =E13+H13 -> 270
B14: 10 | C14: =F13 -> 9000 | F14: =C14+D14-E14 -> 9000 | G14: =G13 -> 0.03 | H14: =(C14+D14)*G14 -> 270 | I14: =E14+H14 -> 270
B15: 11 | C15: =F14 -> 9000 | F15: =C15+D15-E15 -> 9000 | G15: =G14 -> 0.03 | H15: =(C15+D15)*G15 -> 270 | I15: =E15+H15 -> 270
B16: 12 | C16: =F15 -> 9000 | F16: =C16+D16-E16 -> 9000 | G16: =G15 -> 0.03 | H16: =(C16+D16)*G16 -> 270 | I16: =E16+H16 -> 270
B17: 13 | C17: =F16 -> 9000 | F17: =C17+D17-E17 -> 9000 | G17: =G16 -> 0.03 | H17: =(C17+D17)*G17 -> 270 | I17: =E17+H17 -> 270
B18: 14 | C18: =F17 -> 9000 | F18: =C18+D18-E18 -> 9000 | G18: =G17 -> 0.03 | H18: =(C18+D18)*G18 -> 270 | I18: =E18+H18 -> 270
B19: 15 | C19: =F18 -> 9000 | F19: =C19+D19-E19 -> 9000 | G19: =G18 -> 0.03 | H19: =(C19+D19)*G19 -> 270 | I19: =E19+H19 -> 270
B20: 16 | C20: =F19 -> 9000 | F20: =C20+D20-E20 -> 9000 | G20: =G19 -> 0.03 | H20: =(C20+D20)*G20 -> 270 | I20: =E20+H20 -> 270
... B33: 29 | C33: =F32 -> 9000 | F33: =C33+D33-E33 -> 9000 | G33: =G32 -> 0.03 | H33: =(C33+D33)*G33 -> 270 | I33: =E33+H33 -> 270
B34: 30 | C34: =F33 -> 9000 | E34: =D5 -> 9000 | F34: =C34+D34-E34 -> 0 | G34: =G33 -> 0.03 | H34: =(C34+D34)*G34 -> 270 | I34: =E34+H34 -> 9270
B35: 31 | C35: =F34 -> 0 | E35: =D6 -> 0 | F35: =C35+D35-E35 -> 0 | G35: =G34 -> 0.03 | H35: =(C35+D35)*G35 -> 0 | I35: =E35+H35 -> 0
B36: 32 | C36: =F35 -> 0 | E36: =D7 -> 0 | F36: =C36+D36-E36 -> 0 | G36: =G35 -> 0.03 | H36: =(C36+D36)*G36 -> 0 | I36: =E36+H36 -> 0
B37: 33 | C37: =F36 -> 0 | E37: =D8 -> 0 | F37: =C37+D37-E37 -> 0 | G37: =G36 -> 0.03 | H37: =(C37+D37)*G37 -> 0 | I37: =E37+H37 -> 0
B38: 合计 | E38: =SUM(E5:E37) -> 9000 | H38: =SUM(H5:H37) -> 8100 | I38: =SUM(I5:I37) -> 17100
H41: =E38*4.5%*30 -> 12150

Sheet 收入成本
A1: 周期 | B1: 年度 | C1: 种植基地出租收入 | H1: 停车位收入 | L1: 充电桩收入 | R1: 物业收入 | V1: 厂房出租收入 | Z1: 经营收 入合计 | AB1: 修理费占比折旧（自行键入） | AG1: 0.05 | AI1: 金额单位：人民币万元
C2: 负荷率 | D2: 出租价格（元/年·亩） | E2: 出租价格（元/年·亩） | F2: 数量（亩） | G2: 年运营收入（万元） | H2: 负荷率 | I2: 单价 | J2: 数量 | K2: 年运营收入（万元） | L2: 负荷率 | M2: 单价（元/kwh) | N2: 收费数量（个） | O2: 充电桩功率（kw） | P2: 日充电时长 | Q2: 年运营收入（万元） | R2: 负荷率 | S2: 单价 （元/月） | T2: 出租面积 | U2: 年运营收入（万元） | V2: 负荷率 | W2: 单价 （元/月） | X2: 出租面积 | Y2: 年运营收入（万元） | AC2: 年度 | AD2: 外购原材料费 | AE2: 外购燃料动力 | AF2: 工资福利费用 | AG2: 年维修成本 | AH2: 污泥处理费 | AI2: 其他费用 | AJ2: 税费 | AK2: 经营成本合计 | AL2: =资金流入流出平衡表!A20 -> 业务成本流出
AD3: 0.03 | AE3: 0.05 | AG3: 0.05 | AI3: 0.02
A4: 建设期 | B4: 1 | AA4: 地下停车场收入 | AC4: 1 | AE4: =ROUND(Z4*3%,2) -> 0
A5: 运营期 | B5: 2 | C5: 0.5 | D5: 850 | E5: 0 | F5: 113.76 | G5: =ROUND(D5*F5*C5/10000,2) -> 4.83 | H5: 0.4 | I5: 8 | J5: 265 | K5: =ROUND(J5*I5*H5*365/10000,2) -> 30.95 | L5: 0.3 | M5: 0.6 | N5: 40 | O5: 120 | P5: 2 | Q5: =ROUND(L5*M5*N5*330*P5*O5/10000,2) -> 57.02 | R5: =V5 -> 0.5 | S5: 0 | T5: =X5 -> 28489 | U5: =T5*S5*R5*12/10000 -> 0 | V5: =C5 -> 0.5 | W5: 35 | X5: =8400+20089 -> 28489 | Y5: =ROUND(X5*W5*V5*12/10000,2) -> 598.27 | Z5: =ROUND(G5+K5+Y5+Q5,2) -> 691.07 | AA5: 122.36 | AB5: 运营期 | AC5: 2 | AE5: =Z5*5% -> 34.5535 | AF5: =ROUND((项目技术经济指标!I10*项目技术经济指标!J10+项目技术经济指标!K10*项目技术经济指标!L10)*12/10000,2) -> 99 | AG5: =ROUND(固定资产折旧!$E$17*$AG$1,2) -> 35.09 | AI5: =ROUND(Z5*$AI$3,2) -> 13.82 | AJ5: =税费计算!O6 -> 71.79 | AK5: =ROUND(SUM(AD5:AJ5),2) -> 254.25 | AL5: =SUM(AE5:AI5) -> 182.4635
B6: 3 | C6: =C5+5% -> 0.55 | D6: =D5 -> 850 | E6: =E5 -> 0 | F6: =F5 -> 113.76 | G6: =ROUND(D6*F6*C6/10000,2) -> 5.32 | H6: =H5+5% -> 0.45 | I6: =I5 -> 8 | J6: =J5 -> 265 | K6: =ROUND(J6*I6*H6*365/10000,2) -> 34.82 | L6: =L5+10% -> 0.4 | M6: =M5 -> 0.6 | N6: =N5 -> 40 | O6: =O5 -> 120 | P6: =P5 -> 2 | Q6: =ROUND(L6*M6*N6*330*P6*O6/10000,2) -> 76.03 | R6: =V6 -> 0.55 | S6: =S5 -> 0 | T6: =X6 -> 28489 | U6: =T6*S6*R6*12/10000 -> 0 | V6: =C6 -> 0.55 | W6: =W5 -> 35 | X6: =X5 -> 28489 | Y6: =ROUND(X6*W6*V6*12/10000,2) -> 658.1 | Z6: =ROUND(G6+K6+Y6+Q6,2) -> 774.27 | AA6: 132.56 | AC6: 3 | AE6: =Z6*5% -> 38.7135 | AF6: =AF5 -> 99 | AG6: =ROUND(固定资产折旧!$E$17*$AG$1,2) -> 35.09 | AH6: 0 | AI6: =ROUND(Z6*$AI$3,2) -> 15.49 | AJ6: =税费计算!O7 -> 78.97 | AK6: =ROUND(SUM(AD6:AJ6),2) -> 267.26 | AL6: =SUM(AE6:AI6) -> 188.2935
B7: 4 | C7: =C6+5% -> 0.6 | D7: =D6 -> 850 | E7: =E6 -> 0 | F7: =F6 -> 113.76 | G7: =ROUND(D7*F7*C7/10000,2) -> 5.8 | H7: =H6+5% -> 0.5 | I7: =I6 -> 8 | J7: =J6 -> 265 | K7: =ROUND(J7*I7*H7*365/10000,2) -> 38.69 | L7: =L6+10% -> 0.5 | M7: =M6 -> 0.6 | N7: =N6 -> 40 | O7: =O6 -> 120 | P7: =P6 -> 2 | Q7: =ROUND(L7*M7*N7*330*P7*O7/10000,2) -> 95.04 | R7: =V7 -> 0.6 | S7: =S6 -> 0 | T7: =X7 -> 28489 | U7: =T7*S7*R7*12/10000 -> 0 | V7: =C7 -> 0.6 | W7: =W6 -> 35 | X7: =X6 -> 28489 | Y7: =ROUND(X7*W7*V7*12/10000,2) -> 717.92 | Z7: =ROUND(G7+K7+Y7+Q7,2) -> 857.45 | AA7: 142.76 | AC7: 4 | AE7: =Z7*5% -> 42.8725 | AF7: =AF6 -> 99 | AG7: =ROUND(固定资产折旧!$E$17*$AG$1,2) -> 35.09 | AH7: =AH6 -> 0 | AI7: =ROUND(Z7*$AI$3,2) -> 17.15 | AJ7: =税费计算!O8 -> 86.15 | AK7: =ROUND(SUM(AD7:AJ7),2) -> 280.26 | AL7: =SUM(AE7:AI7) -> 194.1125
B8: 5 | C8: =C7+5% -> 0.65 | D8: =D7 -> 850 | E8: =E7 -> 0 | F8: =F7 -> 113.76 | G8: =ROUND(D8*F8*C8/10000,2) -> 6.29 | H8: =L8+5% -> 0.6 | I8: =I7 -> 8 | J8: =J7 -> 265 | K8: =ROUND(J8*I8*H8*365/10000,2) -> 46.43 | L8: =L7+5% -> 0.55 | M8: =M7 -> 0.6 | N8: =N7 -> 40 | O8: =O7 -> 120 | P8: =P7 -> 2 | Q8: =ROUND(L8*M8*N8*330*P8*O8/10000,2) -> 104.54 | R8: =V8 -> 0.65 | S8: =S7 -> 0 | T8: =X8 -> 28489 | U8: =T8*S8*R8*12/10000 -> 0 | V8: =C8 -> 0.65 | W8: =W7 -> 35 | X8: =X7 -> 28489 | Y8: =ROUND(X8*W8*V8*12/10000,2) -> 777.75 | Z8: =ROUND(G8+K8+Y8+Q8,2) -> 935.01 | AA8: 152.96 | AC8: 5 | AE8: =Z8*5% -> 46.7505 | AF8: =AF7 -> 99 | AG8: =ROUND(固定资产折旧!$E$17*$AG$1,2) -> 35.09 | AH8: =AH7 -> 0 | AI8: =ROUND(Z8*$AI$3,2) -> 18.7 | AJ8: =税费计算!O9 -> 93.33 | AK8: =ROUND(SUM(AD8:AJ8),2) -> 292.87 | AL8: =SUM(AE8:AI8) -> 199.5405
B9: 6 | C9: =C8+5% -> 0.7 | D9: =D8 -> 850 | E9: =E8 -> 0 | F9: =F8 -> 113.76 | G9: =ROUND(D9*F9*C9/10000,2) -> 6.77 | H9: 0.6 | I9: =I8 -> 8 | J9: =J8 -> 265 | K9: =ROUND(J9*I9*H9*365/10000,2) -> 46.43 | L9: =L8+5% -> 0.6 | M9: =M8 -> 0.6 | N9: =N8 -> 40 | O9: =O8 -> 120 | P9: =P8 -> 2 | Q9: =ROUND(L9*M9*N9*330*P9*O9/10000,2) -> 114.05 | R9: =V9 -> 0.7 | S9: =S8 -> 0 | T9: =X9 -> 28489 | U9: =T9*S9*R9*12/10000 -> 0 | V9: =C9 -> 0.7 | W9: =W8 -> 35 | X9: =X8 -> 28489 | Y9: =ROUND(X9*W9*V9*12/10000,2) -> 837.58 | Z9: =ROUND(G9+K9+Y9+Q9,2) -> 1004.83 | AA9: 163.15 | AC9: 6 | AE9: =Z9*5% -> 50.2415 | AF9: =AF8 -> 99 | AG9: =ROUND(固定资产折旧!$E$17*$AG$1,2) -> 35.09 | AH9: =AH8 -> 0 | AI9: =ROUND(Z9*$AI$3,2) -> 20.1 | AJ9: =税费计算!O10 -> 100.51 | AK9: =ROUND(SUM(AD9:AJ9),2) -> 304.94 | AL9: =SUM(AE9:AI9) -> 204.4315
B10: 7 | C10: =C9+5% -> 0.75 | D10: =ROUND(D5*1.05,2) -> 892.5 | E10: =E9 -> 0 | F10: =F9 -> 113.76 | G10: =ROUND(D10*F10*C10/10000,2) -> 7.61 | H10: =H9+5% -> 0.65 | I10: =ROUND(I9*1.05,2) -> 8.4 | J10: =J9 -> 265 | K10: =ROUND(J10*I10*H10*365/10000,2) -> 52.81 | L10: =L9 -> 0.6 | M10: =M5*1.1 -> 0.66 | N10: =N9 -> 40 | O10: =O9 -> 120 | P10: =P9 -> 2 | Q10: =ROUND(L10*M10*N10*330*P10*O10/10000,2) -> 125.45 | R10: =V10 -> 0.75 | S10: =S9*1.05 -> 0 | T10: =X10 -> 28489 | U10: =T10*S10*R10*12/10000 -> 0 | V10: =C10 -> 0.75 | W10: =ROUND(W9*1.05,2) -> 36.75 | X10: =X9 -> 28489 | Y10: =ROUND(X10*W10*V10*12/10000,2) -> 942.27 | Z10: =ROUND(G10+K10+Y10+Q10,2) -> 1128.14 | AA10: 190.68 | AC10: 7 | AE10: =Z10*5% -> 56.407 | AF10: =AF5*(1+项目技术经济指标!$M$10) -> 108.9 | AG10: =AG5*(1+$AG$3) -> 36.8445 | AH10: =AH9 -> 0 | AI10: =ROUND(Z10*$AI$3,2) -> 22.56 | AJ10: =税费计算!O11 -> 113.07 | AK10: =ROUND(SUM(AD10:AJ10),2) -> 337.78 | AL10: =SUM(AE10:AI10) -> 224.7115 | AN10: 69.7
B11: 8 | C11: =C10 -> 0.75 | D11: =ROUND(D6*1.05,2) -> 892.5 | E11: =E10 -> 0 | F11: =F10 -> 113.76 | G11: =ROUND(D11*F11*C11/10000,2) -> 7.61 | H11: =H10 -> 0.65 | I11: =I10 -> 8.4 | J11: =J10 -> 265 | K11: =ROUND(J11*I11*H11*365/10000,2) -> 52.81 | L11: =L10 -> 0.6 | M11: =M6*1.1 -> 0.66 | N11: =N10 -> 40 | O11: =O10 -> 120 | P11: =P10 -> 2 | Q11: =ROUND(L11*M11*N11*330*P11*O11/10000,2) -> 125.45 | R11: =V11 -> 0.75 | S11: =S10 -> 0 | T11: =X11 -> 28489 | U11: =T11*S11*R11*12/10000 -> 0 | V11: =C11 -> 0.75 | W11: =W10 -> 36.75 | X11: =X10 -> 28489 | Y11: =ROUND(X11*W11*V11*12/10000,2) -> 942.27 | Z11: =ROUND(G11+K11+Y11+Q11,2) -> 1128.14 | AA11: 190.68 | AC11: 8 | AE11: =Z11*5% -> 56.407 | AF11: =AF6*(1+项目技术经济指标!$M$10) -> 108.9 | AG11: =AG6*(1+$AG$3) -> 36.8445 | AH11: =AH10 -> 0 | AI11: =ROUND(Z11*$AI$3,2) -> 22.56 | AJ11: =税费计算!O12 -> 113.07 | AK11: =ROUND(SUM(AD11:AJ11),2) -> 337.78 | AL11: =SUM(AE11:AI11) -> 224.7115 | AN11: 200
B12: 9 | C12: =C11 -> 0.75 | D12: =ROUND(D7*1.05,2) -> 892.5 | E12: =E11 -> 0 | F12: =F11 -> 113.76 | G12: =ROUND(D12*F12*C12/10000,2) -> 7.61 | H12: =H11 -> 0.65 | I12: =I11 -> 8.4 | J12: =J11 -> 265 | K12: =ROUND(J12*I12*H12*365/10000,2) -> 52.81 | L12: =L11 -> 0.6 | M12: =M7*1.1 -> 0.66 | N12: =N11 -> 40 | O12: =O11 -> 120 | P12: =P11 -> 2 | Q12: =ROUND(L12*M12*N12*330*P12*O12/10000,2) -> 125.45 | R12: =V12 -> 0.75 | S12: =S11 -> 0 | T12: =X12 -> 28489 | U12: =T12*S12*R12*12/10000 -> 0 | V12: =C12 -> 0.75 | W12: =W11 -> 36.75 | X12: =X11 -> 28489 | Y12: =ROUND(X12*W12*V12*12/10000,2) -> 942.27 | Z12: =ROUND(G12+K12+Y12+Q12,2) -> 1128.14 | AA12: 190.68 | AC12: 9 | AE12: =Z12*5% -> 56.407 | AF12: =AF7*(1+项目技术经济指标!$M$10) -> 108.9 | AG12: =AG7*(1+$AG$3) -> 36.8445 | AH12: =AH11 -> 0 | AI12: =ROUND(Z12*$AI$3,2) -> 22.56 | AJ12: =税费计算!O13 -> 113.07 | AK12: =ROUND(SUM(AD12:AJ12),2) -> 337.78 | AL12: =SUM(AE12:AI12) -> 224.7115 | AN12: 50
B13: 10 | C13: =C12 -> 0.75 | D13: =ROUND(D8*1.05,2) -> 892.5 | E13: =E12 -> 0 | F13: =F12 -> 113.76 | G13: =ROUND(D13*F13*C13/10000,2) -> 7.61 | H13: =H12 -> 0.65 | I13: =I12 -> 8.4 | J13: =J12 -> 265 | K13: =ROUND(J13*I13*H13*365/10000,2) -> 52.81 | L13: =L12 -> 0.6 | M13: =M8*1.1 -> 0.66 | N13: =N12 -> 40 | O13: =O12 -> 120 | P13: =P12 -> 2 | Q13: =ROUND(L13*M13*N13*330*P13*O13/10000,2) -> 125.45 | R13: =V13 -> 0.75 | S13: =S12 -> 0 | T13: =X13 -> 28489 | U13: =T13*S13*R13*12/10000 -> 0 | V13: =C13 -> 0.75 | W13: =W12 -> 36.75 | X13: =X12 -> 28489 | Y13: =ROUND(X13*W13*V13*12/10000,2) -> 942.27 | Z13: =ROUND(G13+K13+Y13+Q13,2) -> 1128.14 | AA13: 190.68 | AC13: 10 | AE13: =Z13*5% -> 56.407 | AF13: =AF8*(1+项目技术经济指标!$M$10) -> 108.9 | AG13: =AG8*(1+$AG$3) -> 36.8445 | AH13: =AH12 -> 0 | AI13: =ROUND(Z13*$AI$3,2) -> 22.56 | AJ13: =税费计算!O14 -> 113.07 | AK13: =ROUND(SUM(AD13:AJ13),2) -> 337.78 | AL13: =SUM(AE13:AI13) -> 224.7115 | AN13: 100
B14: 11 | C14: =C13 -> 0.75 | D14: =ROUND(D9*1.05,2) -> 892.5 | E14: =E13 -> 0 | F14: =F13 -> 113.76 | G14: =ROUND(D14*F14*C14/10000,2) -> 7.61 | H14: =H13 -> 0.65 | I14: =I13 -> 8.4 | J14: =J13 -> 265 | K14: =ROUND(J14*I14*H14*365/10000,2) -> 52.81 | L14: =L13 -> 0.6 | M14: =M9*1.1 -> 0.66 | N14: =N13 -> 40 | O14: =O13 -> 120 | P14: =P13 -> 2 | Q14: =ROUND(L14*M14*N14*330*P14*O14/10000,2) -> 125.45 | R14: =V14 -> 0.75 | S14: =S13 -> 0 | T14: =X14 -> 28489 | U14: =T14*S14*R14*12/10000 -> 0 | V14: =C14 -> 0.75 | W14: =W13 -> 36.75 | X14: =X13 -> 28489 | Y14: =ROUND(X14*W14*V14*12/10000,2) -> 942.27 | Z14: =ROUND(G14+K14+Y14+Q14,2) -> 1128.14 | AA14: 190.68 | AC14: 11 | AE14: =Z14*5% -> 56.407 | AF14: =AF9*(1+项目技术经济指标!$M$10) -> 108.9 | AG14: =AG9*(1+$AG$3) -> 36.8445 | AH14: =AH13 -> 0 | AI14: =ROUND(Z14*$AI$3,2) -> 22.56 | AJ14: =税费计算!O15 -> 113.07 | AK14: =ROUND(SUM(AD14:AJ14),2) -> 337.78 | AL14: =SUM(AE14:AI14) -> 224.7115 | AN14: 26.7
B15: 12 | C15: =C14 -> 0.75 | D15: =ROUND(D10*1.05,2) -> 937.13 | E15: =E14 -> 0 | F15: =F14 -> 113.76 | G15: =ROUND(D15*F15*C15/10000,2) -> 8 | H15: =H14 -> 0.65 | I15: =ROUND(I14*1.05,2) -> 8.82 | J15: =J14 -> 265 | K15: =ROUND(J15*I15*H15*365/10000,2) -> 55.45 | L15: =L14 -> 0.6 | M15: =M10*1.1 -> 0.726 | N15: =N14 -> 40 | O15: =O14 -> 120 | P15: =P14 -> 2 | Q15: =ROUND(L15*M15*N15*330*P15*O15/10000,2) -> 138 | R15: =V15 -> 0.75 | S15: =S14*1.05 -> 0 | T15: =X15 -> 28489 | U15: =T15*S15*R15*12/10000 -> 0 | V15: =C15 -> 0.75 | W15: =ROUND(W14*1.05,2) -> 38.59 | X15: =X14 -> 28489 | Y15: =ROUND(X15*W15*V15*12/10000,2) -> 989.45 | Z15: =ROUND(G15+K15+Y15+Q15,2) -> 1190.9 | AA15: 209.75 | AC15: 12 | AE15: =Z15*5% -> 59.545 | AF15: =AF10*(1+项目技术经济指标!$M$10) -> 119.79 | AG15: =AG10*(1+$AG$3) -> 38.686725 | AH15: =AH14 -> 0 | AI15: =ROUND(Z15*$AI$3,2) -> 23.82 | AJ15: =税费计算!O16 -> 118.73 | AK15: =ROUND(SUM(AD15:AJ15),2) -> 360.57 | AL15: =SUM(AE15:AI15) -> 241.84172 | AN15: 87.6
B16: 13 | C16: =C15 -> 0.75 | D16: =ROUND(D11*1.05,2) -> 937.13 | E16: =E15 -> 0 | F16: =F15 -> 113.76 | G16: =ROUND(D16*F16*C16/10000,2) -> 8 | H16: =H15 -> 0.65 | I16: =I15 -> 8.82 | J16: =J15 -> 265 | K16: =ROUND(J16*I16*H16*365/10000,2) -> 55.45 | L16: =L15 -> 0.6 | M16: =M11*1.1 -> 0.726 | N16: =N15 -> 40 | O16: =O15 -> 120 | P16: =P15 -> 2 | Q16: =ROUND(L16*M16*N16*330*P16*O16/10000,2) -> 138 | R16: =V16 -> 0.75 | S16: =S15 -> 0 | T16: =X16 -> 28489 | U16: =T16*S16*R16*12/10000 -> 0 | V16: =C16 -> 0.75 | W16: =W15 -> 38.59 | X16: =X15 -> 28489 | Y16: =ROUND(X16*W16*V16*12/10000,2) -> 989.45 | Z16: =ROUND(G16+K16+Y16+Q16,2) -> 1190.9 | AA16: 209.75 | AC16: 13 | AE16: =Z16*5% -> 59.545 | AF16: =AF11*(1+项目技术经济指标!$M$10) -> 119.79 | AG16: =AG11*(1+$AG$3) -> 38.686725 | AH16: =AH15 -> 0 | AI16: =ROUND(Z16*$AI$3,2) -> 23.82 | AJ16: =税费计算!O17 -> 118.73 | AK16: =ROUND(SUM(AD16:AJ16),2) -> 360.57 | AL16: =SUM(AE16:AI16) -> 241.84172
B17: 14 | C17: =C16 -> 0.75 | D17: =ROUND(D12*1.05,2) -> 937.13 | E17: =E16 -> 0 | F17: =F16 -> 113.76 | G17: =ROUND(D17*F17*C17/10000,2) -> 8 | H17: =H16 -> 0.65 | I17: =I16 -> 8.82 | J17: =J16 -> 265 | K17: =ROUND(J17*I17*H17*365/10000,2) -> 55.45 | L17: =L16 -> 0.6 | M17: =M12*1.1 -> 0.726 | N17: =N16 -> 40 | O17: =O16 -> 120 | P17: =P16 -> 2 | Q17: =ROUND(L17*M17*N17*330*P17*O17/10000,2) -> 138 | R17: =V17 -> 0.75 | S17: =S16 -> 0 | T17: =X17 -> 28489 | U17: =T17*S17*R17*12/10000 -> 0 | V17: =C17 -> 0.75 | W17: =W16 -> 38.59 | X17: =X16 -> 28489 | Y17: =ROUND(X17*W17*V17*12/10000,2) -> 989.45 | Z17: =ROUND(G17+K17+Y17+Q17,2) -> 1190.9 | AA17: 209.75 | AC17: 14 | AE17: =Z17*5% -> 59.545 | AF17: =AF12*(1+项目技术经济指标!$M$10) -> 119.79 | AG17: =AG12*(1+$AG$3) -> 38.686725 | AH17: =AH16 -> 0 | AI17: =ROUND(Z17*$AI$3,2) -> 23.82 | AJ17: =税费计算!O18 -> 118.73 | AK17: =ROUND(SUM(AD17:AJ17),2) -> 360.57 | AL17: =SUM(AE17:AI17) -> 241.84172 | AM17: =SUM(AN10:AN15)+AM22 -> 558.22488
B18: 15 | C18: =C17 -> 0.75 | D18: =ROUND(D13*1.05,2) -> 937.13 | E18: =E17 -> 0 | F18: =F17 -> 113.76 | G18: =ROUND(D18*F18*C18/10000,2) -> 8 | H18: =H17 -> 0.65 | I18: =I17 -> 8.82 | J18: =J17 -> 265 | K18: =ROUND(J18*I18*H18*365/10000,2) -> 55.45 | L18: =L17 -> 0.6 | M18: =M13*1.1 -> 0.726 | N18: =N17 -> 40 | O18: =O17 -> 120 | P18: =P17 -> 2 | Q18: =ROUND(L18*M18*N18*330*P18*O18/10000,2) -> 138 | R18: =V18 -> 0.75 | S18: =S17 -> 0 | T18: =X18 -> 28489 | U18: =T18*S18*R18*12/10000 -> 0 | V18: =C18 -> 0.75 | W18: =W17 -> 38.59 | X18: =X17 -> 28489 | Y18: =ROUND(X18*W18*V18*12/10000,2) -> 989.45 | Z18: =ROUND(G18+K18+Y18+Q18,2) -> 1190.9 | AA18: 209.75 | AC18: 15 | AE18: =Z18*5% -> 59.545 | AF18: =AF13*(1+项目技术经济指标!$M$10) -> 119.79 | AG18: =AG13*(1+$AG$3) -> 38.686725 | AH18: =AH17 -> 0 | AI18: =ROUND(Z18*$AI$3,2) -> 23.82 | AJ18: =税费计算!O19 -> 118.73 | AK18: =ROUND(SUM(AD18:AJ18),2) -> 360.57 | AL18: =SUM(AE18:AI18) -> 241.84172
B19: 16 | C19: =C18 -> 0.75 | D19: =ROUND(D14*1.05,2) -> 937.13 | E19: =E18 -> 0 | F19: =F18 -> 113.76 | G19: =ROUND(D19*F19*C19/10000,2) -> 8 | H19: =H18 -> 0.65 | I19: =I18 -> 8.82 | J19: =J18 -> 265 | K19: =ROUND(J19*I19*H19*365/10000,2) -> 55.45 | L19: =L18 -> 0.6 | M19: =M14*1.1 -> 0.726 | N19: =N18 -> 40 | O19: =O18 -> 120 | P19: =P18 -> 2 | Q19: =ROUND(L19*M19*N19*330*P19*O19/10000,2) -> 138 | R19: =V19 -> 0.75 | S19: =S18 -> 0 | T19: =X19 -> 28489 | U19: =T19*S19*R19*12/10000 -> 0 | V19: =C19 -> 0.75 | W19: =W18 -> 38.59 | X19: =X18 -> 28489 | Y19: =ROUND(X19*W19*V19*12/10000,2) -> 989.45 | Z19: =ROUND(G19+K19+Y19+Q19,2) -> 1190.9 | AA19: 209.75 | AC19: 16 | AE19: =Z19*5% -> 59.545 | AF19: =AF14*(1+项目技术经济指标!$M$10) -> 119.79 | AG19: =AG14*(1+$AG$3) -> 38.686725 | AH19: =AH18 -> 0 | AI19: =ROUND(Z19*$AI$3,2) -> 23.82 | AJ19: =税费计算!O20 -> 118.73 | AK19: =ROUND(SUM(AD19:AJ19),2) -> 360.57 | AL19: =SUM(AE19:AI19) -> 241.84172
B20: 17 | C20: =C19 -> 0.75 | D20: =ROUND(D15*1.05,2) -> 983.99 | E20: =E19 -> 0 | F20: =F19 -> 113.76 | G20: =ROUND(D20*F20*C20/10000,2) -> 8.4 | H20: =H19 -> 0.65 | I20: =ROUND(I19*1.05,2) -> 9.26 | J20: =J19 -> 265 | K20: =ROUND(J20*I20*H20*365/10000,2) -> 58.22 | L20: =L19 -> 0.6 | M20: =M15*1.1 -> 0.7986 | N20: =N19 -> 40 | O20: =O19 -> 120 | P20: =P19 -> 2 | Q20: =ROUND(L20*M20*N20*330*P20*O20/10000,2) -> 151.8 | R20: =V20 -> 0.75 | S20: =S19*1.05 -> 0 | T20: =X20 -> 28489 | U20: =T20*S20*R20*12/10000 -> 0 | V20: =C20 -> 0.75 | W20: =ROUND(W19*1.05,2) -> 40.52 | X20: =X19 -> 28489 | Y20: =ROUND(X20*W20*V20*12/10000,2) -> 1038.94 | Z20: =ROUND(G20+K20+Y20+Q20,2) -> 1257.36 | AA20: 230.9 | AC20: 17 | AE20: =Z20*5% -> 62.868 | AF20: =AF15*(1+项目技术经济指标!$M$10) -> 131.769 | AG20: =AG15*(1+$AG$3) -> 40.621061 | AH20: =AH19 -> 0 | AI20: =ROUND(Z20*$AI$3,2) -> 25.15 | AJ20: =税费计算!O21 -> 158.05789 | AK20: =ROUND(SUM(AD20:AJ20),2) -> 418.47 | AL20: =SUM(AE20:AI20) -> 260.40806 | AN20: 4700
B21: 18 | C21: =C20 -> 0.75 | D21: =ROUND(D16*1.05,2) -> 983.99 | E21: =E20 -> 0 | F21: =F20 -> 113.76 | G21: =ROUND(D21*F21*C21/10000,2) -> 8.4 | H21: =H20 -> 0.65 | I21: =I20 -> 9.26 | J21: =J20 -> 265 | K21: =ROUND(J21*I21*H21*365/10000,2) -> 58.22 | L21: =L20 -> 0.6 | M21: =M16*1.1 -> 0.7986 | N21: =N20 -> 40 | O21: =O20 -> 120 | P21: =P20 -> 2 | Q21: =ROUND(L21*M21*N21*330*P21*O21/10000,2) -> 151.8 | R21: =V21 -> 0.75 | S21: =S20 -> 0 | T21: =X21 -> 28489 | U21: =T21*S21*R21*12/10000 -> 0 | V21: =C21 -> 0.75 | W21: =W20 -> 40.52 | X21: =X20 -> 28489 | Y21: =ROUND(X21*W21*V21*12/10000,2) -> 1038.94 | Z21: =ROUND(G21+K21+Y21+Q21,2) -> 1257.36 | AA21: 230.9 | AC21: 18 | AE21: =Z21*5% -> 62.868 | AF21: =AF16*(1+项目技术经济指标!$M$10) -> 131.769 | AG21: =AG16*(1+$AG$3) -> 40.621061 | AH21: =AH20 -> 0 | AI21: =ROUND(Z21*$AI$3,2) -> 25.15 | AJ21: =税费计算!O22 -> 243.52119 | AK21: =ROUND(SUM(AD21:AJ21),2) -> 503.93 | AL21: =SUM(AE21:AI21) -> 260.40806
B22: 19 | C22: =C21 -> 0.75 | D22: =ROUND(D17*1.05,2) -> 983.99 | E22: =E21 -> 0 | F22: =F21 -> 113.76 | G22: =ROUND(D22*F22*C22/10000,2) -> 8.4 | H22: =H21 -> 0.65 | I22: =I21 -> 9.26 | J22: =J21 -> 265 | K22: =ROUND(J22*I22*H22*365/10000,2) -> 58.22 | L22: =L21 -> 0.6 | M22: =M17*1.1 -> 0.7986 | N22: =N21 -> 40 | O22: =O21 -> 120 | P22: =P21 -> 2 | Q22: =ROUND(L22*M22*N22*330*P22*O22/10000,2) -> 151.8 | R22: =V22 -> 0.75 | S22: =S21 -> 0 | T22: =X22 -> 28489 | U22: =T22*S22*R22*12/10000 -> 0 | V22: =C22 -> 0.75 | W22: =W21 -> 40.52 | X22: =X21 -> 28489 | Y22: =ROUND(X22*W22*V22*12/10000,2) -> 1038.94 | Z22: =ROUND(G22+K22+Y22+Q22,2) -> 1257.36 | AA22: 230.9 | AC22: 19 | AE22: =Z22*5% -> 62.868 | AF22: =AF17*(1+项目技术经济指标!$M$10) -> 131.769 | AG22: =AG17*(1+$AG$3) -> 40.621061 | AH22: =AH21 -> 0 | AI22: =ROUND(Z22*$AI$3,2) -> 25.15 | AJ22: =税费计算!O23 -> 243.52119 | AK22: =ROUND(SUM(AD22:AJ22),2) -> 503.93 | AL22: =SUM(AE22:AI22) -> 260.40806 | AM22: =16150/666.67 -> 24.224879
B23: 20 | C23: =C22 -> 0.75 | D23: =ROUND(D18*1.05,2) -> 983.99 | E23: =E22 -> 0 | F23: =F22 -> 113.76 | G23: =ROUND(D23*F23*C23/10000,2) -> 8.4 | H23: =H22 -> 0.65 | I23: =I22 -> 9.26 | J23: =J22 -> 265 | K23: =ROUND(J23*I23*H23*365/10000,2) -> 58.22 | L23: =L22 -> 0.6 | M23: =M18*1.1 -> 0.7986 | N23: =N22 -> 40 | O23: =O22 -> 120 | P23: =P22 -> 2 | Q23: =ROUND(L23*M23*N23*330*P23*O23/10000,2) -> 151.8 | R23: =V23 -> 0.75 | S23: =S22 -> 0 | T23: =X23 -> 28489 | U23: =T23*S23*R23*12/10000 -> 0 | V23: =C23 -> 0.75 | W23: =W22 -> 40.52 | X23: =X22 -> 28489 | Y23: =ROUND(X23*W23*V23*12/10000,2) -> 1038.94 | Z23: =ROUND(G23+K23+Y23+Q23,2) -> 1257.36 | AA23: 230.9 | AC23: 20 | AE23: =Z23*5% -> 62.868 | AF23: =AF18*(1+项目技术经济指标!$M$10) -> 131.769 | AG23: =AG18*(1+$AG$3) -> 40.621061 | AH23: =AH22 -> 0 | AI23: =ROUND(Z23*$AI$3,2) -> 25.15 | AJ23: =税费计算!O24 -> 243.52119 | AK23: =ROUND(SUM(AD23:AJ23),2) -> 503.93 | AL23: =SUM(AE23:AI23) -> 260.40806
B24: 21 | C24: =C23 -> 0.75 | D24: =ROUND(D19*1.05,2) -> 983.99 | E24: =E23 -> 0 | F24: =F23 -> 113.76 | G24: =ROUND(D24*F24*C24/10000,2) -> 8.4 | H24: =H23 -> 0.65 | I24: =I23 -> 9.26 | J24: =J23 -> 265 | K24: =ROUND(J24*I24*H24*365/10000,2) -> 58.22 | L24: =L23 -> 0.6 | M24: =M19*1.1 -> 0.7986 | N24: =N23 -> 40 | O24: =O23 -> 120 | P24: =P23 -> 2 | Q24: =ROUND(L24*M24*N24*330*P24*O24/10000,2) -> 151.8 | R24: =V24 -> 0.75 | S24: =S23 -> 0 | T24: =X24 -> 28489 | U24: =T24*S24*R24*12/10000 -> 0 | V24: =C24 -> 0.75 | W24: =W23 -> 40.52 | X24: =X23 -> 28489 | Y24: =ROUND(X24*W24*V24*12/10000,2) -> 1038.94 | Z24: =ROUND(G24+K24+Y24+Q24,2) -> 1257.36 | AA24: 230.9 | AC24: 21 | AE24: =Z24*5% -> 62.868 | AF24: =AF19*(1+项目技术经济指标!$M$10) -> 131.769 | AG24: =AG19*(1+$AG$3) -> 40.621061 | AH24: =AH23 -> 0 | AI24: =ROUND(Z24*$AI$3,2) -> 25.15 | AJ24: =税费计算!O25 -> 243.52119 | AK24: =ROUND(SUM(AD24:AJ24),2) -> 503.93 | AL24: =SUM(AE24:AI24) -> 260.40806 | AN24: 1500
B25: 22 | C25: =C24 -> 0.75 | D25: =ROUND(D20*1.05,2) -> 1033.19 | E25: =E24 -> 0 | F25: =F24 -> 113.76 | G25: =ROUND(D25*F25*C25/10000,2) -> 8.82 | H25: =H24 -> 0.65 | I25: =ROUND(I24*1.05,2) -> 9.72 | J25: =J24 -> 265 | K25: =ROUND(J25*I25*H25*365/10000,2) -> 61.11 | L25: =L24 -> 0.6 | M25: =M20*1.1 -> 0.87846 | N25: =N24 -> 40 | O25: =O24 -> 120 | P25: =P24 -> 2 | Q25: =ROUND(L25*M25*N25*330*P25*O25/10000,2) -> 166.98 | R25: =V25 -> 0.75 | S25: =S24*1.05 -> 0 | T25: =X25 -> 28489 | U25: =T25*S25*R25*12/10000 -> 0 | V25: =C25 -> 0.75 | W25: =ROUND(W24*1.05,2) -> 42.55 | X25: =X24 -> 28489 | Y25: =ROUND(X25*W25*V25*12/10000,2) -> 1090.99 | Z25: =ROUND(G25+K25+Y25+Q25,2) -> 1327.9 | AA25: 254.13 | AC25: 22 | AE25: =Z25*5% -> 66.395 | AF25: =AF20*(1+项目技术经济指标!$M$10) -> 144.9459 | AG25: =AG20*(1+$AG$3) -> 42.652114 | AH25: =AH24 -> 0 | AI25: =ROUND(Z25*$AI$3,2) -> 26.56 | AJ25: =税费计算!O26 -> 256.69752 | AK25: =ROUND(SUM(AD25:AJ25),2) -> 537.25 | AL25: =SUM(AE25:AI25) -> 280.55301 | AN25: 2000
B26: 23 | C26: =C25 -> 0.75 | D26: =ROUND(D21*1.05,2) -> 1033.19 | E26: =E25 -> 0 | F26: =F25 -> 113.76 | G26: =ROUND(D26*F26*C26/10000,2) -> 8.82 | H26: =H25 -> 0.65 | I26: =I25 -> 9.72 | J26: =J25 -> 265 | K26: =ROUND(J26*I26*H26*365/10000,2) -> 61.11 | L26: =L25 -> 0.6 | M26: =M21*1.1 -> 0.87846 | N26: =N25 -> 40 | O26: =O25 -> 120 | P26: =P25 -> 2 | Q26: =ROUND(L26*M26*N26*330*P26*O26/10000,2) -> 166.98 | R26: =V26 -> 0.75 | S26: =S25 -> 0 | T26: =X26 -> 28489 | U26: =T26*S26*R26*12/10000 -> 0 | V26: =C26 -> 0.75 | W26: =W25 -> 42.55 | X26: =X25 -> 28489 | Y26: =ROUND(X26*W26*V26*12/10000,2) -> 1090.99 | Z26: =ROUND(G26+K26+Y26+Q26,2) -> 1327.9 | AA26: 254.13 | AC26: 23 | AE26: =Z26*5% -> 66.395 | AF26: =AF21*(1+项目技术经济指标!$M$10) -> 144.9459 | AG26: =AG21*(1+$AG$3) -> 42.652114 | AH26: =AH25 -> 0 | AI26: =ROUND(Z26*$AI$3,2) -> 26.56 | AJ26: =税费计算!O27 -> 256.69752 | AK26: =ROUND(SUM(AD26:AJ26),2) -> 537.25 | AL26: =SUM(AE26:AI26) -> 280.55301 | AN26: 600
B27: 24 | C27: =C26 -> 0.75 | D27: =ROUND(D22*1.05,2) -> 1033.19 | E27: =E26 -> 0 | F27: =F26 -> 113.76 | G27: =ROUND(D27*F27*C27/10000,2) -> 8.82 | H27: =H26 -> 0.65 | I27: =I26 -> 9.72 | J27: =J26 -> 265 | K27: =ROUND(J27*I27*H27*365/10000,2) -> 61.11 | L27: =L26 -> 0.6 | M27: =M22*1.1 -> 0.87846 | N27: =N26 -> 40 | O27: =O26 -> 120 | P27: =P26 -> 2 | Q27: =ROUND(L27*M27*N27*330*P27*O27/10000,2) -> 166.98 | R27: =V27 -> 0.75 | S27: =S26 -> 0 | T27: =X27 -> 28489 | U27: =T27*S27*R27*12/10000 -> 0 | V27: =C27 -> 0.75 | W27: =W26 -> 42.55 | X27: =X26 -> 28489 | Y27: =ROUND(X27*W27*V27*12/10000,2) -> 1090.99 | Z27: =ROUND(G27+K27+Y27+Q27,2) -> 1327.9 | AA27: 254.13 | AC27: 24 | AE27: =Z27*5% -> 66.395 | AF27: =AF22*(1+项目技术经济指标!$M$10) -> 144.9459 | AG27: =AG22*(1+$AG$3) -> 42.652114 | AH27: =AH26 -> 0 | AI27: =ROUND(Z27*$AI$3,2) -> 26.56 | AJ27: =税费计算!O28 -> 256.69752 | AK27: =ROUND(SUM(AD27:AJ27),2) -> 537.25 | AL27: =SUM(AE27:AI27) -> 280.55301 | AN27: 600
B28: 25 | C28: =C27 -> 0.75 | D28: =ROUND(D23*1.05,2) -> 1033.19 | E28: =E27 -> 0 | F28: =F27 -> 113.76 | G28: =ROUND(D28*F28*C28/10000,2) -> 8.82 | H28: =H27 -> 0.65 | I28: =I27 -> 9.72 | J28: =J27 -> 265 | K28: =ROUND(J28*I28*H28*365/10000,2) -> 61.11 | L28: =L27 -> 0.6 | M28: =M23*1.1 -> 0.87846 | N28: =N27 -> 40 | O28: =O27 -> 120 | P28: =P27 -> 2 | Q28: =ROUND(L28*M28*N28*330*P28*O28/10000,2) -> 166.98 | R28: =V28 -> 0.75 | S28: =S27 -> 0 | T28: =X28 -> 28489 | U28: =T28*S28*R28*12/10000 -> 0 | V28: =C28 -> 0.75 | W28: =W27 -> 42.55 | X28: =X27 -> 28489 | Y28: =ROUND(X28*W28*V28*12/10000,2) -> 1090.99 | Z28: =ROUND(G28+K28+Y28+Q28,2) -> 1327.9 | AA28: 254.13 | AC28: 25 | AE28: =Z28*5% -> 66.395 | AF28: =AF23*(1+项目技术经济指标!$M$10) -> 144.9459 | AG28: =AG23*(1+$AG$3) -> 42.652114 | AH28: =AH27 -> 0 | AI28: =ROUND(Z28*$AI$3,2) -> 26.56 | AJ28: =税费计算!O29 -> 256.69752 | AK28: =ROUND(SUM(AD28:AJ28),2) -> 537.25 | AL28: =SUM(AE28:AI28) -> 280.55301 | AN28: 1000
B29: 26 | C29: =C28 -> 0.75 | D29: =ROUND(D24*1.05,2) -> 1033.19 | E29: =E28 -> 0 | F29: =F28 -> 113.76 | G29: =ROUND(D29*F29*C29/10000,2) -> 8.82 | H29: =H28 -> 0.65 | I29: =I28 -> 9.72 | J29: =J28 -> 265 | K29: =ROUND(J29*I29*H29*365/10000,2) -> 61.11 | L29: =L28 -> 0.6 | M29: =M24*1.1 -> 0.87846 | N29: =N28 -> 40 | O29: =O28 -> 120 | P29: =P28 -> 2 | Q29: =ROUND(L29*M29*N29*330*P29*O29/10000,2) -> 166.98 | R29: =V29 -> 0.75 | S29: =S28 -> 0 | T29: =X29 -> 28489 | U29: =T29*S29*R29*12/10000 -> 0 | V29: =C29 -> 0.75 | W29: =W28 -> 42.55 | X29: =X28 -> 28489 | Y29: =ROUND(X29*W29*V29*12/10000,2) -> 1090.99 | Z29: =ROUND(G29+K29+Y29+Q29,2) -> 1327.9 | AA29: 254.13 | AC29: 26 | AE29: =Z29*5% -> 66.395 | AF29: =AF24*(1+项目技术经济指标!$M$10) -> 144.9459 | AG29: =AG24*(1+$AG$3) -> 42.652114 | AH29: =AH28 -> 0 | AI29: =ROUND(Z29*$AI$3,2) -> 26.56 | AJ29: =税费计算!O30 -> 256.69752 | AK29: =ROUND(SUM(AD29:AJ29),2) -> 537.25 | AL29: =SUM(AE29:AI29) -> 280.55301 | AN29: 1300
B30: 27 | C30: =C29 -> 0.75 | D30: =ROUND(D25*1.05,2) -> 1084.85 | E30: =E29 -> 0 | F30: =F29 -> 113.76 | G30: =ROUND(D30*F30*C30/10000,2) -> 9.26 | H30: =H29 -> 0.65 | I30: =ROUND(I29*1.05,2) -> 10.21 | J30: =J29 -> 265 | K30: =ROUND(J30*I30*H30*365/10000,2) -> 64.19 | L30: =L29 -> 0.6 | M30: =M25*1.1 -> 0.966306 | N30: =N29 -> 40 | O30: =O29 -> 120 | P30: =P29 -> 2 | Q30: =ROUND(L30*M30*N30*330*P30*O30/10000,2) -> 183.68 | R30: =V30 -> 0.75 | S30: =S29*1.05 -> 0 | T30: =X30 -> 28489 | U30: =T30*S30*R30*12/10000 -> 0 | V30: =C30 -> 0.75 | W30: =ROUND(W29*1.05,2) -> 44.68 | X30: =X29 -> 28489 | Y30: =ROUND(X30*W30*V30*12/10000,2) -> 1145.6 | Z30: =ROUND(G30+K30+Y30+Q30,2) -> 1402.73 | AA30: 279.44 | AC30: 27 | AE30: =Z30*5% -> 70.1365 | AF30: =AF25*(1+项目技术经济指标!$M$10) -> 159.44049 | AG30: =AG25*(1+$AG$3) -> 44.78472 | AH30: =AH29 -> 0 | AI30: =ROUND(Z30*$AI$3,2) -> 28.05 | AJ30: =税费计算!O31 -> 270.59092 | AK30: =ROUND(SUM(AD30:AJ30),2) -> 573 | AL30: =SUM(AE30:AI30) -> 302.41171 | AN30: 2000
B31: 28 | C31: =C30 -> 0.75 | D31: =ROUND(D26*1.05,2) -> 1084.85 | E31: =E30 -> 0 | F31: =F30 -> 113.76 | G31: =ROUND(D31*F31*C31/10000,2) -> 9.26 | H31: =H30 -> 0.65 | I31: =I30 -> 10.21 | J31: =J30 -> 265 | K31: =ROUND(J31*I31*H31*365/10000,2) -> 64.19 | L31: =L30 -> 0.6 | M31: =M26*1.1 -> 0.966306 | N31: =N30 -> 40 | O31: =O30 -> 120 | P31: =P30 -> 2 | Q31: =ROUND(L31*M31*N31*330*P31*O31/10000,2) -> 183.68 | R31: =V31 -> 0.75 | S31: =S30 -> 0 | T31: =X31 -> 28489 | U31: =T31*S31*R31*12/10000 -> 0 | V31: =C31 -> 0.75 | W31: =W30 -> 44.68 | X31: =X30 -> 28489 | Y31: =ROUND(X31*W31*V31*12/10000,2) -> 1145.6 | Z31: =ROUND(G31+K31+Y31+Q31,2) -> 1402.73 | AA31: 279.44 | AC31: 28 | AE31: =Z31*5% -> 70.1365 | AF31: =AF26*(1+项目技术经济指标!$M$10) -> 159.44049 | AG31: =AG26*(1+$AG$3) -> 44.78472 | AH31: =AH30 -> 0 | AI31: =ROUND(Z31*$AI$3,2) -> 28.05 | AJ31: =税费计算!O32 -> 270.59092 | AK31: =ROUND(SUM(AD31:AJ31),2) -> 573 | AL31: =SUM(AE31:AI31) -> 302.41171 | AN31: =490*5 -> 2450
B32: 29 | C32: =C31 -> 0.75 | D32: =ROUND(D27*1.05,2) -> 1084.85 | E32: =E31 -> 0 | F32: =F31 -> 113.76 | G32: =ROUND(D32*F32*C32/10000,2) -> 9.26 | H32: =H31 -> 0.65 | I32: =I31 -> 10.21 | J32: =J31 -> 265 | K32: =ROUND(J32*I32*H32*365/10000,2) -> 64.19 | L32: =L31 -> 0.6 | M32: =M27*1.1 -> 0.966306 | N32: =N31 -> 40 | O32: =O31 -> 120 | P32: =P31 -> 2 | Q32: =ROUND(L32*M32*N32*330*P32*O32/10000,2) -> 183.68 | R32: =V32 -> 0.75 | S32: =S31 -> 0 | T32: =X32 -> 28489 | U32: =T32*S32*R32*12/10000 -> 0 | V32: =C32 -> 0.75 | W32: =W31 -> 44.68 | X32: =X31 -> 28489 | Y32: =ROUND(X32*W32*V32*12/10000,2) -> 1145.6 | Z32: =ROUND(G32+K32+Y32+Q32,2) -> 1402.73 | AA32: 279.44 | AC32: 29 | AE32: =Z32*5% -> 70.1365 | AF32: =AF27*(1+项目技术经济指标!$M$10) -> 159.44049 | AG32: =AG27*(1+$AG$3) -> 44.78472 | AH32: =AH31 -> 0 | AI32: =ROUND(Z32*$AI$3,2) -> 28.05 | AJ32: =税费计算!O33 -> 270.59092 | AK32: =ROUND(SUM(AD32:AJ32),2) -> 573 | AL32: =SUM(AE32:AI32) -> 302.41171
B33: 30 | C33: =C32 -> 0.75 | D33: =ROUND(D28*1.05,2) -> 1084.85 | E33: =E32 -> 0 | F33: =F32 -> 113.76 | G33: =ROUND(D33*F33*C33/10000,2) -> 9.26 | H33: =H32 -> 0.65 | I33: =I32 -> 10.21 | J33: =J32 -> 265 | K33: =ROUND(J33*I33*H33*365/10000,2) -> 64.19 | L33: =L32 -> 0.6 | M33: =M28*1.1 -> 0.966306 | N33: =N32 -> 40 | O33: =O32 -> 120 | P33: =P32 -> 2 | Q33: =ROUND(L33*M33*N33*330*P33*O33/10000,2) -> 183.68 | R33: =V33 -> 0.75 | S33: =S32 -> 0 | T33: =X33 -> 28489 | U33: =T33*S33*R33*12/10000 -> 0 | V33: =C33 -> 0.75 | W33: =W32 -> 44.68 | X33: =X32 -> 28489 | Y33: =ROUND(X33*W33*V33*12/10000,2) -> 1145.6 | Z33: =ROUND(G33+K33+Y33+Q33,2) -> 1402.73 | AA33: 279.44 | AC33: 30 | AE33: =Z33*5% -> 70.1365 | AF33: =AF28*(1+项目技术经济指标!$M$10) -> 159.44049 | AG33: =AG28*(1+$AG$3) -> 44.78472 | AH33: =AH32 -> 0 | AI33: =ROUND(Z33*$AI$3,2) -> 28.05 | AJ33: =税费计算!O34 -> 270.59092 | AK33: =ROUND(SUM(AD33:AJ33),2) -> 573 | AL33: =SUM(AE33:AI33) -> 302.41171
B34: 31 | Y34: =ROUND(X34*W34*V34*12/10000,2) -> 0 | Z34: =ROUND(G34+K34+Y34,2) -> 0 | AC34: 31 | AE34: =ROUND(Z34*$AE$3,2) -> 0 | AH34: =AH33 -> 0 | AI34: =ROUND(Z34*$AI$3,2) -> 0 | AJ34: =ROUND(税费计算!O35,2) -> 0 | AK34: =ROUND(SUM(AD34:AJ34),2) -> 0 | AL34: =SUM(AE34:AI34) -> 0
Y35: =ROUND(X35*W35*V35*12/10000,2) -> 0 | Z35: =ROUND(G35+K35+Y35,2) -> 0
A36: 合计 | G36: =SUM(G4:G35) -> 230.2 | K36: =SUM(K5:K33) -> 1592.03 | Q36: =SUM(Q4:Q35) -> 4092.55 | U36: =SUM(U5:U33) -> 0 | Y36: =SUM(Y4:Y35) -> 28480.27 | Z36: =SUM(Z5:Z33) -> 34395.05 | AA36: 6258.85 | AB36: 合计 | AD36: =SUM(AD4:AD35) -> 0 | AE36: =SUM(AE4:AE35) -> 1719.7525 | AF36: =SUM(AF4:AF35) -> 3659.7865 | AG36: =SUM(AG4:AG35) -> 1148.6109 | AH36: =SUM(AH4:AH35) -> 0 | AI36: =SUM(AI4:AI35) -> 687.91 | AJ36: =SUM(AJ4:AJ35) -> 5087.7439 | AK36: =SUM(AK4:AK35) -> 12303.77 | AL36: =SUM(AL5:AL34) -> 7216.0598 | AM36: =SUM(AE36:AI36) -> 7216.0598
AF37: =AF36/20/29 -> 6.3099767
Y38: =V20*W20*X20*12 -> 10389369
AD39: =Z36-AK36 -> 22091.28 | AE39: =Z36-AK36 -> 22091.28
AE41: =AF36/29/14 -> 9.0142524
...

Sheet 资金平衡表
B1: 年度 | C1: 借贷本息支付 | F1: 经营收入 | H1: 总费用成本 | J1: 收益余额
C2: 本金 | D2: 利息 | E2: 本息合计 | F2: 1 | G2: 下降10% | H2: 1 | I2: 上升10% | J2: 1 | K2: 收入下降10% | L2: 成本上升10% | M2: 收入下降10%且成本上升10%
B3: 1 | C3: =还本付息!E5 -> 0 | D3: =还本付息!H5 -> 270 | E3: =C3+D3 -> 270
B4: 2 | C4: =还本付息!E6 -> 0 | D4: =还本付息!H6 -> 270 | E4: =C4+D4 -> 270 | F4: =ROUND(收入成本!Z5,2) -> 691.07 | G4: =ROUND(收入成本!Z5*0.9,2) -> 621.96 | H4: =ROUND(收入成本!AK5,2) -> 254.25 | I4: =ROUND(收入成本!AL5*1.1+收入成本!AJ5,2) -> 272.5 | J4: =F4-H4 -> 436.82 | K4: =G4-H4 -> 367.71 | L4: =F4-I4 -> 418.57 | M4: =G4-I4 -> 349.46
B5: 3 | C5: =还本付息!E7 -> 0 | D5: =还本付息!H7 -> 270 | E5: =C5+D5 -> 270 | F5: =ROUND(收入成本!Z6,2) -> 774.27 | G5: =ROUND(收入成本!Z6*0.9,2) -> 696.84 | H5: =ROUND(收入成本!AK6,2) -> 267.26 | I5: =ROUND(收入成本!AL6*1.1+收入成本!AJ6,2) -> 286.09 | J5: =F5-H5 -> 507.01 | K5: =G5-H5 -> 429.58 | L5: =F5-I5 -> 488.18 | M5: =G5-I5 -> 410.75
B6: 4 | C6: =还本付息!E8 -> 0 | D6: =还本付息!H8 -> 270 | E6: =C6+D6 -> 270 | F6: =ROUND(收入成本!Z7,2) -> 857.45 | G6: =ROUND(收入成本!Z7*0.9,2) -> 771.71 | H6: =ROUND(收入成本!AK7,2) -> 280.26 | I6: =ROUND(收入成本!AL7*1.1+收入成本!AJ7,2) -> 299.67 | J6: =F6-H6 -> 577.19 | K6: =G6-H6 -> 491.45 | L6: =F6-I6 -> 557.78 | M6: =G6-I6 -> 472.04
B7: 5 | C7: =还本付息!E9 -> 0 | D7: =还本付息!H9 -> 270 | E7: =C7+D7 -> 270 | F7: =ROUND(收入成本!Z8,2) -> 935.01 | G7: =ROUND(收入成本!Z8*0.9,2) -> 841.51 | H7: =ROUND(收入成本!AK8,2) -> 292.87 | I7: =ROUND(收入成本!AL8*1.1+收入成本!AJ8,2) -> 312.82 | J7: =F7-H7 -> 642.14 | K7: =G7-H7 -> 548.64 | L7: =F7-I7 -> 622.19 | M7: =G7-I7 -> 528.69
B8: 6 | C8: =还本付息!E10 -> 0 | D8: =还本付息!H10 -> 270 | E8: =C8+D8 -> 270 | F8: =ROUND(收入成本!Z9,2) -> 1004.83 | G8: =ROUND(收入成本!Z9*0.9,2) -> 904.35 | H8: =ROUND(收入成本!AK9,2) -> 304.94 | I8: =ROUND(收入成本!AL9*1.1+收入成本!AJ9,2) -> 325.38 | J8: =F8-H8 -> 699.89 | K8: =G8-H8 -> 599.41 | L8: =F8-I8 -> 679.45 | M8: =G8-I8 -> 578.97
B9: 7 | C9: =还本付息!E11 -> 0 | D9: =还本付息!H11 -> 270 | E9: =C9+D9 -> 270 | F9: =ROUND(收入成本!Z10,2) -> 1128.14 | G9: =ROUND(收入成本!Z10*0.9,2) -> 1015.33 | H9: =ROUND(收入成本!AK10,2) -> 337.78 | I9: =ROUND(收入成本!AL10*1.1+收入成本!AJ10,2) -> 360.25 | J9: =F9-H9 -> 790.36 | K9: =G9-H9 -> 677.55 | L9: =F9-I9 -> 767.89 | M9: =G9-I9 -> 655.08
