Workbook
Name 在此区间: '建设单位管理费'!$L$5
Name 在此区间内: '建设单位管理费'!$L$5

Sheet 标准化指标设定
C1: 本表所有此颜色单元格为基础数据，需自行嵌入。其余单元格均为联动，勿调整。
B3: 农村污水处理及中水再利用建设项目
A4: 江西省指标要求和假设参数设计 | J4: 江西省生活用水定额 | S4: 吉水县2021年末人口统计
A5: 序号 | B5: 指标项 | C5: 江西省用地指标（2018） | D5: 参数设定 | E5: 单位 | F5: 项目数据 | G5: 备注
A6: 1 | B6: 二级污水处理站用地 | C6: 参考城市污水处理厂建设用地指标 | D6: =1.5+(F11/10000-1)*((6-1.5)/(5-1)) -> 0.7125 | E6: 公顷 | G6: 1、为应对突发情况污水处理厂、污水管网泵站设计规模应比计算规模适当增大 2、污水处理厂规模按项目数据中的污水处理量来测算，收入计算时按参数设定中的处理量来计算
A7: 1.1 | B7: 区域人口 | C7: 根据地区情况确定 | D7: =G60/10000 -> 28.4983 | E7: 万人
A8: 1.2 | B8: 用水定额 | C8: 参考江西省生活用水定额 | D8: 200 | E8: L/（人*天）
A9: 1.3 | B9: 产污系数 | C9: 0.80-0.9 | D9: 0.85
A10: 1.4 | B10: 污水收集系数 | C10: 0.7-0.95 | D10: 0.9
A11: 1.5 | B11: 污水处理量 | D11: =D7*D8*D9*D10*10000/1000 -> 43602.399 | E11: m³/天 | F11: 3000
A12: 1.6 | B12: 容积率 | C12: ≥0.7 | D12: 0.75
A13: 2 | B13: 污水管网泵站用地 | C13: 参考污水管网泵站建设用地指标 | D13: =800+(F15-0.1)*(2500-800)/(1-0.1) -> 2122.2222 | E13: ㎡
A14: 2.1 | B14: 容积率 | C14: ≥0.7 | D14: =F28/D13 -> 0.84816754 | I14: 污水处理厂规模按项目数据中的污水处理量来测定，收入计算时按参数设定中的处理量来计算
A15: 2.2 | B15: 建设规模 | C15: 参考污水管网泵站建设用地指标 | D15: =F11/(24*60*60) -> 0.034722222 | F15: 0.8
A16: 一 | B16: 总建筑面积 | F16: =F17+F28 -> 7143
A17: 1 | B17: 污水处理厂 | E17: ㎡ | F17: =INT(D6*10000*D12) -> 5343 | G17: 0.15774845 | K17: 江西省用地指标（2018）
A18: 1.1 | B18: 粗格栅池 | C18: 根据实际需要确定 | E18: ㎡ | F18: 6300 | G18: =F17*G17 -> 842.84999
A19: 1.2 | B19: 提升池 | C19: 根据实际需要确定 | E19: ㎡ | F19: 6300 | G19: =F17*G17 -> 842.84999
A20: 1.3 | B20: 沉砂池 | C20: 根据实际需要确定 | E20: ㎡ | F20: 6300 | G20: =F17*G17 -> 842.84999
A21: 1.4 | B21: 兼氧 FMBR 池 | C21: 根据实际需要确定 | E21: ㎡ | F21: 3800 | G21: =F17*H21 -> 508.38571 | H21: 0.095149861
A22: 1.5 | B22: 消毒回用池 | C22: 根据实际需要确定 | E22: ㎡ | F22: 3800 | G22: =F17*H21 -> 508.38571
A23: 1.6 | B23: 污泥池 | C23: 根据实际需要确定 | E23: ㎡ | F23: 3100 | G23: =F17*H23 -> 414.73571 | H23: 0.077622255
A24: 1.7 | B24: 贮泥池 | C24: 根据实际需要确定 | E24: ㎡ | F24: 3100 | G24: =F17*H23 -> 414.73571
A25: 1.8 | B25: 污泥脱水机房 | C25: 根据实际需要确定 | E25: ㎡ | F25: 3600 | G25: =F17*H25 -> 481.62856 | H25: 0.090141974
A26: 1.9 | B26: 管理用房 | C26: 建筑面积比例不超过总建筑面积的15% | E26: ㎡ | F26: =F17-SUM(G18:G25) -> 486.57864 | G26: =F16*0.15 -> 1071.45
A27: 2 | B27: 厂区室外工程 | C27: 不得低于用地面积的30% | D27: 0.3 | E27: ㎡ | F27: =INT(D6*10000*D27) -> 2137
A28: 3 | B28: 污水管网泵站 | E28: ㎡ | F28: 1800 | K28: 容积率
A29: 4 | B29: 污水管网 | E29: ㎞ | F29: =F30 -> 3.6
A30: 4.1 | B30: 新建污水管道 | C30: 根据实际需要确定 | E30: ㎞ | F30: =F31+F32+F33 -> 3.6
A31: 4.1.1 | B31: HDPE缠绕结构壁管-DN300 | C31: 根据实际需要确定 | E31: ㎞ | F31: 1.2
A32: 4.1.2 | B32: HDPE缠绕结构壁管-DN400 | C32: 根据实际需要确定 | E32: ㎞ | F32: 1.3
A33: 4.1.3 | B33: HDPE缠绕结构壁管-DN500 | C33: 根据实际需要确定 | E33: ㎞ | F33: 1.1
A34: 4.2 | B34: 检查井 | C34: 检查井之间的距离不宜大于50m | D34: 40 | E34: 个 | F34: =F30*1000/D34 -> 90
I42: 吉水县农村生活污水治理专项规划
E50: 36573 | F50: 24368 | G50: 42477
E51: 31338 | F51: 19132 | G51: 29008
E52: 27783 | F52: 18504 | G52: 34226
E53: 31264 | F53: 27490 | G53: 38580
E54: 16007 | F54: 6259 | G54: 14591
E55: 10649 | F55: 8510 | G55: 14010
...

Sheet 项目技术经济指标
A1: 序号 | B1: 内容名称 | C1: 单位 | D1: 数量 | E1: 备注
A2: 一 | B2: 方案技术指标
B3: 总建筑面积 | D3: =D4+D15 -> 7200
A4: ='标准化指标设定'!A17 -> 1 | B4: ='标准化指标设定'!B17 -> 污水处理厂 | C4: ='标准化指标设定'!E17 -> ㎡ | D4: =SUM(D5:D13) -> 5200
A5: ='标准化指标设定'!A18 -> 1.1 | B5: ='标准化指标设定'!B18 -> 粗格栅池 | C5: ='标准化指标设定'!E18 -> ㎡ | D5: 800
A6: ='标准化指标设定'!A19 -> 1.2 | B6: ='标准化指标设定'!B19 -> 提升池 | C6: ='标准化指标设定'!E19 -> ㎡ | D6: 800
A7: ='标准化指标设定'!A20 -> 1.3 | B7: ='标准化指标设定'!B20 -> 沉砂池 | C7: ='标准化指标设定'!E20 -> ㎡ | D7: 800
A8: ='标准化指标设定'!A21 -> 1.4 | B8: ='标准化指标设定'!B21 -> 兼氧 FMBR 池 | C8: ='标准化指标设定'!E21 -> ㎡ | D8: 500 | G8: 成本 | H8: 工资 | I8: 管理人员 | K8: 职工 | M8: 每五年增长率
A9: ='标准化指标设定'!A22 -> 1.5 | B9: ='标准化指标设定'!B22 -> 消毒回用池 | C9: ='标准化指标设定'!E22 -> ㎡ | D9: 500 | I9: 人数 | J9: 月工资 | K9: 人数 | L9: 月工资
A10: ='标准化指标设定'!A23 -> 1.6 | B10: ='标准化指标设定'!B23 -> 污泥池 | C10: ='标准化指标设定'!E23 -> ㎡ | D10: 400 | I10: 1 | J10: 4000 | K10: 3 | L10: 3500 | M10: 0.1
A11: ='标准化指标设定'!A24 -> 1.7 | B11: ='标准化指标设定'!B24 -> 贮泥池 | C11: ='标准化指标设定'!E24 -> ㎡ | D11: 400
A12: ='标准化指标设定'!A25 -> 1.8 | B12: ='标准化指标设定'!B25 -> 污泥脱水机房 | C12: ='标准化指标设定'!E25 -> ㎡ | D12: 500
A13: ='标准化指标设定'!A26 -> 1.9 | B13: ='标准化指标设定'!B26 -> 管理用房 | C13: ='标准化指标设定'!E26 -> ㎡ | D13: 500
A14: ='标准化指标设定'!A27 -> 2 | B14: ='标准化指标设定'!B27 -> 厂区室外工程 | C14: ='标准化指标设定'!E27 -> ㎡ | D14: 2000
A15: ='标准化指标设定'!A28 -> 3 | B15: ='标准化指标设定'!B28 -> 污水管网泵站 | C15: ='标准化指标设定'!E28 -> ㎡ | D15: 2000
A16: ='标准化指标设定'!A29 -> 4 | B16: ='标准化指标设定'!B29 -> 污水管网 | C16: ='标准化指标设定'!E29 -> ㎞ | D16: ='标准化指标设定'!F29 -> 3.6 | H16: 项目总建筑面积为16260平方米，其中新建污水处理厂15468㎡，污水处理规模为1.5万m³/天，含粗格栅池2400㎡、提升池2400㎡、沉砂池2400㎡、兼氧 FMBR 池2000㎡、消毒回用池1600㎡、污泥池1200㎡、贮泥池1200㎡、污泥脱水机房1500㎡、管理用房768㎡；新建污水管网提升泵站792㎡，污水提升规模为0.2m³/秒；新建污水管网50㎞、检查井1250座。
A17: ='标准化指标设定'!A30 -> 4.1 | B17: ='标准化指标设定'!B30 -> 新建污水管道 | C17: ='标准化指标设定'!E30 -> ㎞ | D17: ='标准化指标设定'!F30 -> 3.6
A18: ='标准化指标设定'!A31 -> 4.1.1 | B18: ='标准化指标设定'!B31 -> HDPE缠绕结构壁管-DN300 | C18: ='标准化指标设定'!E31 -> ㎞ | D18: ='标准化指标设定'!F31 -> 1.2
A19: ='标准化指标设定'!A32 -> 4.1.2 | B19: ='标准化指标设定'!B32 -> HDPE缠绕结构壁管-DN400 | C19: ='标准化指标设定'!E32 -> ㎞ | D19: ='标准化指标设定'!F32 -> 1.3
A20: ='标准化指标设定'!A33 -> 4.1.3 | B20: ='标准化指标设定'!B33 -> HDPE缠绕结构壁管-DN500 | C20: ='标准化指标设定'!E33 -> ㎞ | D20: ='标准化指标设定'!F33 -> 1.1
A21: ='标准化指标设定'!A34 -> 4.2 | B21: ='标准化指标设定'!B34 -> 检查井 | C21: ='标准化指标设定'!E34 -> 个 | D21: ='标准化指标设定'!F34 -> 90
A22: 5 | B22: 中水管网 | C22: km | D22: =D23 -> 8
A23: 5.1 | B23: 新建污水管道 | C23: ㎞ | D23: =SUM(D24:D26) -> 8
A24: 5.1.1 | B24: HDPE缠绕结构壁管-DN300 | C24: ㎞ | D24: 2.6
A25: 5.1.2 | B25: HDPE缠绕结构壁管-DN400 | C25: ㎞ | D25: 2.8
A26: 5.1.3 | B26: HDPE缠绕结构壁管-DN500 | C26: ㎞ | D26: 2.6
A27: 5.2 | B27: 检查井 | C27: 个 | D27: 200
A28: 二 | B28: 经济技术指标
A29: 1 | B29: 总投资 | C29: 万元 | D29: ='总投资估算'!G55 -> 5000
A30: 1.1 | B30: 工程费用 | C30: 万元 | D30: =D31+D32 -> 3992.88
A31: 1.1.1 | B31: 建筑安装工程费用 | C31: 万元 | D31: ='总投资估算'!C3+'总投资估算'!D3 -> 3427.98
A32: 1.1.2 | B32: 设备及工器具购置费 | C32: 万元 | D32: ='总投资估算'!E3 -> 564.9
A33: 1.2 | B33: 工程建设其他费用 | C33: 万元 | D33: ='总投资估算'!G31 -> 559.82
A34: 1.3 | B34: 基本预备费 | C34: 万元 | D34: ='总投资估算'!G50 -> 348.3
A35: 1.4 | B35: 建设期利息 | C35: 万元 | D35: ='总投资估算'!G54 -> 99
A36: 2 | B36: 资金筹措 | C36: 万元 | D36: =SUM(D37:D38) -> 5000
A37: 2.1 | B37: 自筹资本金 | C37: 万元 | D37: ='分年计划及建设期利息'!G2 -> 2800 | E37: =D37/$D$36 -> 0.56
A38: 2.2 | B38: 融资及政府债券 | C38: 万元 | D38: ='资金平衡表'!C36 -> 2200 | E38: =D38/$D$36 -> 0.44
A39: 3 | B39: 年均营业收入 | C39: 万元 | D39: =AVERAGE('收入成本'!P5:P34) -> 369.93931
A40: 4 | B40: 年均税收 | C40: 万元 | D40: =AVERAGE('收入成本'!Z5:Z34) -> 5.1172414
...

Sheet 总投资估算
A1: 序号 | B1: 工程或费用名称 | C1: 估算金额（万元） | I1: 技术经济指标 | L1: 备注
C2: 建筑工程费 | D2: 安装工程费 | E2: 设备购置费 | F2: 其他费用 | G2: 小计 | H2: 比例 | I2: 单位 | J2: 数量 | K2: 单价（元）
A3: 一 | B3: 工程费用 | C3: =C4+C17+C18+C19+C25 -> 2199 | D3: =D4+D17+D18+D19+D25 -> 1228.98 | E3: =E4+E17+E18+E19+E25 -> 564.9 | F3: =F4+F17+F18+F19+F25 -> 0 | G3: =C3+E3+D3+F3 -> 3992.88 | H3: =G3/$G$55 -> 0.798576 | M3: =G3/'标准化指标设定'!F16 -> 0.55899202
A4: ='项目技术经济指标'!A4 -> 1 | B4: ='项目技术经济指标'!B4 -> 污水处理厂 | C4: =SUM(C5:C16) -> 1499 | D4: =SUM(D5:D16) -> 385 | E4: =SUM(E5:E16) -> 400 | F4: =SUM(F5:F16) -> 0 | G4: =C4+E4+D4+F4 -> 2284 | H4: =G4/$G$55 -> 0.4568 | I4: ='项目技术经济指标'!C4 -> ㎡ | J4: ='项目技术经济指标'!D4 -> 5200
A5: ='项目技术经济指标'!A5 -> 1.1 | B5: ='项目技术经济指标'!B5 -> 粗格栅池 | C5: =ROUND(J5*K5/10000,2) -> 248 | G5: =C5+E5+D5+F5 -> 248 | H5: =G5/$G$55 -> 0.0496 | I5: ='项目技术经济指标'!C5 -> ㎡ | J5: ='项目技术经济指标'!D5 -> 800 | K5: 3100 | L5: 含装修 | M5: 2600±400
A6: ='项目技术经济指标'!A6 -> 1.2 | B6: ='项目技术经济指标'!B6 -> 提升池 | C6: =ROUND(J6*K6/10000,2) -> 248 | G6: =C6+E6+D6+F6 -> 248 | H6: =G6/$G$55 -> 0.0496 | I6: ='项目技术经济指标'!C6 -> ㎡ | J6: ='项目技术经济指标'!D6 -> 800 | K6: 3100 | L6: 含装修 | M6: 2400±200
A7: ='项目技术经济指标'!A7 -> 1.3 | B7: ='项目技术经济指标'!B7 -> 沉砂池 | C7: =ROUND(J7*K7/10000,2) -> 224 | G7: =C7+E7+D7+F7 -> 224 | H7: =G7/$G$55 -> 0.0448 | I7: ='项目技术经济指标'!C7 -> ㎡ | J7: ='项目技术经济指标'!D7 -> 800 | K7: 2800 | L7: 含装修 | M7: 2200±200
A8: ='项目技术经济指标'!A8 -> 1.4 | B8: ='项目技术经济指标'!B8 -> 兼氧 FMBR 池 | C8: =ROUND(J8*K8/10000,2) -> 155 | G8: =C8+E8+D8+F8 -> 155 | H8: =G8/$G$55 -> 0.031 | I8: ='项目技术经济指标'!C8 -> ㎡ | J8: ='项目技术经济指标'!D8 -> 500 | K8: 3100 | L8: 含装修 | M8: 2600±400
A9: ='项目技术经济指标'!A9 -> 1.5 | B9: ='项目技术经济指标'!B9 -> 消毒回用池 | C9: =ROUND(J9*K9/10000,2) -> 140 | G9: =C9+E9+D9+F9 -> 140 | H9: =G9/$G$55 -> 0.028 | I9: ='项目技术经济指标'!C9 -> ㎡ | J9: ='项目技术经济指标'!D9 -> 500 | K9: 2800 | L9: 含装修 | M9: 2000±300
A10: ='项目技术经济指标'!A10 -> 1.6 | B10: ='项目技术经济指标'!B10 -> 污泥池 | C10: =ROUND(J10*K10/10000,2) -> 112 | G10: =C10+E10+D10+F10 -> 112 | H10: =G10/$G$55 -> 0.0224 | I10: ='项目技术经济指标'!C10 -> ㎡ | J10: ='项目技术经济指标'!D10 -> 400 | K10: 2800 | L10: 含装修 | M10: 2000±200
A11: ='项目技术经济指标'!A11 -> 1.7 | B11: ='项目技术经济指标'!B11 -> 贮泥池 | C11: =ROUND(J11*K11/10000,2) -> 112 | G11: =C11+E11+D11+F11 -> 112 | H11: =G11/$G$55 -> 0.0224 | I11: ='项目技术经济指标'!C11 -> ㎡ | J11: ='项目技术经济指标'!D11 -> 400 | K11: 2800 | L11: 含装修 | M11: 2000±200
A12: ='项目技术经济指标'!A12 -> 1.8 | B12: ='项目技术经济指标'!B12 -> 污泥脱水机房 | C12: =ROUND(J12*K12/10000,2) -> 130 | G12: =C12+E12+D12+F12 -> 130 | H12: =G12/$G$55 -> 0.026 | I12: ='项目技术经济指标'!C12 -> ㎡ | J12: ='项目技术经济指标'!D12 -> 500 | K12: 2600 | L12: 含装修 | M12: 2400±200
A13: ='项目技术经济指标'!A13 -> 1.9 | B13: ='项目技术经济指标'!B13 -> 管理用房 | C13: =ROUND(J13*K13/10000,2) -> 130 | G13: =C13+E13+D13+F13 -> 130 | H13: =G13/$G$55 -> 0.026 | I13: ='项目技术经济指标'!C13 -> ㎡ | J13: ='项目技术经济指标'!D13 -> 500 | K13: 2600 | L13: 含装修 | M13: 2400±200
A14: 1.1 | B14: 终端水质在线监测系统 | D14: =ROUND(J14*K14/10000,2)*20% -> 40 | E14: =ROUND(J14*K14/10000,2)*80% -> 160 | G14: =C14+E14+D14+F14 -> 200 | H14: =G14/$G$55 -> 0.04 | I14: 套 | J14: 1 | K14: 2000000 | M14: 1500000±500000
A15: 1.11 | B15: 中控系统 | D15: =ROUND(J15*K15/10000,2)*20% -> 60 | E15: =ROUND(J15*K15/10000,2)*80% -> 240 | G15: =C15+E15+D15+F15 -> 300 | H15: =G15/$G$55 -> 0.06 | I15: 套 | J15: 1 | K15: 3000000 | M15: 3000000±1000000
A16: 1.12 | B16: 场内配套基础设施 | D16: =ROUND(J16*K16/10000,2) -> 285 | G16: =C16+E16+D16+F16 -> 285 | H16: =G16/$G$55 -> 0.057 | I16: ㎡ | J16: ='标准化指标设定'!D6*10000 -> 7125 | K16: 400 | M16: 200±100
A17: ='项目技术经济指标'!A14 -> 2 | B17: ='项目技术经济指标'!B14 -> 厂区室外工程 | C17: =J17*K17/10000 -> 100 | G17: =C17+E17+D17+F17 -> 100 | H17: =G17/$G$55 -> 0.02 | I17: ='项目技术经济指标'!C14 -> ㎡ | J17: ='项目技术经济指标'!D14 -> 2000 | K17: 500
A18: ='项目技术经济指标'!A15 -> 3 | B18: ='项目技术经济指标'!B15 -> 污水管网泵站 | C18: =ROUND(J18*K18/10000,2) -> 600 | D18: =E18*20% -> 15 | E18: 75 | G18: =C18+E18+D18+F18 -> 690 | H18: =G18/$G$55 -> 0.138 | I18: ='项目技术经济指标'!C15 -> ㎡ | J18: 2000 | K18: 3000 | M18: 2400±300
A19: ='项目技术经济指标'!A16 -> 4 | B19: ='项目技术经济指标'!B16 -> 污水管网 | C19: =C20+C24 -> 0 | D19: =D20+D24 -> 256.58 | E19: =E20+E24 -> 27.9 | F19: =F20+F24 -> 0 | G19: =C19+E19+D19+F19 -> 284.48 | H19: =G19/$G$55 -> 0.056896 | I19: ='项目技术经济指标'!C16 -> ㎞ | J19: ='项目技术经济指标'!D16 -> 3.6
A20: ='项目技术经济指标'!A17 -> 4.1 | B20: ='项目技术经济指标'!B17 -> 新建污水管道 | C20: =SUM(C21:C23) -> 0 | D20: =SUM(D21:D23) -> 251 | E20: =SUM(E21:E23) -> 0 | F20: =SUM(F21:F23) -> 0 | G20: =C20+E20+D20+F20 -> 251 | H20: =G20/$G$55 -> 0.0502 | I20: ='项目技术经济指标'!C17 -> ㎞ | J20: ='项目技术经济指标'!D17 -> 3.6
A21: ='项目技术经济指标'!A18 -> 4.1.1 | B21: ='项目技术经济指标'!B18 -> HDPE缠绕结构壁管-DN300 | D21: =ROUND(J21*K21/10000,2) -> 72 | G21: =C21+E21+D21+F21 -> 72 | H21: =G21/$G$55 -> 0.0144 | I21: m | J21: ='项目技术经济指标'!D18*1000 -> 1200 | K21: 600 | M21: 400±100
A22: ='项目技术经济指标'!A19 -> 4.1.2 | B22: ='项目技术经济指标'!B19 -> HDPE缠绕结构壁管-DN400 | D22: =ROUND(J22*K22/10000,2) -> 91 | G22: =C22+E22+D22+F22 -> 91 | H22: =G22/$G$55 -> 0.0182 | I22: m | J22: ='项目技术经济指标'!D19*1000 -> 1300 | K22: 700 | M22: 500±100
A23: ='项目技术经济指标'!A20 -> 4.1.3 | B23: ='项目技术经济指标'!B20 -> HDPE缠绕结构壁管-DN500 | D23: =ROUND(J23*K23/10000,2) -> 88 | G23: =C23+E23+D23+F23 -> 88 | H23: =G23/$G$55 -> 0.0176 | I23: m | J23: ='项目技术经济指标'!D20*1000 -> 1100 | K23: 800 | M23: 600±200
A24: ='项目技术经济指标'!A21 -> 4.2 | B24: ='项目技术经济指标'!B21 -> 检查井 | D24: =E24*20% -> 5.58 | E24: =ROUND(J24*K24/10000,2) -> 27.9 | G24: =C24+E24+D24+F24 -> 33.48 | H24: =G24/$G$55 -> 0.006696 | I24: ='项目技术经济指标'!C21 -> 个 | J24: ='项目技术经济指标'!D21 -> 90 | K24: 3100 | M24: 2800±400
A25: ='项目技术经济指标'!A22 -> 5 | B25: ='项目技术经济指标'!B22 -> 中水管网 | C25: =C26+C30 -> 0 | D25: =D26+D30 -> 572.4 | E25: =E26+E30 -> 62 | F25: =F26+F30 -> 0 | G25: =C25+E25+D25+F25 -> 634.4 | H25: =G25/$G$55 -> 0.12688 | I25: ='项目技术经济指标'!C22 -> km | J25: ='项目技术经济指标'!D22 -> 8
A26: ='项目技术经济指标'!A23 -> 5.1 | B26: ='项目技术经济指标'!B23 -> 新建污水管道 | C26: =SUM(C27:C29) -> 0 | D26: =SUM(D27:D29) -> 560 | E26: =SUM(E27:E29) -> 0 | F26: =SUM(F27:F29) -> 0 | G26: =C26+E26+D26+F26 -> 560 | H26: =G26/$G$55 -> 0.112 | I26: ='项目技术经济指标'!C23 -> ㎞ | J26: ='项目技术经济指标'!D23 -> 8
A27: ='项目技术经济指标'!A24 -> 5.1.1 | B27: ='项目技术经济指标'!B24 -> HDPE缠绕结构壁管-DN300 | D27: =ROUND(J27*K27/10000,2) -> 156 | G27: =C27+E27+D27+F27 -> 156 | H27: =G27/$G$55 -> 0.0312 | I27: m | J27: 2600 | K27: 600
A28: ='项目技术经济指标'!A25 -> 5.1.2 | B28: ='项目技术经济指标'!B25 -> HDPE缠绕结构壁管-DN400 | D28: =ROUND(J28*K28/10000,2) -> 196 | G28: =C28+E28+D28+F28 -> 196 | H28: =G28/$G$55 -> 0.0392 | I28: m | J28: 2800 | K28: 700
A29: ='项目技术经济指标'!A26 -> 5.1.3 | B29: ='项目技术经济指标'!B26 -> HDPE缠绕结构壁管-DN500 | D29: =ROUND(J29*K29/10000,2) -> 208 | G29: =C29+E29+D29+F29 -> 208 | H29: =G29/$G$55 -> 0.0416 | I29: m | J29: 2600 | K29: 800
A30: ='项目技术经济指标'!A27 -> 5.2 | B30: ='项目技术经济指标'!B27 -> 检查井 | D30: =E30*20% -> 12.4 | E30: =ROUND(J30*K30/10000,2) -> 62 | G30: =C30+E30+D30+F30 -> 74.4 | H30: =G30/$G$55 -> 0.01488 | I30: 个 | J30: ='项目技术经济指标'!D27 -> 200 | K30: 3100
A31: 二 | B31: 工程建设其他费用 | F31: =SUM(F32:F49) -> 559.82 | G31: =F31 -> 559.82 | H31: =G31/$G$55 -> 0.111964
A32: 1 | B32: ='其他费自动计算'!B12 -> 建设单位管理费 | F32: =ROUND('其他费自动计算'!C12,2) -> 64.89 | G32: =F32 -> 64.89 | H32: =G32/$G$55 -> 0.012978 | I32: ='工程建设其他费细则说明'!E4 -> 财建[2016]504号
A33: 2 | B33: ='其他费自动计算'!B13 -> 场地准备及临时设施费 | F33: =ROUND('其他费自动计算'!C13,2) -> 39.93 | G33: =F33 -> 39.93 | H33: =G33/$G$55 -> 0.007986 | I33: ='工程建设其他费细则说明'!E18 -> 建标〔2011〕1号
A34: 3 | B34: ='其他费自动计算'!B14 -> 前期工作咨询费 | F34: =ROUND('其他费自动计算'!C14,2) -> 16.57 | G34: =F34 -> 16.57 | H34: =G34/$G$55 -> 0.003314 | I34: ='工程建设其他费细则说明'!E21 -> 计价格［1999］1283号
A35: 4 | B35: ='其他费自动计算'!B15 -> 勘察费 | F35: =ROUND('其他费自动计算'!C15,2) -> 39.93 | G35: =F35 -> 39.93 | H35: =G35/$G$55 -> 0.007986 | I35: ='工程建设其他费细则说明'!E36 -> 建标〔2011〕1号
A36: 5 | B36: ='其他费自动计算'!B16 -> 设计费 | F36: =ROUND('其他费自动计算'!C16,2) -> 133.64 | G36: =F36 -> 133.64 | H36: =G36/$G$55 -> 0.026728 | I36: ='工程建设其他费细则说明'!E37 -> 计价格[2002]10号
A37: 6 | B37: ='其他费自动计算'!B17 -> 工程监理费 | F37: =ROUND('其他费自动计算'!C17,2) -> 99.3 | G37: =F37 -> 99.3 | H37: =G37/$G$55 -> 0.01986 | I37: ='工程建设其他费细则说明'!E38 -> 发改价格[2007]670号
A38: 7 | B38: ='其他费自动计算'!B18 -> 招标代理费 | F38: =ROUND('其他费自动计算'!C18,2) -> 31.34 | G38: =F38 -> 31.34 | H38: =G38/$G$55 -> 0.006268 | I38: ='工程建设其他费细则说明'!E42 -> 发改价格[2011]534号
A39: 8 | B39: ='其他费自动计算'!B19 -> 施工图审查费 | F39: =ROUND('其他费自动计算'!C19,2) -> 5.39 | G39: =F39 -> 5.39 | H39: =G39/$G$55 -> 0.001078 | I39: ='工程建设其他费细则说明'!E43 -> 赣价房字[2000]6号
A40: 9 | B40: ='其他费自动计算'!B20 -> 工程造价咨询费 | F40: =ROUND('其他费自动计算'!C20,2) -> 33.96 | G40: =F40 -> 33.96 | H40: =G40/$G$55 -> 0.006792 | I40: ='工程建设其他费细则说明'!E45 -> 赣价协[2021]23号
...

Sheet 其他费自动计算
A1: 序号 | B1: 费用输入（万元） | C1: 输入👇
A2: 1 | B2: 工程费用 | C2: ='总投资估算'!G3 -> 3992.88 | E2: 总投资 | G2: 总建筑面积
A3: 2 | B3: 总投资 | E3: 5000 | F3: ☜手动输入 | G3: ='项目技术经济指标'!D3/10000 -> 0.72 | H3: ☜手动输入
A4: 3 | B4: 设备购置费 | C4: ='总投资估算'!E3 -> 564.9
A7: 地区筛选 | B7: 红谷滩区
E9: 单位：万元 | G9: 地区折扣目录
A10: 序号 | B10: 费用名称 | C10: 估算金额 | D10: 地区折扣 | E10: 折后金额 | F10: 计费基础 | G10: 南昌市 | I10: 红谷滩区 | K10: 南昌县
G11: 参考文件 | H11: 折扣率 | I11: 参考文件 | J11: 折扣率 | K11: 参考文件 | L11: 折扣率
A12: 1 | B12: ='工程建设其他费细则说明'!B4 -> 建设单位管理费 | C12: =H112 -> 64.8932 | D12: =SUMIF(G$10:L$10,B$7,H12) -> 0.8 | E12: =C12*D12 -> 51.91456 | F12: 工程费用 | H12: 0.3 | J12: 0.8 | L12: 0.7
A13: 2 | B13: ='工程建设其他费细则说明'!B18 -> 场地准备及临时设施费 | C13: =C2*1% -> 39.9288 | D13: =SUMIF(G$10:L$10,B$7,H13) -> 0.6 | E13: =C13*D13 -> 23.95728 | F13: 工程费用 | H13: 0.6 | J13: 0.6 | L13: 0.6
A14: 3 | B14: ='工程建设其他费细则说明'!B21 -> 前期工作咨询费 | C14: =G34 -> 16.569796 | D14: =SUMIF(G$10:L$10,B$7,H14) -> 0.5 | E14: =C14*D14 -> 8.2848978 | F14: 总投资 | H14: 0.5 | J14: 0.5 | L14: 0.6
A15: 4 | B15: ='工程建设其他费细则说明'!B36 -> 勘察费 | C15: =C2*1% -> 39.9288 | D15: =SUMIF(G$10:L$10,B$7,H15) -> 0.4 | E15: =C15*D15 -> 15.97152 | F15: 工程费用 | H15: 0.8 | J15: 0.4 | L15: 0.85
A16: 5 | B16: ='工程建设其他费细则说明'!B37 -> 设计费 | C16: =E123 -> 133.63604 | D16: =SUMIF(G$10:L$10,B$7,H16) -> 0.4 | E16: =C16*D16 -> 53.454418 | F16: 工程费用 | H16: 0.9 | J16: 0.4 | L16: 0.85
A17: 6 | B17: ='工程建设其他费细则说明'!B38 -> 工程监理费 | C17: =E147 -> 99.297988 | D17: =SUMIF(G$10:L$10,B$7,H17) -> 0.7 | E17: =C17*D17 -> 69.508592 | F17: 工程费用 | H17: 0.5 | J17: 0.7 | L17: 0.7
A18: 7 | B18: ='工程建设其他费细则说明'!B42 -> 招标代理费 | C18: =S57 -> 31.339588 | D18: =SUMIF(G$10:L$10,B$7,H18) -> 0.49 | E18: =C18*D18 -> 15.356398 | F18: 分包 | H18: 0.3 | J18: 0.49 | L18: 0.8
A19: 8 | B19: ='工程建设其他费细则说明'!B43 -> 施工图审查费 | C19: =H181 -> 5.391456 | D19: =SUMIF(G$10:L$10,B$7,H19) -> 0.7 | E19: =C19*D19 -> 3.7740192 | F19: 工程费用 | H19: 0.4 | J19: 0.7 | L19: 0.6
A20: 9 | B20: ='工程建设其他费细则说明'!B45 -> 工程造价咨询费 | C20: =H169 -> 33.964464 | D20: =SUMIF(G$10:L$10,B$7,H20) -> 0.5 | E20: =C20*D20 -> 16.982232 | F20: 工程费用 | H20: 0.7 | J20: 0.5 | L20: 0.7
A21: 10 | B21: ='工程建设其他费细则说明'!B46 -> 工程保险费 | C21: =C2*0.5% -> 19.9644 | D21: =SUMIF(G$10:L$10,B$7,H21) -> 0.7 | E21: =C21*D21 -> 13.97508 | F21: 工程费用 | H21: 0.6 | J21: 0.7 | L21: 0.7
A22: 11 | B22: ='工程建设其他费细则说明'!B23 -> 环境影响评价费 | C22: =G64 -> 5.1176471 | D22: =SUMIF(G$10:L$10,B$7,H22) -> 0.7 | E22: =C22*D22 -> 3.5823529 | F22: 总投资 | H22: 0.7 | J22: 0.7 | L22: 0.7
A23: 12 | B23: ='工程建设其他费细则说明'!B29 -> 节能评估费 | C23: =H218 -> 6 | D23: =SUMIF(G$10:L$10,B$7,H23) -> 0.7 | E23: =C23*D23 -> 4.2 | F23: 工程费用 | H23: 0.7 | J23: 0.7 | L23: 0.7
A24: 13 | B24: ='工程建设其他费细则说明'!B27 -> 水土保持评价费 | C24: =G190 -> 30 | D24: =SUMIF(G$10:L$10,B$7,H24) -> 0.7 | E24: =C24*D24 -> 21 | F24: 工程费用 | H24: 0.7 | J24: 0.7 | L24: 0.7
A25: 14 | B25: ='工程建设其他费细则说明'!B32 -> 劳动安全卫生评审费 | C25: =C2*0.5% -> 19.9644 | D25: =SUMIF(G$10:L$10,B$7,H25) -> 0.7 | E25: =C25*D25 -> 13.97508 | F25: 工程费用 | H25: 0.7 | J25: 0.7 | L25: 0.7
A26: 15 | B26: ='工程建设其他费细则说明'!B31 -> 社会稳定风险评估费 | C26: =I75 -> 4.6285714 | D26: =SUMIF(G$10:L$10,B$7,H26) -> 0.7 | E26: =C26*D26 -> 3.24 | F26: 总投资 | H26: 0.7 | J26: 0.7 | L26: 0.7
A27: 16 | B27: ='工程建设其他费细则说明'!B24 -> 安全预评价费 | C27: =G87 -> 7 | D27: =SUMIF(G$10:L$10,B$7,H27) -> 0.7 | E27: =C27*D27 -> 4.9 | F27: 总投资 | H27: 0.7 | J27: 0.7 | L27: 0.7
A28: 17 | B28: ='工程建设其他费细则说明'!B33 -> 交通影响评估费 | C28: 0 | D28: =SUMIF(G$10:L$10,B$7,H28) -> 0.7 | E28: =C28*D28 -> 0 | F28: 总建筑面积 | H28: 0.7 | J28: 0.7 | L28: 0.7
A29: 合计 | C29: =SUM(C12:C28) -> 557.62515
A32: 前期工作咨询费（可行性研究报告）
A33: 序号 | B33: 计费额 | E33: 基价 | F33: 输入费用👇 | G33: 直线内插法计取
F34: =E3 -> 5000 | G34: =SUM(G35:G41) -> 16.569796
A35: 1 | C35: > | D35: 1000 | E35: 3 | F35: =IF(F34<=D35,1,0) -> 0 | G35: =IF($F35=1,(E35/D35*$F34),0) -> 0
A36: 2 | B36: 1001 | C36: ~ | D36: 3000 | E36: 6 | F36: =IF(AND($F$34<=D36,$F$34>B36),1,0) -> 0 | G36: =IF($F36=1,(E36+((E37-E36)/(D36-B36)*($F$34-B36))),0) -> 0
A37: 3 | B37: 3001 | C37: ~ | D37: 10000 | E37: 12 | F37: =IF(AND($F$34<=D37,$F$34>B37),1,0) -> 1 | G37: =IF($F37=1,(E37+((E38-E37)/(D37-B37)*($F$34-B37))),0) -> 16.569796
A38: 4 | B38: 10001 | C38: ~ | D38: 50000 | E38: 28 | F38: =IF(AND($F$34<=D38,$F$34>B38),1,0) -> 0 | G38: =IF($F38=1,(E38+((E39-E38)/(D38-B38)*($F$34-B38))),0) -> 0
A39: 5 | B39: 50001 | C39: ~ | D39: 100000 | E39: 75 | F39: =IF(AND($F$34<=D39,$F$34>B39),1,0) -> 0 | G39: =IF($F39=1,(E39+((E40-E39)/(D39-B39)*($F$34-B39))),0) -> 0
A40: 6 | B40: 100000 | C40: ~ | D40: 500000 | E40: 110 | F40: =IF(AND($F$34<=D40,$F$34>B40),1,0) -> 0 | G40: =IF($F40=1,(E40+((E41-E40)/(D40-B40)*($F$34-B40))),0) -> 0
A41: 7 | B41: 500000 | E41: 200 | F41: =IF(AND($F$34>B41),1,0) -> 0 | G41: =IF($F41=1,MIN(250,F34*E41/B41),0) -> 0
A44: 招标代理服务费
A45: 计费额 | D45: 货物采购 | G45: 服务招标（勘察） | J45: 服务招标（设计） | M45: 服务招标（监理） | P45: 工程招标
D46: =C4 -> 564.9 | G46: =C15 -> 39.9288 | J46: =C16 -> 133.63604 | M46: =C17 -> 99.297988 | P46: =C2-C4 -> 3427.98
B47: < | C47: 100 | D47: =C47*E47 -> 1.5 | E47: 0.015 | F47: =IF(D46<=C47,D46*E47,0) -> 0 | G47: =C47*H47 -> 1.5 | H47: 0.015 | I47: =IF(H46<=C47,H46*H47,0) -> 0 | J47: =C47*K47 -> 1.5 | K47: 0.015 | L47: =IF(J46<=C47,J46*K47,0) -> 0 | M47: =C47*N47 -> 1.5 | N47: 0.015 | O47: =IF(M46<=C47,M46*N47,0) -> 1.4894698 | P47: =C47*Q47 -> 1 | Q47: 0.01 | R47: =IF(P46<=C47,P46*Q47,0) -> 0
...

Sheet 分年计划及建设期利息
B1: 工期起始 | C1: 45108.9 | D1: 月数汇总 | F1: 资金来源 | G1: 金额（万元） | H1: 占比 | K1: ☜该色块为需手动输入
B2: 工期结束 | C2: 45900 | D2: 12 | F2: 资本金 | G2: =G4-G3 -> 2800 | H2: =G2/$G$4 -> 0.56 | K2: ☜出现该色块的单元格为报错格
B3: 建设年度 | C3: 建设年度起 | D3: 建设年度止 | F3: 发债金额 | G3: ='资金平衡表'!C36 -> 2200 | H3: =G3/$G$4 -> 0.44
B4: 第一年度 | C4: =C1 -> 45108.9 | D4: =EOMONTH(C4,11) -> 45473 | F4: 总投资 | G4: ='总投资估算'!G55 -> 5000 | H4: =G4/$G$4 -> 1
B5: 第二年度 | C5: =EOMONTH(D4,1) -> 45504 | D5: =EOMONTH(C5,11) -> 45838
B6: 第三年度 | C6: =EOMONTH(D5,1) -> 45869 | D6: =C2 -> 45900
B8: 表1-分年资金使用
B9: 序号 | C9: 项目 | D9: 合计 | E9: 建设期 | I9: 检查列
E10: 2024 | F10: =E10+1 -> 2025 | G10: =F10+1 -> 2026 | H10: =G10+1 -> 2027
B11: 一 | C11: 进度安排
B12: 1 | C12: 建设进度 | D12: =SUM(E12:H12) -> 1 | E12: 0.9 | F12: 0.1 | G12: =1-F12-E12 -> 0 | H12: 0 | I12: =SUM(E12:H12) -> 1
B13: 2 | C13: 其他费投入进度 | D13: =SUM(E13:H13) -> 1 | E13: 0.9 | F13: 0.1 | G13: =1-F13-E13 -> 0 | H13: 0 | I13: =SUM(E13:H13) -> 1
B14: 3 | C14: 专项债投入进度 | D14: =SUM(E14:H14) -> 1 | E14: 1 | F14: 0 | G14: =1-F14-E14 -> 0 | H14: 0 | I14: =SUM(E14:H14) -> 1
B15: 一 | C15: 总投资 | D15: =D16+D20 -> 5000 | E15: =E16+E20 -> 4509.9 | F15: =F16+F20 -> 490.1 | G15: =G16+G20 -> 0 | H15: =H16+H20 -> 0 | I15: =SUM(E15:H15) -> 5000 | J15: =I15-D15 -> 0
B16: 1 | C16: 建设投资 | D16: =SUM(E16:H16) -> 4901 | E16: =E17+E18+E19 -> 4410.9 | F16: =F17+F18+F19 -> 490.1 | G16: =G17+G18+G19 -> 0 | H16: =H17+H18+H19 -> 0 | I16: =SUM(E16:H16) -> 4901 | J16: =I16-D16 -> 0
B17: 1.1 | C17: 工程费用 | D17: ='总投资估算'!G3 -> 3992.88 | E17: =ROUND($D$17*E12,2) -> 3593.59 | F17: =ROUND($D$17*F12,2) -> 399.29 | G17: =ROUND($D$17*G12,2) -> 0 | H17: =ROUND($D$17*H12,2) -> 0 | I17: =SUM(E17:H17) -> 3992.88 | J17: =I17-D17 -> 0
B18: 1.2 | C18: 工程建设其他费 | D18: ='总投资估算'!G31 -> 559.82 | E18: =ROUND($D$18*E13,2) -> 503.84 | F18: =ROUND($D$18*F13,2) -> 55.98 | G18: =ROUND($D$18*G13,2) -> 0 | H18: =ROUND($D$18*H13,2) -> 0 | I18: =SUM(E18:H18) -> 559.82 | J18: =I18-D18 -> 0
B19: 1.3 | C19: 基本预备费 | D19: ='总投资估算'!G50 -> 348.3 | E19: =ROUND($D$19*E12,2) -> 313.47 | F19: =ROUND($D$19*F12,2) -> 34.83 | G19: =ROUND($D$19*G12,2) -> 0 | H19: =ROUND($D$19*H12,2) -> 0 | I19: =SUM(E19:H19) -> 348.3 | J19: =I19-D19 -> 0
B20: 2 | C20: 建设期利息 | D20: =SUM(E20:H20) -> 99 | E20: ='还本付息'!H5 -> 99 | F20: 0 | G20: 0 | H20: 0 | I20: =SUM(E20:H20) -> 99 | J20: =I20-D20 -> 0
B21: 二 | C21: 资金筹措 | D21: =D22+D23 -> 5000 | E21: =E15 -> 4509.9 | F21: =F15 -> 490.1 | G21: =G15 -> 0 | H21: =H15 -> 0 | I21: =SUM(E21:H21) -> 5000 | J21: =I21-D21 -> 0
B22: 1 | C22: 项目资本金 | D22: =G2 -> 2800 | E22: =E21-E23 -> 2309.9 | F22: =F21-F23 -> 490.1 | G22: =G21-G23 -> 0 | H22: =H21-H23 -> 0 | I22: =SUM(E22:H22) -> 2800 | J22: =I22-D22 -> 0
B23: 2 | C23: 专项债券 | D23: ='资金平衡表'!C36 -> 2200 | E23: =$D$23*E14 -> 2200 | F23: =$D$23*F14 -> 0 | G23: =$D$23*G14 -> 0 | H23: =$D$23*H14 -> 0 | I23: =SUM(E23:H23) -> 2200 | J23: =I23-D23 -> 0

Sheet 信息采集表
A1: 填表注释：公式请勿修改 | B1: 黄色单元格需要填写 | C1: 此为测算结果
A2: 1、项目建设期运营期相关
A3: 项目实际情况：
A4: ①截止到填表日，本项目是否开工 | B4: 否
A5: ②本项目建设期 | B5: =DATEDIF(B6,B7+1,"M") -> 26 | C5: 个月。
A6: ③本项目建设期开工日期 | B6: ='分年计划及建设期利息'!C1 -> 45108.9 | C6: 如：202X年X月1日
A7: ④本项目建设期完工日期 | B7: ='分年计划及建设期利息'!C2 -> 45900 | C7: 如：202X年X月1日 | D7: =(B7-B6)/30-B5 -> 0.37 | E7: （④-③）/30-② | F7: 注意与B5单元格的勾稽关系
A9: 项目可研报告中数据情况：
A10: ⑤本项目建设期 | B10: =B5 -> 26 | C10: 个月。 | D10: =B10-B5 -> 0 | E10: ⑤-②
A11: ⑥本项目建设期开工日期 | B11: =B6 -> 45108.9 | C11: 如：202X年X月1日 | D11: =B11-B6 -> 0 | E11: ⑥-③ | F11: 如与项目实际情况存在较大差异。1、笔误等情况酌情修改可研；2、编制错误或是以前年度编制可研造成，考虑是否影响可研数据的准确性（以前年度编制的可研，依据的参考数据都是以前年度的，是否与现在情况存在偏差，是否合理）；
A12: ⑦本项目建设期完工日期 | B12: =B7 -> 45900 | C12: 如：202X年X月1日 | D12: =B12-B7 -> 0 | E12: ⑦-④
A13: ⑧建设工程费用 | B13: ='分年计划及建设期利息'!D17 -> 3992.88 | C13: =B13-B24 -> 0 | D13: ⑧-⑭ | E13: 此处进行测算，存在差异，则需找具体原因
A14: ⑨工程建设其他费用 | B14: ='分年计划及建设期利息'!D18 -> 559.82 | C14: =B14-B25 -> 0 | D14: ⑨-⑮ | E14: 此处进行测算，存在差异，则需找具体原因
A15: ⑩预备费 | B15: ='分年计划及建设期利息'!D19 -> 348.3 | C15: =B15-B26 -> 0 | D15: ⑩-⑯ | E15: 此处进行测算，存在差异，则需找具体原因
A16: ⑪建设期利息 | B16: ='分年计划及建设期利息'!D20 -> 99 | C16: =B16-B27 -> 0 | D16: ⑪-⑰ | E16: 此处进行测算，存在差异，则需找具体原因
A17: 合计 | B17: =SUM(B13:B16) -> 5000 | C17: =B17-B28 -> 0 | D17: 合计差异 | E17: 此处进行测算，存在差异，则需找具体原因
A19: 2、投资构成及分年度计划（万元）
A20: 可研批复文号
A21: ⑫可研批复金额 | B21: =B22 -> 5000 | C21: =B21-B22 -> 0 | D21: ⑫-⑬ | E21: 此处进行测算，存在差异，则需找具体原因
A22: ⑬可研总投资金额 | B22: ='总投资估算'!G55 -> 5000 | C22: =B28-B22 -> 0 | D22: ⑬-（⑭+⑮+⑯+⑰） | E22: 此处进行测算，存在差异，则需找具体原因
A23: 具体每年项目投资情况 | B23: 合计 | C23: 以前年度 | D23: 2022年 | E23: 2023年 | F23: 2024年 | G23: 2025年 | H23: 2026年 | I23: 2027年
A24: ⑭建设工程费用 | B24: =SUM(C24:I24) -> 3992.88 | D24: ='分年计划及建设期利息'!E17 -> 3593.59 | E24: ='分年计划及建设期利息'!F17 -> 399.29 | F24: ='分年计划及建设期利息'!G17 -> 0 | G24: ='分年计划及建设期利息'!H17 -> 0
A25: ⑮工程建设其他费用 | B25: =SUM(C25:I25) -> 559.82 | D25: ='分年计划及建设期利息'!E18 -> 503.84 | E25: ='分年计划及建设期利息'!F18 -> 55.98 | F25: ='分年计划及建设期利息'!G18 -> 0 | G25: ='分年计划及建设期利息'!H18 -> 0
A26: ⑯预备费 | B26: =SUM(C26:I26) -> 348.3 | D26: ='分年计划及建设期利息'!E19 -> 313.47 | E26: ='分年计划及建设期利息'!F19 -> 34.83 | F26: ='分年计划及建设期利息'!G19 -> 0 | G26: ='分年计划及建设期利息'!H19 -> 0
A27: ⑰建设期利息 | B27: =SUM(C27:I27) -> 99 | D27: ='分年计划及建设期利息'!E20 -> 99 | E27: ='分年计划及建设期利息'!F20 -> 0 | F27: ='分年计划及建设期利息'!G20 -> 0 | G27: ='分年计划及建设期利息'!H20 -> 0
A28: 合计 | B28: =SUM(B24:B27) -> 5000 | C28: =SUM(C24:C27) -> 0 | D28: =SUM(D24:D27) -> 4509.9 | E28: =SUM(E24:E27) -> 490.1 | F28: =SUM(F24:F27) -> 0 | G28: =SUM(G24:G27) -> 0 | H28: =SUM(H24:H27) -> 0 | I28: =SUM(I24:I27) -> 0 | J28: 此处数据请与建设期所填数据核对，是否勾稽，不要存在无建设期，但存在项目投资的情况
A29: 注：若项目已开工，以前年度的支出按实际支出金额填写；若项目截止目前还未开工，按未来计划支出金额分年度填写
A31: 3、项目建设期运营期相关（万元） | B31: =B28-B36 -> 0 | C31: （⑭+⑮+⑯+⑰）-（⑱+⑲+⑳） | E31: 此处进行测算，存在差异，则需找具体原因 | G31: =B33/B36 -> 0.56 | H31: ⑱/（⑱+⑲+⑳） | I31: 此处不能小于20%，资本金必须大于等于占比20%
A32: 项目筹资情况 | B32: 合计 | C32: 以前年度 | D32: 2022年 | E32: 2023年 | F32: 2024年 | G32: 2025年 | H32: 2026年 | I32: 2027年
A33: ⑱资本金 | B33: =SUM(C33:I33) -> 2800 | D33: ='分年计划及建设期利息'!E22 -> 2309.9 | E33: ='分年计划及建设期利息'!F22 -> 490.1 | F33: ='分年计划及建设期利息'!G22 -> 0 | G33: ='分年计划及建设期利息'!H22 -> 0
A34: ⑲其他融资 | B34: =SUM(C34:I34) -> 0 | J34: 如果该列填数，则前面的资料，一定要囊括这部分的资料
A35: ⑳债券发行 | B35: =SUM(C35:I35) -> 2200 | D35: ='分年计划及建设期利息'!E23 -> 2200 | E35: ='分年计划及建设期利息'!F23 -> 0 | F35: ='分年计划及建设期利息'!G23 -> 0 | G35: ='分年计划及建设期利息'!H23 -> 0
A36: 合计 | B36: =SUM(C36:I36) -> 5000 | C36: =SUM(C33:C35) -> 0 | D36: =SUM(D33:D35) -> 4509.9 | E36: =SUM(E33:E35) -> 490.1 | F36: =SUM(F33:F35) -> 0 | G36: =SUM(G33:G35) -> 0 | H36: =SUM(H33:H35) -> 0 | I36: =SUM(I33:I35) -> 0
A37: 注：此列允许存在差异：如果是负数，则填列无误；如果是正数，则需修改发行债券分年计划，因此当年发债金额不允许大于当年投资金额 | D37: =D35-D28 -> -2309.9 | E37: =E35-E28 -> -490.1 | F37: =F35-F28 -> 0 | G37: =G35-G28 -> 0 | H37: =H35-H28 -> 0 | I37: =I35-I28 -> 0

Sheet 收入成本
A1: 周期 | B1: 年度 | C1: 污水处理收入 | H1: 中水收入 | L1: 污泥处理费 | P1: 经营收 入合计 | R1: 修理费占比折旧（自行键入） | X1: 0.05 | Y1: 金额单位：人民币万元
C2: 负荷率 | D2: 单价（元/t） | E2: 政府补贴（元/t） | F2: 收费数量（t/d) | G2: 年运营收入（万元） | H2: 负荷率 | I2: 单价（元/t） | J2: 收费数量（t/d) | K2: 年运营收入（万元） | L2: 负荷率 | M2: 单价（元/t） | N2: 收费数量（t/d) | O2: 年运营收入（万元） | S2: 年度 | T2: 外购原材料费 | U2: 外购燃料动力 | V2: 污泥处理费 | W2: 工资福利费用 | X2: 年维修成本 | Y2: 其他费用 | Z2: 税费 | AA2: 经营成本合计 | AB2: ='资金流入流出平衡表'!A20 -> 业务成本流出
T3: 0.05 | X3: 0.05 | Y3: 0.02
A4: 建设期 | B4: 1 | S4: 1 | U4: =ROUND(P4*3%,2) -> 0
A5: 运营期 | B5: 2 | C5: 0.5 | D5: 2.5 | E5: 1 | F5: 3000 | G5: =ROUND(C5*(D5+E5)*F5*365/10000,2) -> 191.63 | H5: 0.5 | I5: 0.5 | J5: =F5*0.7 -> 2100 | K5: =ROUND(H5*I5*J5*365/10000,2) -> 19.16 | L5: 0 | M5: 0 | N5: 0 | O5: =ROUND(L5*M5*N5*365/10000,2) -> 0 | P5: =G5+K5+O5 -> 210.79 | R5: 运营期 | S5: 2 | T5: =$X$51*C5 -> 8.4831 | U5: =$AC$50*C5 -> 6.57 | V5: =AC47 -> 1.752 | W5: =ROUND(('项目技术经济指标'!I10*'项目技术经济指标'!J10+'项目技术经济指标'!K10*'项目技术经济指标'!L10)*12/10000,2) -> 17.4 | X5: =ROUND('固定资产折旧'!$E$17*$X$1,2) -> 8.63 | Y5: =ROUND(P5*$Y$3,2) -> 4.22 | Z5: =ROUND('税费计算'!P7,2) -> 0 | AA5: =ROUND(SUM(T5:Z5),2) -> 47.06 | AB5: =AA5-Z5 -> 47.06
B6: 3 | C6: =C5+5% -> 0.55 | D6: =D5 -> 2.5 | E6: =E5 -> 1 | F6: =F5 -> 3000 | G6: =ROUND(C6*(D6+E6)*F6*365/10000,2) -> 210.79 | H6: =H5+5% -> 0.55 | I6: =I5 -> 0.5 | J6: =J5 -> 2100 | K6: =ROUND(H6*I6*J6*365/10000,2) -> 21.08 | L6: =H6 -> 0.55 | M6: =M5 -> 0 | N6: =N5 -> 0 | O6: =ROUND(L6*M6*N6*365/10000,2) -> 0 | P6: =G6+K6+O6 -> 231.87 | S6: 3 | T6: =$X$51*C6 -> 9.33141 | U6: =$AC$50*C6 -> 7.227 | V6: =V5 -> 1.752 | W6: =W5 -> 17.4 | X6: =ROUND('固定资产折旧'!$E$17*$X$1,2) -> 8.63 | Y6: =ROUND(P6*$Y$3,2) -> 4.64 | Z6: =ROUND('税费计算'!P8,2) -> 0 | AA6: =ROUND(SUM(T6:Z6),2) -> 48.98 | AB6: =AA6-Z6 -> 48.98
B7: 4 | C7: =C6+5% -> 0.6 | D7: =D6 -> 2.5 | E7: =E6 -> 1 | F7: =F6 -> 3000 | G7: =ROUND(C7*(D7+E7)*F7*365/10000,2) -> 229.95 | H7: =H6+5% -> 0.6 | I7: =I6 -> 0.5 | J7: =J6 -> 2100 | K7: =ROUND(H7*I7*J7*365/10000,2) -> 23 | L7: =H7 -> 0.6 | M7: =M6 -> 0 | N7: =N6 -> 0 | O7: =ROUND(L7*M7*N7*365/10000,2) -> 0 | P7: =G7+K7+O7 -> 252.95 | S7: 4 | T7: =$X$51*C7 -> 10.17972 | U7: =$AC$50*C7 -> 7.884 | V7: =V6 -> 1.752 | W7: =W6 -> 17.4 | X7: =ROUND('固定资产折旧'!$E$17*$X$1,2) -> 8.63 | Y7: =ROUND(P7*$Y$3,2) -> 5.06 | Z7: =ROUND('税费计算'!P9,2) -> 0 | AA7: =ROUND(SUM(T7:Z7),2) -> 50.91 | AB7: =AA7-Z7 -> 50.91
B8: 5 | C8: =C7+5% -> 0.65 | D8: =D7 -> 2.5 | E8: =E7 -> 1 | F8: =F7 -> 3000 | G8: =ROUND(C8*(D8+E8)*F8*365/10000,2) -> 249.11 | H8: =H7+5% -> 0.65 | I8: =I7 -> 0.5 | J8: =J7 -> 2100 | K8: =ROUND(H8*I8*J8*365/10000,2) -> 24.91 | L8: =H8 -> 0.65 | M8: =M7 -> 0 | N8: =N7 -> 0 | O8: =ROUND(L8*M8*N8*365/10000,2) -> 0 | P8: =G8+K8+O8 -> 274.02 | S8: 5 | T8: =$X$51*C8 -> 11.02803 | U8: =$AC$50*C8 -> 8.541 | V8: =V7 -> 1.752 | W8: =W7 -> 17.4 | X8: =ROUND('固定资产折旧'!$E$17*$X$1,2) -> 8.63 | Y8: =ROUND(P8*$Y$3,2) -> 5.48 | Z8: =ROUND('税费计算'!P10,2) -> 0 | AA8: =ROUND(SUM(T8:Z8),2) -> 52.83 | AB8: =AA8-Z8 -> 52.83
B9: 6 | C9: =C8+5% -> 0.7 | D9: =D8 -> 2.5 | E9: =E8 -> 1 | F9: =F8 -> 3000 | G9: =ROUND(C9*(D9+E9)*F9*365/10000,2) -> 268.28 | H9: =H8+5% -> 0.7 | I9: =I8 -> 0.5 | J9: =J8 -> 2100 | K9: =ROUND(H9*I9*J9*365/10000,2) -> 26.83 | L9: =H9 -> 0.7 | M9: =M8 -> 0 | N9: =N8 -> 0 | O9: =ROUND(L9*M9*N9*365/10000,2) -> 0 | P9: =G9+K9+O9 -> 295.11 | S9: 6 | T9: =$X$51*C9 -> 11.87634 | U9: =$AC$50*C9 -> 9.198 | V9: =V8 -> 1.752 | W9: =W8 -> 17.4 | X9: =ROUND('固定资产折旧'!$E$17*$X$1,2) -> 8.63 | Y9: =ROUND(P9*$Y$3,2) -> 5.9 | Z9: =ROUND('税费计算'!P11,2) -> 0 | AA9: =ROUND(SUM(T9:Z9),2) -> 54.76 | AB9: =AA9-Z9 -> 54.76
B10: 7 | C10: =C9+5% -> 0.75 | D10: =ROUND(D9*$C$36,2) -> 2.75 | E10: =E9 -> 1 | F10: =F9 -> 3000 | G10: =ROUND(C10*(D10+E10)*F10*365/10000,2) -> 307.97 | H10: =H9+5% -> 0.75 | I10: =ROUND(I9*$C$36,2) -> 0.55 | J10: =J9 -> 2100 | K10: =ROUND(H10*I10*J10*365/10000,2) -> 31.62 | L10: =H10 -> 0.75 | M10: =ROUND(M9*$C$36,2) -> 0 | N10: =N9 -> 0 | O10: =ROUND(L10*M10*N10*365/10000,2) -> 0 | P10: =G10+K10+O10 -> 339.59 | S10: 7 | T10: =$X$51*C10 -> 12.72465 | U10: =$AC$50*C10 -> 9.855 | V10: =V9 -> 1.752 | W10: =ROUND(W5*(1+'项目技术经济指标'!$M$10),2) -> 19.14 | X10: =ROUND(X5*(1+$X$3),2) -> 9.06 | Y10: =ROUND(P10*$Y$3,2) -> 6.79 | Z10: =ROUND('税费计算'!P12,2) -> 0 | AA10: =ROUND(SUM(T10:Z10),2) -> 59.32 | AB10: =AA10-Z10 -> 59.32
B11: 8 | C11: =C10 -> 0.75 | D11: =D10 -> 2.75 | E11: =E10 -> 1 | F11: =F10 -> 3000 | G11: =ROUND(C11*(D11+E11)*F11*365/10000,2) -> 307.97 | H11: =H10 -> 0.75 | I11: =I10 -> 0.55 | J11: =J10 -> 2100 | K11: =ROUND(H11*I11*J11*365/10000,2) -> 31.62 | L11: =H11 -> 0.75 | M11: =M10 -> 0 | N11: =N10 -> 0 | O11: =ROUND(L11*M11*N11*365/10000,2) -> 0 | P11: =G11+K11+O11 -> 339.59 | S11: 8 | T11: =$X$51*C11 -> 12.72465 | U11: =$AC$50*C11 -> 9.855 | V11: =V10 -> 1.752 | W11: =ROUND(W6*(1+'项目技术经济指标'!$M$10),2) -> 19.14 | X11: =ROUND(X6*(1+$X$3),2) -> 9.06 | Y11: =ROUND(P11*$Y$3,2) -> 6.79 | Z11: =ROUND('税费计算'!P13,2) -> 0 | AA11: =ROUND(SUM(T11:Z11),2) -> 59.32 | AB11: =AA11-Z11 -> 59.32
B12: 9 | C12: =C11 -> 0.75 | D12: =D11 -> 2.75 | E12: =E11 -> 1 | F12: =F11 -> 3000 | G12: =ROUND(C12*(D12+E12)*F12*365/10000,2) -> 307.97 | H12: =H11 -> 0.75 | I12: =I11 -> 0.55 | J12: =J11 -> 2100 | K12: =ROUND(H12*I12*J12*365/10000,2) -> 31.62 | L12: =H12 -> 0.75 | M12: =M11 -> 0 | N12: =N11 -> 0 | O12: =ROUND(L12*M12*N12*365/10000,2) -> 0 | P12: =G12+K12+O12 -> 339.59 | S12: 9 | T12: =$X$51*C12 -> 12.72465 | U12: =$AC$50*C12 -> 9.855 | V12: =V11 -> 1.752 | W12: =ROUND(W7*(1+'项目技术经济指标'!$M$10),2) -> 19.14 | X12: =ROUND(X7*(1+$X$3),2) -> 9.06 | Y12: =ROUND(P12*$Y$3,2) -> 6.79 | Z12: =ROUND('税费计算'!P14,2) -> 0 | AA12: =ROUND(SUM(T12:Z12),2) -> 59.32 | AB12: =AA12-Z12 -> 59.32
B13: 10 | C13: =C12 -> 0.75 | D13: =D12 -> 2.75 | E13: =E12 -> 1 | F13: =F12 -> 3000 | G13: =ROUND(C13*(D13+E13)*F13*365/10000,2) -> 307.97 | H13: =H12 -> 0.75 | I13: =I12 -> 0.55 | J13: =J12 -> 2100 | K13: =ROUND(H13*I13*J13*365/10000,2) -> 31.62 | L13: =H13 -> 0.75 | M13: =M12 -> 0 | N13: =N12 -> 0 | O13: =ROUND(L13*M13*N13*365/10000,2) -> 0 | P13: =G13+K13+O13 -> 339.59 | S13: 10 | T13: =$X$51*C13 -> 12.72465 | U13: =$AC$50*C13 -> 9.855 | V13: =V12 -> 1.752 | W13: =ROUND(W8*(1+'项目技术经济指标'!$M$10),2) -> 19.14 | X13: =ROUND(X8*(1+$X$3),2) -> 9.06 | Y13: =ROUND(P13*$Y$3,2) -> 6.79 | Z13: =ROUND('税费计算'!P15,2) -> 0 | AA13: =ROUND(SUM(T13:Z13),2) -> 59.32 | AB13: =AA13-Z13 -> 59.32
B14: 11 | C14: =C13 -> 0.75 | D14: =D13 -> 2.75 | E14: =E13 -> 1 | F14: =F13 -> 3000 | G14: =ROUND(C14*(D14+E14)*F14*365/10000,2) -> 307.97 | H14: =H13 -> 0.75 | I14: =I13 -> 0.55 | J14: =J13 -> 2100 | K14: =ROUND(H14*I14*J14*365/10000,2) -> 31.62 | L14: =H14 -> 0.75 | M14: =M13 -> 0 | N14: =N13 -> 0 | O14: =ROUND(L14*M14*N14*365/10000,2) -> 0 | P14: =G14+K14+O14 -> 339.59 | S14: 11 | T14: =$X$51*C14 -> 12.72465 | U14: =$AC$50*C14 -> 9.855 | V14: =V13 -> 1.752 | W14: =ROUND(W9*(1+'项目技术经济指标'!$M$10),2) -> 19.14 | X14: =ROUND(X9*(1+$X$3),2) -> 9.06 | Y14: =ROUND(P14*$Y$3,2) -> 6.79 | Z14: =ROUND('税费计算'!P16,2) -> 0 | AA14: =ROUND(SUM(T14:Z14),2) -> 59.32 | AB14: =AA14-Z14 -> 59.32
B15: 12 | C15: =C14 -> 0.75 | D15: =ROUND(D14*$C$36,2) -> 3.03 | E15: =E14 -> 1 | F15: =F14 -> 3000 | G15: =ROUND(C15*(D15+E15)*F15*365/10000,2) -> 330.96 | H15: =H14 -> 0.75 | I15: =ROUND(I14*$C$36,2) -> 0.61 | J15: =J14 -> 2100 | K15: =ROUND(H15*I15*J15*365/10000,2) -> 35.07 | L15: =H15 -> 0.75 | M15: =ROUND(M14*$C$36,2) -> 0 | N15: =N14 -> 0 | O15: =ROUND(L15*M15*N15*365/10000,2) -> 0 | P15: =G15+K15+O15 -> 366.03 | S15: 12 | T15: =$X$51*C15 -> 12.72465 | U15: =$AC$50*C15 -> 9.855 | V15: =V14 -> 1.752 | W15: =ROUND(W10*(1+'项目技术经济指标'!$M$10),2) -> 21.05 | X15: =ROUND(X10*(1+$X$3),2) -> 9.51 | Y15: =ROUND(P15*$Y$3,2) -> 7.32 | Z15: =ROUND('税费计算'!P17,2) -> 0 | AA15: =ROUND(SUM(T15:Z15),2) -> 62.21 | AB15: =AA15-Z15 -> 62.21
B16: 13 | C16: =C15 -> 0.75 | D16: =D15 -> 3.03 | E16: =E15 -> 1 | F16: =F15 -> 3000 | G16: =ROUND(C16*(D16+E16)*F16*365/10000,2) -> 330.96 | H16: =H15 -> 0.75 | I16: =I15 -> 0.61 | J16: =J15 -> 2100 | K16: =ROUND(H16*I16*J16*365/10000,2) -> 35.07 | L16: =H16 -> 0.75 | M16: =M15 -> 0 | N16: =N15 -> 0 | O16: =ROUND(L16*M16*N16*365/10000,2) -> 0 | P16: =G16+K16+O16 -> 366.03 | S16: 13 | T16: =$X$51*C16 -> 12.72465 | U16: =$AC$50*C16 -> 9.855 | V16: =V15 -> 1.752 | W16: =ROUND(W11*(1+'项目技术经济指标'!$M$10),2) -> 21.05 | X16: =ROUND(X11*(1+$X$3),2) -> 9.51 | Y16: =ROUND(P16*$Y$3,2) -> 7.32 | Z16: =ROUND('税费计算'!P18,2) -> 0 | AA16: =ROUND(SUM(T16:Z16),2) -> 62.21 | AB16: =AA16-Z16 -> 62.21
B17: 14 | C17: =C16 -> 0.75 | D17: =D16 -> 3.03 | E17: =E16 -> 1 | F17: =F16 -> 3000 | G17: =ROUND(C17*(D17+E17)*F17*365/10000,2) -> 330.96 | H17: =H16 -> 0.75 | I17: =I16 -> 0.61 | J17: =J16 -> 2100 | K17: =ROUND(H17*I17*J17*365/10000,2) -> 35.07 | L17: =H17 -> 0.75 | M17: =M16 -> 0 | N17: =N16 -> 0 | O17: =ROUND(L17*M17*N17*365/10000,2) -> 0 | P17: =G17+K17+O17 -> 366.03 | S17: 14 | T17: =$X$51*C17 -> 12.72465 | U17: =$AC$50*C17 -> 9.855 | V17: =V16 -> 1.752 | W17: =ROUND(W12*(1+'项目技术经济指标'!$M$10),2) -> 21.05 | X17: =ROUND(X12*(1+$X$3),2)+'总投资估算'!E3/2 -> 291.96 | Y17: =ROUND(P17*$Y$3,2) -> 7.32 | Z17: =ROUND('税费计算'!P19,2) -> 0 | AA17: =ROUND(SUM(T17:Z17),2) -> 344.66 | AB17: =AA17-Z17 -> 344.66
B18: 15 | C18: =C17 -> 0.75 | D18: =D17 -> 3.03 | E18: =E17 -> 1 | F18: =F17 -> 3000 | G18: =ROUND(C18*(D18+E18)*F18*365/10000,2) -> 330.96 | H18: =H17 -> 0.75 | I18: =I17 -> 0.61 | J18: =J17 -> 2100 | K18: =ROUND(H18*I18*J18*365/10000,2) -> 35.07 | L18: =H18 -> 0.75 | M18: =M17 -> 0 | N18: =N17 -> 0 | O18: =ROUND(L18*M18*N18*365/10000,2) -> 0 | P18: =G18+K18+O18 -> 366.03 | S18: 15 | T18: =$X$51*C18 -> 12.72465 | U18: =$AC$50*C18 -> 9.855 | V18: =V17 -> 1.752 | W18: =ROUND(W13*(1+'项目技术经济指标'!$M$10),2) -> 21.05 | X18: =ROUND(X13*(1+$X$3),2)+'总投资估算'!E3/2 -> 291.96 | Y18: =ROUND(P18*$Y$3,2) -> 7.32 | Z18: =ROUND('税费计算'!P20,2) -> 0 | AA18: =ROUND(SUM(T18:Z18),2) -> 344.66 | AB18: =AA18-Z18 -> 344.66
B19: 16 | C19: =C18 -> 0.75 | D19: =D18 -> 3.03 | E19: =E18 -> 1 | F19: =F18 -> 3000 | G19: =ROUND(C19*(D19+E19)*F19*365/10000,2) -> 330.96 | H19: =H18 -> 0.75 | I19: =I18 -> 0.61 | J19: =J18 -> 2100 | K19: =ROUND(H19*I19*J19*365/10000,2) -> 35.07 | L19: =H19 -> 0.75 | M19: =M18 -> 0 | N19: =N18 -> 0 | O19: =ROUND(L19*M19*N19*365/10000,2) -> 0 | P19: =G19+K19+O19 -> 366.03 | S19: 16 | T19: =$X$51*C19 -> 12.72465 | U19: =$AC$50*C19 -> 9.855 | V19: =V18 -> 1.752 | W19: =ROUND(W14*(1+'项目技术经济指标'!$M$10),2) -> 21.05 | X19: =ROUND(X14*(1+$X$3),2) -> 9.51 | Y19: =ROUND(P19*$Y$3,2) -> 7.32 | Z19: =ROUND('税费计算'!P21,2) -> 0 | AA19: =ROUND(SUM(T19:Z19),2) -> 62.21 | AB19: =AA19-Z19 -> 62.21
B20: 17 | C20: =C19 -> 0.75 | D20: =ROUND(D15*$C$36,2) -> 3.33 | E20: =E19 -> 1 | F20: =F19 -> 3000 | G20: =ROUND(C20*(D20+E20)*F20*365/10000,2) -> 355.6 | H20: =H19 -> 0.75 | I20: =ROUND(I15*$C$36,2) -> 0.67 | J20: =J19 -> 2100 | K20: =ROUND(H20*I20*J20*365/10000,2) -> 38.52 | L20: =H20 -> 0.75 | M20: =ROUND(M19*$C$36,2) -> 0 | N20: =N19 -> 0 | O20: =ROUND(L20*M20*N20*365/10000,2) -> 0 | P20: =G20+K20+O20 -> 394.12 | S20: 17 | T20: =$X$51*C20 -> 12.72465 | U20: =$AC$50*C20 -> 9.855 | V20: =V19 -> 1.752 | W20: =ROUND(W15*(1+'项目技术经济指标'!$M$10),2) -> 23.16 | X20: =ROUND(X15*(1+$X$3),2) -> 9.99 | Y20: =ROUND(P20*$Y$3,2) -> 7.88 | Z20: =ROUND('税费计算'!P22,2) -> 0 | AA20: =ROUND(SUM(T20:Z20),2) -> 65.36 | AB20: =AA20-Z20 -> 65.36
B21: 18 | C21: =C20 -> 0.75 | D21: =D20 -> 3.33 | E21: =E20 -> 1 | F21: =F20 -> 3000 | G21: =ROUND(C21*(D21+E21)*F21*365/10000,2) -> 355.6 | H21: =H20 -> 0.75 | I21: =I20 -> 0.67 | J21: =J20 -> 2100 | K21: =ROUND(H21*I21*J21*365/10000,2) -> 38.52 | L21: =H21 -> 0.75 | M21: =M20 -> 0 | N21: =N20 -> 0 | O21: =ROUND(L21*M21*N21*365/10000,2) -> 0 | P21: =G21+K21+O21 -> 394.12 | S21: 18 | T21: =$X$51*C21 -> 12.72465 | U21: =$AC$50*C21 -> 9.855 | V21: =V20 -> 1.752 | W21: =ROUND(W16*(1+'项目技术经济指标'!$M$10),2) -> 23.16 | X21: =ROUND(X16*(1+$X$3),2) -> 9.99 | Y21: =ROUND(P21*$Y$3,2) -> 7.88 | Z21: =ROUND('税费计算'!P23,2) -> 0 | AA21: =ROUND(SUM(T21:Z21),2) -> 65.36 | AB21: =AA21-Z21 -> 65.36
B22: 19 | C22: =C21 -> 0.75 | D22: =D21 -> 3.33 | E22: =E21 -> 1 | F22: =F21 -> 3000 | G22: =ROUND(C22*(D22+E22)*F22*365/10000,2) -> 355.6 | H22: =H21 -> 0.75 | I22: =I21 -> 0.67 | J22: =J21 -> 2100 | K22: =ROUND(H22*I22*J22*365/10000,2) -> 38.52 | L22: =H22 -> 0.75 | M22: =M21 -> 0 | N22: =N21 -> 0 | O22: =ROUND(L22*M22*N22*365/10000,2) -> 0 | P22: =G22+K22+O22 -> 394.12 | S22: 19 | T22: =$X$51*C22 -> 12.72465 | U22: =$AC$50*C22 -> 9.855 | V22: =V21 -> 1.752 | W22: =ROUND(W17*(1+'项目技术经济指标'!$M$10),2) -> 23.16 | X22: =ROUND(X19*(1+$X$3),2) -> 9.99 | Y22: =ROUND(P22*$Y$3,2) -> 7.88 | Z22: =ROUND('税费计算'!P24,2) -> 0 | AA22: =ROUND(SUM(T22:Z22),2) -> 65.36 | AB22: =AA22-Z22 -> 65.36
B23: 20 | C23: =C22 -> 0.75 | D23: =D22 -> 3.33 | E23: =E22 -> 1 | F23: =F22 -> 3000 | G23: =ROUND(C23*(D23+E23)*F23*365/10000,2) -> 355.6 | H23: =H22 -> 0.75 | I23: =I22 -> 0.67 | J23: =J22 -> 2100 | K23: =ROUND(H23*I23*J23*365/10000,2) -> 38.52 | L23: =H23 -> 0.75 | M23: =M22 -> 0 | N23: =N22 -> 0 | O23: =ROUND(L23*M23*N23*365/10000,2) -> 0 | P23: =G23+K23+O23 -> 394.12 | S23: 20 | T23: =$X$51*C23 -> 12.72465 | U23: =$AC$50*C23 -> 9.855 | V23: =V22 -> 1.752 | W23: =ROUND(W18*(1+'项目技术经济指标'!$M$10),2) -> 23.16 | X23: =ROUND(X19*(1+$X$3),2) -> 9.99 | Y23: =ROUND(P23*$Y$3,2) -> 7.88 | Z23: =ROUND('税费计算'!P25,2) -> 0 | AA23: =ROUND(SUM(T23:Z23),2) -> 65.36 | AB23: =AA23-Z23 -> 65.36
B24: 21 | C24: =C23 -> 0.75 | D24: =D23 -> 3.33 | E24: =E23 -> 1 | F24: =F23 -> 3000 | G24: =ROUND(C24*(D24+E24)*F24*365/10000,2) -> 355.6 | H24: =H23 -> 0.75 | I24: =I23 -> 0.67 | J24: =J23 -> 2100 | K24: =ROUND(H24*I24*J24*365/10000,2) -> 38.52 | L24: =H24 -> 0.75 | M24: =M23 -> 0 | N24: =N23 -> 0 | O24: =ROUND(L24*M24*N24*365/10000,2) -> 0 | P24: =G24+K24+O24 -> 394.12 | S24: 21 | T24: =$X$51*C24 -> 12.72465 | U24: =$AC$50*C24 -> 9.855 | V24: =V23 -> 1.752 | W24: =ROUND(W19*(1+'项目技术经济指标'!$M$10),2) -> 23.16 | X24: =ROUND(X19*(1+$X$3),2) -> 9.99 | Y24: =ROUND(P24*$Y$3,2) -> 7.88 | Z24: =ROUND('税费计算'!P26,2) -> 0 | AA24: =ROUND(SUM(T24:Z24),2) -> 65.36 | AB24: =AA24-Z24 -> 65.36
B25: 22 | C25: =C24 -> 0.75 | D25: =ROUND(D20*$C$36,2) -> 3.66 | E25: =E24 -> 1 | F25: =F24 -> 3000 | G25: =ROUND(C25*(D25+E25)*F25*365/10000,2) -> 382.7 | H25: =H24 -> 0.75 | I25: =ROUND(I20*$C$36,2) -> 0.74 | J25: =J24 -> 2100 | K25: =ROUND(H25*I25*J25*365/10000,2) -> 42.54 | L25: =H25 -> 0.75 | M25: =ROUND(M24*$C$36,2) -> 0 | N25: =N24 -> 0 | O25: =ROUND(L25*M25*N25*365/10000,2) -> 0 | P25: =G25+K25+O25 -> 425.24 | S25: 22 | T25: =$X$51*C25 -> 12.72465 | U25: =$AC$50*C25 -> 9.855 | V25: =V24 -> 1.752 | W25: =ROUND(W20*(1+'项目技术经济指标'!$M$10),2) -> 25.48 | X25: =ROUND(X20*(1+$X$3),2) -> 10.49 | Y25: =ROUND(P25*$Y$3,2) -> 8.5 | Z25: =ROUND('税费计算'!P27,2) -> 0 | AA25: =ROUND(SUM(T25:Z25),2) -> 68.8 | AB25: =AA25-Z25 -> 68.8
B26: 23 | C26: =C25 -> 0.75 | D26: =D25 -> 3.66 | E26: =E25 -> 1 | F26: =F25 -> 3000 | G26: =ROUND(C26*(D26+E26)*F26*365/10000,2) -> 382.7 | H26: =H25 -> 0.75 | I26: =I25 -> 0.74 | J26: =J25 -> 2100 | K26: =ROUND(H26*I26*J26*365/10000,2) -> 42.54 | L26: =H26 -> 0.75 | M26: =M25 -> 0 | N26: =N25 -> 0 | O26: =ROUND(L26*M26*N26*365/10000,2) -> 0 | P26: =G26+K26+O26 -> 425.24 | S26: 23 | T26: =$X$51*C26 -> 12.72465 | U26: =$AC$50*C26 -> 9.855 | V26: =V25 -> 1.752 | W26: =ROUND(W21*(1+'项目技术经济指标'!$M$10),2) -> 25.48 | X26: =ROUND(X21*(1+$X$3),2) -> 10.49 | Y26: =ROUND(P26*$Y$3,2) -> 8.5 | Z26: =ROUND('税费计算'!P28,2) -> 0 | AA26: =ROUND(SUM(T26:Z26),2) -> 68.8 | AB26: =AA26-Z26 -> 68.8
B27: 24 | C27: =C26 -> 0.75 | D27: =D26 -> 3.66 | E27: =E26 -> 1 | F27: =F26 -> 3000 | G27: =ROUND(C27*(D27+E27)*F27*365/10000,2) -> 382.7 | H27: =H26 -> 0.75 | I27: =I26 -> 0.74 | J27: =J26 -> 2100 | K27: =ROUND(H27*I27*J27*365/10000,2) -> 42.54 | L27: =H27 -> 0.75 | M27: =M26 -> 0 | N27: =N26 -> 0 | O27: =ROUND(L27*M27*N27*365/10000,2) -> 0 | P27: =G27+K27+O27 -> 425.24 | S27: 24 | T27: =$X$51*C27 -> 12.72465 | U27: =$AC$50*C27 -> 9.855 | V27: =V26 -> 1.752 | W27: =ROUND(W22*(1+'项目技术经济指标'!$M$10),2) -> 25.48 | X27: =ROUND(X22*(1+$X$3),2) -> 10.49 | Y27: =ROUND(P27*$Y$3,2) -> 8.5 | Z27: =ROUND('税费计算'!P29,2) -> 10.57 | AA27: =ROUND(SUM(T27:Z27),2) -> 79.37 | AB27: =AA27-Z27 -> 68.8
B28: 25 | C28: =C27 -> 0.75 | D28: =D27 -> 3.66 | E28: =E27 -> 1 | F28: =F27 -> 3000 | G28: =ROUND(C28*(D28+E28)*F28*365/10000,2) -> 382.7 | H28: =H27 -> 0.75 | I28: =I27 -> 0.74 | J28: =J27 -> 2100 | K28: =ROUND(H28*I28*J28*365/10000,2) -> 42.54 | L28: =H28 -> 0.75 | M28: =M27 -> 0 | N28: =N27 -> 0 | O28: =ROUND(L28*M28*N28*365/10000,2) -> 0 | P28: =G28+K28+O28 -> 425.24 | S28: 25 | T28: =$X$51*C28 -> 12.72465 | U28: =$AC$50*C28 -> 9.855 | V28: =V27 -> 1.752 | W28: =ROUND(W23*(1+'项目技术经济指标'!$M$10),2) -> 25.48 | X28: =ROUND(X23*(1+$X$3),2) -> 10.49 | Y28: =ROUND(P28*$Y$3,2) -> 8.5 | Z28: =ROUND('税费计算'!P30,2) -> 25.79 | AA28: =ROUND(SUM(T28:Z28),2) -> 94.59 | AB28: =AA28-Z28 -> 68.8
B29: 26 | C29: =C28 -> 0.75 | D29: =D28 -> 3.66 | E29: =E28 -> 1 | F29: =F28 -> 3000 | G29: =ROUND(C29*(D29+E29)*F29*365/10000,2) -> 382.7 | H29: =H28 -> 0.75 | I29: =I28 -> 0.74 | J29: =J28 -> 2100 | K29: =ROUND(H29*I29*J29*365/10000,2) -> 42.54 | L29: =H29 -> 0.75 | M29: =M28 -> 0 | N29: =N28 -> 0 | O29: =ROUND(L29*M29*N29*365/10000,2) -> 0 | P29: =G29+K29+O29 -> 425.24 | S29: 26 | T29: =$X$51*C29 -> 12.72465 | U29: =$AC$50*C29 -> 9.855 | V29: =V28 -> 1.752 | W29: =ROUND(W24*(1+'项目技术经济指标'!$M$10),2) -> 25.48 | X29: =ROUND(X24*(1+$X$3),2) -> 10.49 | Y29: =ROUND(P29*$Y$3,2) -> 8.5 | Z29: =ROUND('税费计算'!P31,2) -> 28.01 | AA29: =ROUND(SUM(T29:Z29),2) -> 96.81 | AB29: =AA29-Z29 -> 68.8
B30: 27 | C30: =C29 -> 0.75 | D30: =ROUND(D25*$C$36,2) -> 4.03 | E30: =E29 -> 1 | F30: =F29 -> 3000 | G30: =ROUND(C30*(D30+E30)*F30*365/10000,2) -> 413.09 | H30: =H29 -> 0.75 | I30: =ROUND(I25*$C$36,2) -> 0.81 | J30: =J29 -> 2100 | K30: =ROUND(H30*I30*J30*365/10000,2) -> 46.56 | L30: =H30 -> 0.75 | M30: =ROUND(M29*$C$36,2) -> 0 | N30: =N29 -> 0 | O30: =ROUND(L30*M30*N30*365/10000,2) -> 0 | P30: =G30+K30+O30 -> 459.65 | S30: 27 | T30: =$X$51*C30 -> 12.72465 | U30: =$AC$50*C30 -> 9.855 | V30: =V29 -> 1.752 | W30: =ROUND(W25*(1+'项目技术经济指标'!$M$10),2) -> 28.03 | X30: =ROUND(X25*(1+$X$3),2) -> 11.01 | Y30: =ROUND(P30*$Y$3,2) -> 9.19 | Z30: =ROUND('税费计算'!P32,2) -> 28.01 | AA30: =ROUND(SUM(T30:Z30),2) -> 100.57 | AB30: =AA30-Z30 -> 72.56
B31: 28 | C31: =C30 -> 0.75 | D31: =D30 -> 4.03 | E31: =E30 -> 1 | F31: =F30 -> 3000 | G31: =ROUND(C31*(D31+E31)*F31*365/10000,2) -> 413.09 | H31: =H30 -> 0.75 | I31: =I30 -> 0.81 | J31: =J30 -> 2100 | K31: =ROUND(H31*I31*J31*365/10000,2) -> 46.56 | L31: =H31 -> 0.75 | M31: =M30 -> 0 | N31: =N30 -> 0 | O31: =ROUND(L31*M31*N31*365/10000,2) -> 0 | P31: =G31+K31+O31 -> 459.65 | S31: 28 | T31: =$X$51*C31 -> 12.72465 | U31: =$AC$50*C31 -> 9.855 | V31: =V30 -> 1.752 | W31: =ROUND(W26*(1+'项目技术经济指标'!$M$10),2) -> 28.03 | X31: =ROUND(X26*(1+$X$3),2) -> 11.01 | Y31: =ROUND(P31*$Y$3,2) -> 9.19 | Z31: =ROUND('税费计算'!P33,2) -> 28.01 | AA31: =ROUND(SUM(T31:Z31),2) -> 100.57 | AB31: =AA31-Z31 -> 72.56
B32: 29 | C32: =C31 -> 0.75 | D32: =D31 -> 4.03 | E32: =E31 -> 1 | F32: =F31 -> 3000 | G32: =ROUND(C32*(D32+E32)*F32*365/10000,2) -> 413.09 | H32: =H31 -> 0.75 | I32: =I31 -> 0.81 | J32: =J31 -> 2100 | K32: =ROUND(H32*I32*J32*365/10000,2) -> 46.56 | L32: =H32 -> 0.75 | M32: =M31 -> 0 | N32: =N31 -> 0 | O32: =ROUND(L32*M32*N32*365/10000,2) -> 0 | P32: =G32+K32+O32 -> 459.65 | S32: 29 | T32: =$X$51*C32 -> 12.72465 | U32: =$AC$50*C32 -> 9.855 | V32: =V31 -> 1.752 | W32: =ROUND(W27*(1+'项目技术经济指标'!$M$10),2) -> 28.03 | X32: =ROUND(X27*(1+$X$3),2) -> 11.01 | Y32: =ROUND(P32*$Y$3,2) -> 9.19 | Z32: =ROUND('税费计算'!P34,2) -> 28.01 | AA32: =ROUND(SUM(T32:Z32),2) -> 100.57 | AB32: =AA32-Z32 -> 72.56
B33: 30 | C33: =C32 -> 0.75 | D33: =D32 -> 4.03 | E33: =E32 -> 1 | F33: =F32 -> 3000 | G33: =ROUND(C33*(D33+E33)*F33*365/10000,2) -> 413.09 | H33: =H32 -> 0.75 | I33: =I32 -> 0.81 | J33: =J32 -> 2100 | K33: =ROUND(H33*I33*J33*365/10000,2) -> 46.56 | L33: =H33 -> 0.75 | M33: =M32 -> 0 | N33: =N32 -> 0 | O33: =ROUND(L33*M33*N33*365/10000,2) -> 0 | P33: =G33+K33+O33 -> 459.65 | S33: 30 | T33: =$X$51*C33 -> 12.72465 | U33: =$AC$50*C33 -> 9.855 | V33: =V32 -> 1.752 | W33: =ROUND(W28*(1+'项目技术经济指标'!$M$10),2) -> 28.03 | X33: =ROUND(X28*(1+$X$3),2) -> 11.01 | Y33: =ROUND(P33*$Y$3,2) -> 9.19 | Z33: =ROUND('税费计算'!P35,2) -> 0 | AA33: =ROUND(SUM(T33:Z33),2) -> 72.56 | AB33: =AA33-Z33 -> 72.56
V34: =V33 -> 1.752
A35: 合计 | G35: =SUM(G4:G34) -> 9688.27 | K35: =SUM(K4:K34) -> 1039.97 | O35: =SUM(O4:O34) -> 0 | P35: =SUM(P4:P34) -> 10728.24 | R35: 合计 | T35: =SUM(T4:T34) -> 356.2902 | U35: =SUM(U4:U34) -> 275.94 | V35: =SUM(V4:V34) -> 52.56 | W35: =SUM(W4:W34) -> 643.27 | X35: =SUM(X4:X34) -> 847.34 | Y35: =SUM(Y4:Y34) -> 214.51 | Z35: =SUM(Z4:Z34) -> 148.4 | AA35: =SUM(AA4:AA34) -> 2536.53 | AB35: =SUM(AB5:AB34) -> 2388.13 | AC35: =P35-AA35 -> 8191.71
C36: 1.1
T45: 参考同类型项目
T46: 原材料 | U46: 消耗量（吨） | W46: 单价/吨 | X46: 总价（万元） | Y46: 污水处理量（吨） | Z46: 每万吨污水 淤泥产生量（吨） | AA46: 年淤泥量（吨） | AB46: 处理单价（元/吨） | AC46: 淤泥处理费
T47: 药剂 PAC | U47: =$F$5/20000*160 -> 24 | W47: 1800 | X47: =U47*W47/10000 -> 4.32 | Y47: =F5 -> 3000 | Z47: 1 | AA47: =Y47/10000*Z47*365 -> 109.5 | AB47: 160 | AC47: =AA47*AB47/10000 -> 1.752
T48: 药剂 PAM | U48: =$F$5/20000*7.8 -> 1.17 | W48: 28600 | X48: =U48*W48/10000 -> 3.3462
...

Sheet 税费计算
A1: 年份 | B1: 增值税 | L1: 城市建设 维护税 | M1: 教育费 附加 | N1: 地方教育费附加 | O1: 房产税 | P1: 税费合计 | Q1: 工程施工进项税计算表
B2: 销项税 | G2: 进项税 | K2: 进销项 抵扣后 合计 | Q2: 序号 | R2: 项目 | S2: 含税金额 | T2: 税率 | U2: 进项税 | V2: 不含税金额（用于折旧）
B3: ='收入成本'!C1 -> 污水处理收入 | D3: ='收入成本'!H1 -> 中水收入 | F3: 销项税 合计 | G3: 外购燃料动力 | H3: 维修 | I3: 进项税 合计 | J3: 工程施工留抵进项余额 | Q3: 1.1 | R3: 工程费用 | S3: ='项目技术经济指标'!D30 -> 3992.88 | T3: - | U3: =U4+U5 -> 348.03 | V3: =S3-U3 -> 3644.85
B4: 0.06 | D4: 0.09 | G4: 0.13 | H4: 0.06 | L4: 0.05 | M4: 0.03 | N4: 0.02 | Q4: 1.1.1 | R4: 建筑安装工程费 | S4: ='项目技术经济指标'!D31 -> 3427.98 | T4: 0.09 | U4: =ROUND(S4/(1+T4)*T4,2) -> 283.04 | V4: =S4-U4 -> 3144.94
A5: 1 | B5: =ROUND('收入成本'!G4/(1+$B$4)*$B$4*0.3,2) -> 0 | D5: =ROUND('收入成本'!K4/(1+$D$4)*$D$4*0.5,2) -> 0 | E5: =ROUND('收入成本'!O4/(1+$E$4)*$E$4,2) -> 0 | F5: =SUM(B5:E5) -> 0 | G5: =ROUND('收入成本'!U4/(1+$G$4)*$G$4,2) -> 0 | H5: =ROUND('收入成本'!X4/(1+$H$4)*$H$4,2) -> 0 | I5: =G5+H5 -> 0 | J5: 初始值 | P5: =SUM(K5:O5) -> 0 | Q5: 1.1.2 | R5: 设备购置费 | S5: ='项目技术经济指标'!D32 -> 564.9 | T5: 0.13 | U5: =ROUND(S5/(1+T5)*T5,2) -> 64.99 | V5: =S5-U5 -> 499.91
A6: 2 | B6: =ROUND('收入成本'!G5/(1+$B$4)*$B$4,2) -> 10.85 | D6: =ROUND('收入成本'!K5/(1+$D$4)*$D$4,2) -> 1.58 | E6: =ROUND('收入成本'!O5/(1+$E$4)*$E$4,2) -> 0 | F6: =SUM(B6:E6) -> 12.43 | G6: =ROUND('收入成本'!U5/(1+$G$4)*$G$4,2) -> 0.76 | H6: =ROUND('收入成本'!X5/(1+$H$4)*$H$4,2) -> 0.49 | I6: =G6+H6 -> 1.25 | J6: =U9 -> 408.48 | P6: =SUM(K6:O6) -> 0 | Q6: 1.2 | R6: 工程建设其他费 | S6: ='项目技术经济指标'!D33 -> 559.82 | T6: 0.06 | U6: =ROUND(S6/(1+T6)*T6,2) -> 31.69 | V6: =S6-U6 -> 528.13
A7: 3 | B7: =ROUND('收入成本'!G6/(1+$B$4)*$B$4,2) -> 11.93 | D7: =ROUND('收入成本'!K6/(1+$D$4)*$D$4,2) -> 1.74 | E7: =ROUND('收入成本'!O6/(1+$E$4)*$E$4,2) -> 0 | F7: =SUM(B7:E7) -> 13.67 | G7: =ROUND('收入成本'!U6/(1+$G$4)*$G$4,2) -> 0.83 | H7: =ROUND('收入成本'!X6/(1+$H$4)*$H$4,2) -> 0.49 | I7: =G7+H7 -> 1.32 | J7: =IF((J6+H7+G7)-SUM(B7:E7)<0,0,(J6+H7+G7)-SUM(B7:E7)) -> 396.13 | K7: =IF((J6+H7+G7)-SUM(B7:E7)>0,0,SUM(B7:E7)-(J6+H7+G7)) -> 0 | L7: =ROUND(K7*$L$4,2) -> 0 | M7: =ROUND(K7*$M$4,2) -> 0 | N7: =ROUND(K7*$N$4,2) -> 0 | P7: =SUM(K7:O7) -> 0 | Q7: 1.3 | R7: 基本预备费 | S7: ='项目技术经济指标'!D34 -> 348.3 | T7: 0.09 | U7: =ROUND(S7/(1+T7)*T7,2) -> 28.76 | V7: =S7-U7 -> 319.54
A8: 4 | B8: =ROUND('收入成本'!G7/(1+$B$4)*$B$4,2) -> 13.02 | D8: =ROUND('收入成本'!K7/(1+$D$4)*$D$4,2) -> 1.9 | E8: =ROUND('收入成本'!O7/(1+$E$4)*$E$4,2) -> 0 | F8: =SUM(B8:E8) -> 14.92 | G8: =ROUND('收入成本'!U7/(1+$G$4)*$G$4,2) -> 0.91 | H8: =ROUND('收入成本'!X7/(1+$H$4)*$H$4,2) -> 0.49 | I8: =G8+H8 -> 1.4 | J8: =IF((J7+H8+G8)-SUM(B8:E8)<0,0,(J7+H8+G8)-SUM(B8:E8)) -> 382.61 | K8: =IF((J7+H8+G8)-SUM(B8:E8)>0,0,SUM(B8:E8)-(J7+H8+G8)) -> 0 | L8: =ROUND(K8*$L$4,2) -> 0 | M8: =ROUND(K8*$M$4,2) -> 0 | N8: =ROUND(K8*$N$4,2) -> 0 | P8: =SUM(K8:O8) -> 0 | Q8: 1.4 | R8: 建设期利息 | S8: ='项目技术经济指标'!D35 -> 99 | T8: 0 | U8: =ROUND(S8/(1+T8)*T8,2) -> 0 | V8: =S8-U8 -> 99
A9: 5 | B9: =ROUND('收入成本'!G8/(1+$B$4)*$B$4,2) -> 14.1 | D9: =ROUND('收入成本'!K8/(1+$D$4)*$D$4,2) -> 2.06 | E9: =ROUND('收入成本'!O8/(1+$E$4)*$E$4,2) -> 0 | F9: =SUM(B9:E9) -> 16.16 | G9: =ROUND('收入成本'!U8/(1+$G$4)*$G$4,2) -> 0.98 | H9: =ROUND('收入成本'!X8/(1+$H$4)*$H$4,2) -> 0.49 | I9: =G9+H9 -> 1.47 | J9: =IF((J8+H9+G9)-SUM(B9:E9)<0,0,(J8+H9+G9)-SUM(B9:E9)) -> 367.92 | K9: =IF((J8+H9+G9)-SUM(B9:E9)>0,0,SUM(B9:E9)-(J8+H9+G9)) -> 0 | L9: =ROUND(K9*$L$4,2) -> 0 | M9: =ROUND(K9*$M$4,2) -> 0 | N9: =ROUND(K9*$N$4,2) -> 0 | P9: =SUM(K9:O9) -> 0 | Q9: 1 | R9: 总投资 | S9: =S3+S6+S7+S8 -> 5000 | U9: =SUM(U4:U8) -> 408.48 | V9: =SUM(V4:V8) -> 4591.52
A10: 6 | B10: =ROUND('收入成本'!G9/(1+$B$4)*$B$4,2) -> 15.19 | D10: =ROUND('收入成本'!K9/(1+$D$4)*$D$4,2) -> 2.22 | E10: =ROUND('收入成本'!O9/(1+$E$4)*$E$4,2) -> 0 | F10: =SUM(B10:E10) -> 17.41 | G10: =ROUND('收入成本'!U9/(1+$G$4)*$G$4,2) -> 1.06 | H10: =ROUND('收入成本'!X9/(1+$H$4)*$H$4,2) -> 0.49 | I10: =G10+H10 -> 1.55 | J10: =IF((J9+H10+G10)-SUM(B10:E10)<0,0,(J9+H10+G10)-SUM(B10:E10)) -> 352.06 | K10: =IF((J9+H10+G10)-SUM(B10:E10)>0,0,SUM(B10:E10)-(J9+H10+G10)) -> 0 | L10: =ROUND(K10*$L$4,2) -> 0 | M10: =ROUND(K10*$M$4,2) -> 0 | N10: =ROUND(K10*$N$4,2) -> 0 | P10: =SUM(K10:O10) -> 0
A11: 7 | B11: =ROUND('收入成本'!G10/(1+$B$4)*$B$4,2) -> 17.43 | D11: =ROUND('收入成本'!K10/(1+$D$4)*$D$4,2) -> 2.61 | E11: =ROUND('收入成本'!O10/(1+$E$4)*$E$4,2) -> 0 | F11: =SUM(B11:E11) -> 20.04 | G11: =ROUND('收入成本'!U10/(1+$G$4)*$G$4,2) -> 1.13 | H11: =ROUND('收入成本'!X10/(1+$H$4)*$H$4,2) -> 0.51 | I11: =G11+H11 -> 1.64 | J11: =IF((J10+H11+G11)-SUM(B11:E11)<0,0,(J10+H11+G11)-SUM(B11:E11)) -> 333.66 | K11: =IF((J10+H11+G11)-SUM(B11:E11)>0,0,SUM(B11:E11)-(J10+H11+G11)) -> 0 | L11: =ROUND(K11*$L$4,2) -> 0 | M11: =ROUND(K11*$M$4,2) -> 0 | N11: =ROUND(K11*$N$4,2) -> 0 | P11: =SUM(K11:O11) -> 0
A12: 8 | B12: =ROUND('收入成本'!G11/(1+$B$4)*$B$4,2) -> 17.43 | D12: =ROUND('收入成本'!K11/(1+$D$4)*$D$4,2) -> 2.61 | E12: =ROUND('收入成本'!O11/(1+$E$4)*$E$4,2) -> 0 | F12: =SUM(B12:E12) -> 20.04 | G12: =ROUND('收入成本'!U11/(1+$G$4)*$G$4,2) -> 1.13 | H12: =ROUND('收入成本'!X11/(1+$H$4)*$H$4,2) -> 0.51 | I12: =G12+H12 -> 1.64 | J12: =IF((J11+H12+G12)-SUM(B12:E12)<0,0,(J11+H12+G12)-SUM(B12:E12)) -> 315.26 | K12: =IF((J11+H12+G12)-SUM(B12:E12)>0,0,SUM(B12:E12)-(J11+H12+G12)) -> 0 | L12: =ROUND(K12*$L$4,2) -> 0 | M12: =ROUND(K12*$M$4,2) -> 0 | N12: =ROUND(K12*$N$4,2) -> 0 | P12: =SUM(K12:O12) -> 0
A13: 9 | B13: =ROUND('收入成本'!G12/(1+$B$4)*$B$4,2) -> 17.43 | D13: =ROUND('收入成本'!K12/(1+$D$4)*$D$4,2) -> 2.61 | E13: =ROUND('收入成本'!O12/(1+$E$4)*$E$4,2) -> 0 | F13: =SUM(B13:E13) -> 20.04 | G13: =ROUND('收入成本'!U12/(1+$G$4)*$G$4,2) -> 1.13 | H13: =ROUND('收入成本'!X12/(1+$H$4)*$H$4,2) -> 0.51 | I13: =G13+H13 -> 1.64 | J13: =IF((J12+H13+G13)-SUM(B13:E13)<0,0,(J12+H13+G13)-SUM(B13:E13)) -> 296.86 | K13: =IF((J12+H13+G13)-SUM(B13:E13)>0,0,SUM(B13:E13)-(J12+H13+G13)) -> 0 | L13: =ROUND(K13*$L$4,2) -> 0 | M13: =ROUND(K13*$M$4,2) -> 0 | N13: =ROUND(K13*$N$4,2) -> 0 | P13: =SUM(K13:O13) -> 0
A14: 10 | B14: =ROUND('收入成本'!G13/(1+$B$4)*$B$4,2) -> 17.43 | D14: =ROUND('收入成本'!K13/(1+$D$4)*$D$4,2) -> 2.61 | E14: =ROUND('收入成本'!O13/(1+$E$4)*$E$4,2) -> 0 | F14: =SUM(B14:E14) -> 20.04 | G14: =ROUND('收入成本'!U13/(1+$G$4)*$G$4,2) -> 1.13 | H14: =ROUND('收入成本'!X13/(1+$H$4)*$H$4,2) -> 0.51 | I14: =G14+H14 -> 1.64 | J14: =IF((J13+H14+G14)-SUM(B14:E14)<0,0,(J13+H14+G14)-SUM(B14:E14)) -> 278.46 | K14: =IF((J13+H14+G14)-SUM(B14:E14)>0,0,SUM(B14:E14)-(J13+H14+G14)) -> 0 | L14: =ROUND(K14*$L$4,2) -> 0 | M14: =ROUND(K14*$M$4,2) -> 0 | N14: =ROUND(K14*$N$4,2) -> 0 | P14: =SUM(K14:O14) -> 0
A15: 11 | B15: =ROUND('收入成本'!G14/(1+$B$4)*$B$4,2) -> 17.43 | D15: =ROUND('收入成本'!K14/(1+$D$4)*$D$4,2) -> 2.61 | E15: =ROUND('收入成本'!O14/(1+$E$4)*$E$4,2) -> 0 | F15: =SUM(B15:E15) -> 20.04 | G15: =ROUND('收入成本'!U14/(1+$G$4)*$G$4,2) -> 1.13 | H15: =ROUND('收入成本'!X14/(1+$H$4)*$H$4,2) -> 0.51 | I15: =G15+H15 -> 1.64 | J15: =IF((J14+H15+G15)-SUM(B15:E15)<0,0,(J14+H15+G15)-SUM(B15:E15)) -> 260.06 | K15: =IF((J14+H15+G15)-SUM(B15:E15)>0,0,SUM(B15:E15)-(J14+H15+G15)) -> 0 | L15: =ROUND(K15*$L$4,2) -> 0 | M15: =ROUND(K15*$M$4,2) -> 0 | N15: =ROUND(K15*$N$4,2) -> 0 | P15: =SUM(K15:O15) -> 0
A16: 12 | B16: =ROUND('收入成本'!G15/(1+$B$4)*$B$4,2) -> 18.73 | D16: =ROUND('收入成本'!K15/(1+$D$4)*$D$4,2) -> 2.9 | E16: =ROUND('收入成本'!O15/(1+$E$4)*$E$4,2) -> 0 | F16: =SUM(B16:E16) -> 21.63 | G16: =ROUND('收入成本'!U15/(1+$G$4)*$G$4,2) -> 1.13 | H16: =ROUND('收入成本'!X15/(1+$H$4)*$H$4,2) -> 0.54 | I16: =G16+H16 -> 1.67 | J16: =IF((J15+H16+G16)-SUM(B16:E16)<0,0,(J15+H16+G16)-SUM(B16:E16)) -> 240.1 | K16: =IF((J15+H16+G16)-SUM(B16:E16)>0,0,SUM(B16:E16)-(J15+H16+G16)) -> 0 | L16: =ROUND(K16*$L$4,2) -> 0 | M16: =ROUND(K16*$M$4,2) -> 0 | N16: =ROUND(K16*$N$4,2) -> 0 | P16: =SUM(K16:O16) -> 0
A17: 13 | B17: =ROUND('收入成本'!G16/(1+$B$4)*$B$4,2) -> 18.73 | D17: =ROUND('收入成本'!K16/(1+$D$4)*$D$4,2) -> 2.9 | E17: =ROUND('收入成本'!O16/(1+$E$4)*$E$4,2) -> 0 | F17: =SUM(B17:E17) -> 21.63 | G17: =ROUND('收入成本'!U16/(1+$G$4)*$G$4,2) -> 1.13 | H17: =ROUND('收入成本'!X16/(1+$H$4)*$H$4,2) -> 0.54 | I17: =G17+H17 -> 1.67 | J17: =IF((J16+H17+G17)-SUM(B17:E17)<0,0,(J16+H17+G17)-SUM(B17:E17)) -> 220.14 | K17: =IF((J16+H17+G17)-SUM(B17:E17)>0,0,SUM(B17:E17)-(J16+H17+G17)) -> 0 | L17: =ROUND(K17*$L$4,2) -> 0 | M17: =ROUND(K17*$M$4,2) -> 0 | N17: =ROUND(K17*$N$4,2) -> 0 | P17: =SUM(K17:O17) -> 0
A18: 14 | B18: =ROUND('收入成本'!G17/(1+$B$4)*$B$4,2) -> 18.73 | D18: =ROUND('收入成本'!K17/(1+$D$4)*$D$4,2) -> 2.9 | E18: =ROUND('收入成本'!O17/(1+$E$4)*$E$4,2) -> 0 | F18: =SUM(B18:E18) -> 21.63 | G18: =ROUND('收入成本'!U17/(1+$G$4)*$G$4,2) -> 1.13 | H18: =ROUND('收入成本'!X17/(1+$H$4)*$H$4,2) -> 16.53 | I18: =G18+H18 -> 17.66 | J18: =IF((J17+H18+G18)-SUM(B18:E18)<0,0,(J17+H18+G18)-SUM(B18:E18)) -> 216.17 | K18: =IF((J17+H18+G18)-SUM(B18:E18)>0,0,SUM(B18:E18)-(J17+H18+G18)) -> 0 | L18: =ROUND(K18*$L$4,2) -> 0 | M18: =ROUND(K18*$M$4,2) -> 0 | N18: =ROUND(K18*$N$4,2) -> 0 | P18: =SUM(K18:O18) -> 0
A19: 15 | B19: =ROUND('收入成本'!G18/(1+$B$4)*$B$4,2) -> 18.73 | D19: =ROUND('收入成本'!K18/(1+$D$4)*$D$4,2) -> 2.9 | E19: =ROUND('收入成本'!O18/(1+$E$4)*$E$4,2) -> 0 | F19: =SUM(B19:E19) -> 21.63 | G19: =ROUND('收入成本'!U18/(1+$G$4)*$G$4,2) -> 1.13 | H19: =ROUND('收入成本'!X18/(1+$H$4)*$H$4,2) -> 16.53 | I19: =G19+H19 -> 17.66 | J19: =IF((J18+H19+G19)-SUM(B19:E19)<0,0,(J18+H19+G19)-SUM(B19:E19)) -> 212.2 | K19: =IF((J18+H19+G19)-SUM(B19:E19)>0,0,SUM(B19:E19)-(J18+H19+G19)) -> 0 | L19: =ROUND(K19*$L$4,2) -> 0 | M19: =ROUND(K19*$M$4,2) -> 0 | N19: =ROUND(K19*$N$4,2) -> 0 | P19: =SUM(K19:O19) -> 0
A20: 16 | B20: =ROUND('收入成本'!G19/(1+$B$4)*$B$4,2) -> 18.73 | D20: =ROUND('收入成本'!K19/(1+$D$4)*$D$4,2) -> 2.9 | E20: =ROUND('收入成本'!O19/(1+$E$4)*$E$4,2) -> 0 | F20: =SUM(B20:E20) -> 21.63 | G20: =ROUND('收入成本'!U19/(1+$G$4)*$G$4,2) -> 1.13 | H20: =ROUND('收入成本'!X19/(1+$H$4)*$H$4,2) -> 0.54 | I20: =G20+H20 -> 1.67 | J20: =IF((J19+H20+G20)-SUM(B20:E20)<0,0,(J19+H20+G20)-SUM(B20:E20)) -> 192.24 | K20: =IF((J19+H20+G20)-SUM(B20:E20)>0,0,SUM(B20:E20)-(J19+H20+G20)) -> 0 | L20: =ROUND(K20*$L$4,2) -> 0 | M20: =ROUND(K20*$M$4,2) -> 0 | N20: =ROUND(K20*$N$4,2) -> 0 | P20: =SUM(K20:O20) -> 0
A21: 17 | B21: =ROUND('收入成本'!G20/(1+$B$4)*$B$4,2) -> 20.13 | D21: =ROUND('收入成本'!K20/(1+$D$4)*$D$4,2) -> 3.18 | E21: =ROUND('收入成本'!O20/(1+$E$4)*$E$4,2) -> 0 | F21: =SUM(B21:E21) -> 23.31 | G21: =ROUND('收入成本'!U20/(1+$G$4)*$G$4,2) -> 1.13 | H21: =ROUND('收入成本'!X20/(1+$H$4)*$H$4,2) -> 0.57 | I21: =G21+H21 -> 1.7 | J21: =IF((J20+H21+G21)-SUM(B21:E21)<0,0,(J20+H21+G21)-SUM(B21:E21)) -> 170.63 | K21: =IF((J20+H21+G21)-SUM(B21:E21)>0,0,SUM(B21:E21)-(J20+H21+G21)) -> 0 | L21: =ROUND(K21*$L$4,2) -> 0 | M21: =ROUND(K21*$M$4,2) -> 0 | N21: =ROUND(K21*$N$4,2) -> 0 | P21: =SUM(K21:O21) -> 0
... A34: 30 | B34: =ROUND('收入成本'!G33/(1+$B$4)*$B$4,2) -> 23.38 | D34: =ROUND('收入成本'!K33/(1+$D$4)*$D$4,2) -> 3.84 | E34: =ROUND('收入成本'!O33/(1+$E$4)*$E$4,2) -> 0 | F34: =SUM(B34:E34) -> 27.22 | G34: =ROUND('收入成本'!U33/(1+$G$4)*$G$4,2) -> 1.13 | H34: =ROUND('收入成本'!X33/(1+$H$4)*$H$4,2) -> 0.62 | I34: =G34+H34 -> 1.75 | J34: =IF((J33+H34+G34)-SUM(B34:E34)<0,0,(J33+H34+G34)-SUM(B34:E34)) -> 0 | K34: =IF((J33+H34+G34)-SUM(B34:E34)>0,0,SUM(B34:E34)-(J33+H34+G34)) -> 25.47 | L34: =ROUND(K34*$L$4,2) -> 1.27 | M34: =ROUND(K34*$M$4,2) -> 0.76 | N34: =ROUND(K34*$N$4,2) -> 0.51 | P34: =SUM(K34:O34) -> 28.01
A35: 31 | B35: =ROUND('收入成本'!G34/(1+$B$4)*$B$4,2) -> 0 | D35: =ROUND('收入成本'!K34/(1+$D$4)*$D$4,2) -> 0 | E35: =ROUND('收入成本'!O33/(1+$E$4)*$E$4,2) -> 0 | F35: =SUM(B35:E35) -> 0 | G35: =ROUND('收入成本'!U33/(1+$G$4)*$G$4,2) -> 1.13 | H35: =ROUND('收入成本'!X33/(1+$H$4)*$H$4,2) -> 0.62 | I35: =G35+H35 -> 1.75 | J35: =IF((J34+H35+G35)-SUM(B35:E35)<0,0,(J34+H35+G35)-SUM(B35:E35)) -> 1.75 | K35: =IF((J34+H35+G35)-SUM(B35:E35)>0,0,SUM(B35:E35)-(J34+H35+G35)) -> 0 | L35: =ROUND(K35*$L$4,2) -> 0 | M35: =ROUND(K35*$M$4,2) -> 0 | N35: =ROUND(K35*$N$4,2) -> 0 | P35: =SUM(K35:O35) -> 0
